Workbook
Name PT_PREDICTION_EQUIPE_R1: 'Pool - Ville de Laval'!$O$90
Name PT_PREDICTION_EQUIPE_R2: 'Pool - Ville de Laval'!$P$90
Name PT_PREDICTION_EQUIPE_R3: 'Pool - Ville de Laval'!$Q$90
Name PT_PREDICTION_EQUIPE_R4: 'Pool - Ville de Laval'!$R$90
Name PT_PREDICTION_NB_PARTIES_R1: 'Pool - Ville de Laval'!$O$91
Name PT_PREDICTION_NB_PARTIES_R2: 'Pool - Ville de Laval'!$P$91
Name PT_PREDICTION_NB_PARTIES_R3: 'Pool - Ville de Laval'!$Q$91
Name PT_PREDICTION_NB_PARTIES_R4: 'Pool - Ville de Laval'!$R$91
Name PT_VICTOIRE_R1: 'Pool - Ville de Laval'!$O$92
Name PT_VICTOIRE_R2: 'Pool - Ville de Laval'!$P$92
Name PT_VICTOIRE_R3: 'Pool - Ville de Laval'!$Q$92
Name PT_VICTOIRE_R4: 'Pool - Ville de Laval'!$R$92

Sheet Pool - Ville de Laval
C2: Résultats complets disponibles à l'adresse suivante : | Q2: https://staker4.github.io/pool/laval.pdf
C4: RONDE 1 | T4: RONDE 2 | AC4: RONDE 3 | AH4: R4
C5: EST | K5: OUEST | S5: Sous-total - RONDE 1 | T5: EST | X5: OUEST | AB5: Sous-total - RONDE 2 | AC5: EST | AE5: OUEST | AG5: Sous-total - RONDE 3 | AJ5: Sous-total - RONDE 4
C6: =Résultats!$J$3 -> 4 | D6: =Résultats!$J$4 -> 1 | E6: =Résultats!$J$6 -> 4 | F6: =Résultats!$J$7 -> 3 | G6: =Résultats!$J$10 -> 4 | H6: =Résultats!$J$11 -> 2 | I6: =Résultats!$J$13 -> 4 | J6: =Résultats!$J$14 -> 2 | K6: =Résultats!$J$17 -> 4 | L6: =Résultats!$J$18 -> 2 | M6: =Résultats!$J$20 -> 4 | N6: =Résultats!$J$21 -> 1 | O6: =Résultats!$J$24 -> 4 | P6: =Résultats!$J$25 -> 0 | Q6: =Résultats!$J$27 -> 0 | R6: =Résultats!$J$28 -> 4 | T6: =Résultats!$V$6 -> 4 | U6: =Résultats!$V$7 -> 1 | V6: =Résultats!$V$10 -> 4 | W6: =Résultats!$V$11 -> 2 | X6: =Résultats!$V$20 -> 3 | Y6: =Résultats!$V$21 -> 4 | Z6: =Résultats!$V$24 -> 4 | AA6: =Résultats!$V$25 -> 2 | AC6: =Résultats!$AH$8 -> 3 | AD6: =Résultats!$AH$9 -> 4 | AE6: =Résultats!$AH$22 -> 1 | AF6: =Résultats!$AH$23 -> 4 | AH6: =Résultats!$AH$15 -> 4 | AI6: =Résultats!$AH$16 -> 1
C7: =IF(ISBLANK($C10),0,($C$6*PT_VICTOIRE_R1)+IF($C$6=4,PT_PREDICTION_EQUIPE_R1+IF($C10=$C$6+$D$6,PT_PREDICTION_NB_PARTIES_R1,0),0)) +IF(ISBLANK($D10),0,($D$6*PT_VICTOIRE_R1)+IF($D$6=4,PT_PREDICTION_EQUIPE_R1+IF($D10=$C$6+$D$6,PT_PREDICTION_NB_PARTIES_R1,0),0)) -> 1
C8: =Résultats!$B$3 -> TAMPA BAY | D8: =Résultats!$B$4 -> NEW JERSEY | E8: =Résultats!$B$6 -> BOSTON | F8: =Résultats!$B$7 -> TORONTO | G8: =Résultats!$B$10 -> WASHINGTON | H8: =Résultats!$B$11 -> COLOMBUS | I8: =Résultats!$B$13 -> PITTSBURGH | J8: =Résultats!$B$14 -> PHILADELPHIE | K8: =Résultats!$B$17 -> NASHVILLE | L8: =Résultats!$B$18 -> COLORADO | M8: =Résultats!$B$20 -> WINNIPEG | N8: =Résultats!$B$21 -> MINNESOTA | O8: =Résultats!$B$24 -> VEGAS | P8: =Résultats!$B$25 -> LOS ANGELES | Q8: =Résultats!$B$27 -> ANAHEIM | R8: =Résultats!$B$28 -> SAN JOSE | T8: =Résultats!$N$6 -> TAMPA BAY | U8: =Résultats!$N$7 -> BOSTON | V8: =Résultats!$N$10 -> WASHINGTON | W8: =Résultats!$N$11 -> PITTSBURGH | X8: =Résultats!$N$20 -> NASHVILLE | Y8: =Résultats!$N$21 -> WINNIPEG | Z8: =Résultats!$N$24 -> VEGAS | AA8: =Résultats!$N$25 -> SAN JOSE | AC8: =Résultats!$Z$8 -> TAMPA BAY | AD8: =Résultats!$Z$9 -> WASHINGTON | AE8: =Résultats!$Z$22 -> WINNIPEG | AF8: =Résultats!$Z$23 -> VEGAS | AH8: =Résultats!$Z$15 -> WASHINGTON | AI8: =Résultats!$Z$16 -> VEGAS
A9: # | B9: NOM | C9: =Résultats!$A$3 -> M1 | D9: =Résultats!$A$4 -> WC | E9: =Résultats!$A$6 -> M2 | F9: =Résultats!$A$7 -> M3 | G9: =Résultats!$A$10 -> A1 | H9: =Résultats!$A$11 -> WC | I9: =Résultats!$A$13 -> A2 | J9: =Résultats!$A$14 -> A3 | K9: =Résultats!$A$17 -> C1 | L9: =Résultats!$A$18 -> WC | M9: =Résultats!$A$20 -> C2 | N9: =Résultats!$A$21 -> C3 | O9: =Résultats!$A$24 -> P1 | P9: =Résultats!$A$25 -> WC | Q9: =Résultats!$A$27 -> P2 | R9: =Résultats!$A$28 -> P3 | T9: =Résultats!$M$6 -> M1 | U9: =Résultats!$M$7 -> M2 | V9: =Résultats!$M$10 -> A1 | W9: =Résultats!$M$11 -> A2 | X9: =Résultats!$M$20 -> C1 | Y9: =Résultats!$M$21 -> C2 | Z9: =Résultats!$M$24 -> P1 | AA9: =Résultats!$M$25 -> P3 | AC9: =Résultats!$Y$8 -> M1 | AD9: =Résultats!$Y$9 -> A1 | AE9: =Résultats!$Y$22 -> C2 | AF9: =Résultats!$Y$23 -> P1 | AH9: =Résultats!$Y$15 -> A1 | AI9: =Résultats!$Y$16 -> P1 | AK9: ÉCART | AL9: TOTAL
A10: =RANK(AL10,$AL$10:$AL$82,) -> 1 | B10: Matias Fajardo | D10: 5 | E10: 7 | G10: 6 | I10: 6 | K10: 5 | M10: 7 | P10: 7 | R10: 6 | S10: =SUM(C11:R11) -> 61 | T10: 7 | V10: 6 | Y10: 7 | Z10: 7 | AB10: =SUM(T11:AA11) -> 64 | AD10: 6 | AE10: 7 | AG10: =SUM(AC11:AF11) -> 20 | AH10: 7 | AJ10: =AH11 -> 24 | AK10: =MAX($AL$10:$AL$82) - AL10 -> 0 | AL10: =$S10+$AB10+$AG10+$AJ10 -> 169
C11: =(IF($C10<>"",($C$6*$O$92)+IF($C$6=4,($O$90)+IF($C10=$C$6+$D$6,$O$91,0),0),0)+IF($D10<>"",($D$6*$O$92)+IF($D$6=4,($O$90)+IF($D10=$C$6+$D$6,$O$91,0),0),0)) -> 1 | E11: =(IF($E10<>"",($E$6*$O$92)+IF($E$6=4,($O$90)+IF($E10=$E$6+$F$6,$O$91,0),0),0)+IF($F10<>"",($F$6*$O$92)+IF($F$6=4,($O$90)+IF($F10=$E$6+$F$6,$O$91,0),0),0)) -> 11 | G11: =(IF($G10<>"",($G$6*$O$92)+IF($G$6=4,($O$90)+IF($G10=$G$6+$H$6,$O$91,0),0),0)+IF($H10<>"",($H$6*$O$92)+IF($H$6=4,($O$90)+IF($H10=$G$6+$H$6,$O$91,0),0),0)) -> 11 | I11: =(IF($I10<>"",($I$6*$O$92)+IF($I$6=4,($O$90)+IF($I10=$I$6+$J$6,$O$91,0),0),0)+IF($J10<>"",($J$6*$O$92)+IF($J$6=4,($O$90)+IF($J10=$I$6+$J$6,$O$91,0),0),0)) -> 11 | K11: =(IF($K10<>"",($K$6*$O$92)+IF($K$6=4,($O$90)+IF($K10=$K$6+$L$6,$O$91,0),0),0)+IF($L10<>"",($L$6*$O$92)+IF($L$6=4,($O$90)+IF($L10=$K$6+$L$6,$O$91,0),0),0)) -> 9 | M11: =(IF($M10<>"",($M$6*$O$92)+IF($M$6=4,($O$90)+IF($M10=$M$6+$N$6,$O$91,0),0),0)+IF($N10<>"",($N$6*$O$92)+IF($N$6=4,($O$90)+IF($N10=$M$6+$N$6,$O$91,0),0),0)) -> 9 | O11: =(IF($O10<>"",($O$6*$O$92)+IF($O$6=4,($O$90)+IF($O10=$O$6+$P$6,$O$91,0),0),0)+IF($P10<>"",($P$6*$O$92)+IF($P$6=4,($O$90)+IF($P10=$O$6+$P$6,$O$91,0),0),0)) -> 0 | Q11: =(IF($Q10<>"",($Q$6*$O$92)+IF($Q$6=4,($O$90)+IF($Q10=$Q$6+$R$6,$O$91,0),0),0)+IF($R10<>"",($R$6*$O$92)+IF($R$6=4,($O$90)+IF($R10=$Q$6+$R$6,$O$91,0),0),0)) -> 9 | T11: =(IF($T10<>"",($T$6*$P$92)+IF($T$6=4,($P$90)+IF($T10=$T$6+$U$6,$P$91,0),0),0)+IF($U10<>"",($U$6*$P$92)+IF($U$6=4,($P$90)+IF($U10=$T$6+$U$6,$P$91,0),0),0)) -> 14 | V11: =(IF($V10<>"",($V$6*$P$92)+IF($V$6=4,($P$90)+IF($V10=$V$6+$W$6,$P$91,0),0),0)+IF($W10<>"",($W$6*$P$92)+IF($W$6=4,($P$90)+IF($W10=$V$6+$W$6,$P$91,0),0),0)) -> 18 | X11: =(IF($X10<>"",($X$6*$P$92)+IF($X$6=4,($P$90)+IF($X10=$X$6+$Y$6,$P$91,0),0),0)+IF($Y10<>"",($Y$6*$P$92)+IF($Y$6=4,($P$90)+IF($Y10=$X$6+$Y$6,$P$91,0),0),0)) -> 18 | Z11: =(IF($Z10<>"",($Z$6*$P$92)+IF($Z$6=4,($P$90)+IF($Z10=$Z$6+$AA$6,$P$91,0),0),0)+IF($AA10<>"",($AA$6*$P$92)+IF($AA$6=4,($P$90)+IF($AA10=$Z$6+$AA$6,$P$91,0),0),0)) -> 14 | AC11: =(IF($AC10<>"",($AC$6*$Q$92)+IF($AC$6=4,($Q$90)+IF($AC10=$AC$6+$AD$6,$Q$91,0),0),0)+IF($AD10<>"",($AD$6*$Q$92)+IF($AD$6=4,($Q$90)+IF($AD10=$AC$6+$AD$6,$Q$91,0),0),0)) -> 19 | AE11: =(IF($AE10<>"",($AE$6*$Q$92)+IF($AE$6=4,($Q$90)+IF($AE10=$AE$6+$AF$6,$Q$91,0),0),0)+IF($AF10<>"",($AF$6*$Q$92)+IF($AF$6=4,($Q$90)+IF($AF10=$AE$6+$AF$6,$Q$91,0),0),0)) -> 1 | AH11: =(IF($AH10<>"",($AH$6*$R$92)+IF($AH$6=4,($R$90)+IF($AH10=$AH$6+$AI$6,$R$91,0),0),0)+IF($AI10<>"",($AI$6*$R$92)+IF($AI$6=4,($R$90)+IF($AI10=$AH$6+$AI$6,$R$91,0),0),0)) -> 24
B12: Prédiction équipe | C12: =IF(ISBLANK(C10), 0, IF(C$6= 4, 1, 0)) -> 0 | D12: =IF(ISBLANK(D10), 0, IF(D$6 = 4, 1, 0)) -> 0 | E12: =IF(ISBLANK(E10), 0, IF(E$6= 4, 1, 0)) -> 1 | F12: =IF(ISBLANK(F10), 0, IF(F$6 = 4, 1, 0)) -> 0 | G12: =IF(ISBLANK(G10), 0, IF(G$6= 4, 1, 0)) -> 1 | H12: =IF(ISBLANK(H10), 0, IF(H$6 = 4, 1, 0)) -> 0 | I12: =IF(ISBLANK(I10), 0, IF(I$6= 4, 1, 0)) -> 1 | J12: =IF(ISBLANK(J10), 0, IF(J$6 = 4, 1, 0)) -> 0 | K12: =IF(ISBLANK(K10), 0, IF(K$6= 4, 1, 0)) -> 1 | L12: =IF(ISBLANK(L10), 0, IF(L$6 = 4, 1, 0)) -> 0 | M12: =IF(ISBLANK(M10), 0, IF(M$6= 4, 1, 0)) -> 1 | N12: =IF(ISBLANK(N10), 0, IF(N$6 = 4, 1, 0)) -> 0 | O12: =IF(ISBLANK(O10), 0, IF(O$6= 4, 1, 0)) -> 0 | P12: =IF(ISBLANK(P10), 0, IF(P$6 = 4, 1, 0)) -> 0 | Q12: =IF(ISBLANK(Q10), 0, IF(Q$6= 4, 1, 0)) -> 0 | R12: =IF(ISBLANK(R10), 0, IF(R$6 = 4, 1, 0)) -> 1 | T12: =IF(ISBLANK(T10), 0, IF(T$6= 4, 1, 0)) -> 1 | U12: =IF(ISBLANK(U10), 0, IF(U$6 = 4, 1, 0)) -> 0 | V12: =IF(ISBLANK(V10), 0, IF(V$6= 4, 1, 0)) -> 1 | W12: =IF(ISBLANK(W10), 0, IF(W$6 = 4, 1, 0)) -> 0 | X12: =IF(ISBLANK(X10), 0, IF(X$6= 4, 1, 0)) -> 0 | Y12: =IF(ISBLANK(Y10), 0, IF(Y$6 = 4, 1, 0)) -> 1 | Z12: =IF(ISBLANK(Z10), 0, IF(Z$6= 4, 1, 0)) -> 1 | AA12: =IF(ISBLANK(AA10), 0, IF(AA$6 = 4, 1, 0)) -> 0 | AC12: =IF(ISBLANK(AC10), 0, IF(AC$6= 4, 1, 0)) -> 0 | AD12: =IF(ISBLANK(AD10), 0, IF(AD$6 = 4, 1, 0)) -> 1 | AE12: =IF(ISBLANK(AE10), 0, IF(AE$6= 4, 1, 0)) -> 0 | AF12: =IF(ISBLANK(AF10), 0, IF(AF$6 = 4, 1, 0)) -> 0 | AH12: =IF(ISBLANK(AH10), 0, IF(AH$6= 4, 1, 0)) -> 1 | AI12: =IF(ISBLANK(AI10), 0, IF(AI$6 = 4, 1, 0)) -> 0 | AK12: =SUM(C12:AI12) -> 12
B13: Prédiciton nb matchs | C13: =IF(C12 = 0, 0, IF(C10 = (C$6+D$6),1,0)) -> 0 | D13: =IF(D12 = 0, 0, IF(D10 = (C$6+D$6),1,0)) -> 0 | E13: =IF(E12 = 0, 0, IF(E10 = (E$6+F$6),1,0)) -> 1 | F13: =IF(F12 = 0, 0, IF(F10 = (E$6+F$6),1,0)) -> 0 | G13: =IF(G12 = 0, 0, IF(G10 = (G$6+H$6),1,0)) -> 1 | H13: =IF(H12 = 0, 0, IF(H10 = (G$6+H$6),1,0)) -> 0 | I13: =IF(I12 = 0, 0, IF(I10 = (I$6+J$6),1,0)) -> 1 | J13: =IF(J12 = 0, 0, IF(J10 = (I$6+J$6),1,0)) -> 0 | K13: =IF(K12 = 0, 0, IF(K10 = (K$6+L$6),1,0)) -> 0 | L13: =IF(L12 = 0, 0, IF(L10 = (K$6+L$6),1,0)) -> 0 | M13: =IF(M12 = 0, 0, IF(M10 = (M$6+N$6),1,0)) -> 0 | N13: =IF(N12 = 0, 0, IF(N10 = (M$6+N$6),1,0)) -> 0 | O13: =IF(O12 = 0, 0, IF(O10 = (O$6+P$6),1,0)) -> 0 | P13: =IF(P12 = 0, 0, IF(P10 = (O$6+P$6),1,0)) -> 0 | Q13: =IF(Q12 = 0, 0, IF(Q10 = (Q$6+R$6),1,0)) -> 0 | R13: =IF(R12 = 0, 0, IF(R10 = (Q$6+R$6),1,0)) -> 0 | T13: =IF(T12 = 0, 0, IF(T10 = (T$6+U$6),1,0)) -> 0 | U13: =IF(U12 = 0, 0, IF(U10 = (T$6+U$6),1,0)) -> 0 | V13: =IF(V12 = 0, 0, IF(V10 = (V$6+W$6),1,0)) -> 1 | W13: =IF(W12 = 0, 0, IF(W10 = (V$6+W$6),1,0)) -> 0 | X13: =IF(X12 = 0, 0, IF(X10 = (X$6+Y$6),1,0)) -> 0 | Y13: =IF(Y12 = 0, 0, IF(Y10 = (X$6+Y$6),1,0)) -> 1 | Z13: =IF(Z12 = 0, 0, IF(Z10 = (Z$6+AA$6),1,0)) -> 0 | AA13: =IF(AA12 = 0, 0, IF(AA10 = (Z$6+AA$6),1,0)) -> 0 | AC13: =IF(AC12 = 0, 0, IF(AC10 = (AC$6+AD$6),1,0)) -> 0 | AD13: =IF(AD12 = 0, 0, IF(AD10 = (AC$6+AD$6),1,0)) -> 0 | AE13: =IF(AE12 = 0, 0, IF(AE10 = (AE$6+AF$6),1,0)) -> 0 | AF13: =IF(AF12 = 0, 0, IF(AF10 = (AE$6+AF$6),1,0)) -> 0 | AH13: =IF(AH12 = 0, 0, IF(AH10 = (AH$6+AI$6),1,0)) -> 0 | AI13: =IF(AI12 = 0, 0, IF(AI10 = (AH$6+AI$6),1,0)) -> 0 | AK13: =SUM(C13:AI13) -> 5
A14: =RANK(AL14,$AL$10:$AL$82,) -> 2 | B14: Jean-Christophe Pichot | D14: 7 | F14: 7 | G14: 7 | I14: 7 | K14: 7 | M14: 7 | O14: 7 | R14: 7 | S14: =SUM(C15:R15) -> 58 | U14: 7 | V14: 7 | Y14: 7 | Z14: 7 | AB14: =SUM(T15:AA15) -> 47 | AD14: 6 | AF14: 6 | AG14: =SUM(AC15:AF15) -> 38 | AH14: 6 | AJ14: =AH15 -> 24 | AK14: =MAX($AL$10:$AL$82) - AL14 -> 2 | AL14: =$S14+$AB14+$AG14+$AJ14 -> 167
A15: =RANK(AL15,$AL$10:$AL$82,) -> #N/A | C15: =(IF($C14<>"",($C$6*$O$92)+IF($C$6=4,($O$90)+IF($C14=$C$6+$D$6,$O$91,0),0),0)+IF($D14<>"",($D$6*$O$92)+IF($D$6=4,($O$90)+IF($D14=$C$6+$D$6,$O$91,0),0),0)) -> 1 | E15: =(IF($E14<>"",($E$6*$O$92)+IF($E$6=4,($O$90)+IF($E14=$E$6+$F$6,$O$91,0),0),0)+IF($F14<>"",($F$6*$O$92)+IF($F$6=4,($O$90)+IF($F14=$E$6+$F$6,$O$91,0),0),0)) -> 3 | G15: =(IF($G14<>"",($G$6*$O$92)+IF($G$6=4,($O$90)+IF($G14=$G$6+$H$6,$O$91,0),0),0)+IF($H14<>"",($H$6*$O$92)+IF($H$6=4,($O$90)+IF($H14=$G$6+$H$6,$O$91,0),0),0)) -> 9 | I15: =(IF($I14<>"",($I$6*$O$92)+IF($I$6=4,($O$90)+IF($I14=$I$6+$J$6,$O$91,0),0),0)+IF($J14<>"",($J$6*$O$92)+IF($J$6=4,($O$90)+IF($J14=$I$6+$J$6,$O$91,0),0),0)) -> 9 | K15: =(IF($K14<>"",($K$6*$O$92)+IF($K$6=4,($O$90)+IF($K14=$K$6+$L$6,$O$91,0),0),0)+IF($L14<>"",($L$6*$O$92)+IF($L$6=4,($O$90)+IF($L14=$K$6+$L$6,$O$91,0),0),0)) -> 9 | M15: =(IF($M14<>"",($M$6*$O$92)+IF($M$6=4,($O$90)+IF($M14=$M$6+$N$6,$O$91,0),0),0)+IF($N14<>"",($N$6*$O$92)+IF($N$6=4,($O$90)+IF($N14=$M$6+$N$6,$O$91,0),0),0)) -> 9 | O15: =(IF($O14<>"",($O$6*$O$92)+IF($O$6=4,($O$90)+IF($O14=$O$6+$P$6,$O$91,0),0),0)+IF($P14<>"",($P$6*$O$92)+IF($P$6=4,($O$90)+IF($P14=$O$6+$P$6,$O$91,0),0),0)) -> 9 | Q15: =(IF($Q14<>"",($Q$6*$O$92)+IF($Q$6=4,($O$90)+IF($Q14=$Q$6+$R$6,$O$91,0),0),0)+IF($R14<>"",($R$6*$O$92)+IF($R$6=4,($O$90)+IF($R14=$Q$6+$R$6,$O$91,0),0),0)) -> 9 | T15: =(IF($T14<>"",($T$6*$P$92)+IF($T$6=4,($P$90)+IF($T14=$T$6+$U$6,$P$91,0),0),0)+IF($U14<>"",($U$6*$P$92)+IF($U$6=4,($P$90)+IF($U14=$T$6+$U$6,$P$91,0),0),0)) -> 1 | V15: =(IF($V14<>"",($V$6*$P$92)+IF($V$6=4,($P$90)+IF($V14=$V$6+$W$6,$P$91,0),0),0)+IF($W14<>"",($W$6*$P$92)+IF($W$6=4,($P$90)+IF($W14=$V$6+$W$6,$P$91,0),0),0)) -> 14 | X15: =(IF($X14<>"",($X$6*$P$92)+IF($X$6=4,($P$90)+IF($X14=$X$6+$Y$6,$P$91,0),0),0)+IF($Y14<>"",($Y$6*$P$92)+IF($Y$6=4,($P$90)+IF($Y14=$X$6+$Y$6,$P$91,0),0),0)) -> 18 | Z15: =(IF($Z14<>"",($Z$6*$P$92)+IF($Z$6=4,($P$90)+IF($Z14=$Z$6+$AA$6,$P$91,0),0),0)+IF($AA14<>"",($AA$6*$P$92)+IF($AA$6=4,($P$90)+IF($AA14=$Z$6+$AA$6,$P$91,0),0),0)) -> 14 | AC15: =(IF($AC14<>"",($AC$6*$Q$92)+IF($AC$6=4,($Q$90)+IF($AC14=$AC$6+$AD$6,$Q$91,0),0),0)+IF($AD14<>"",($AD$6*$Q$92)+IF($AD$6=4,($Q$90)+IF($AD14=$AC$6+$AD$6,$Q$91,0),0),0)) -> 19 | AE15: =(IF($AE14<>"",($AE$6*$Q$92)+IF($AE$6=4,($Q$90)+IF($AE14=$AE$6+$AF$6,$Q$91,0),0),0)+IF($AF14<>"",($AF$6*$Q$92)+IF($AF$6=4,($Q$90)+IF($AF14=$AE$6+$AF$6,$Q$91,0),0),0)) -> 19 | AH15: =(IF($AH14<>"",($AH$6*$R$92)+IF($AH$6=4,($R$90)+IF($AH14=$AH$6+$AI$6,$R$91,0),0),0)+IF($AI14<>"",($AI$6*$R$92)+IF($AI$6=4,($R$90)+IF($AI14=$AH$6+$AI$6,$R$91,0),0),0)) -> 24 | AK15: =MAX($AL$10:$AL$82) - AL15 -> 169
B16: Prédiction équipe | C16: =IF(ISBLANK(C14), 0, IF(C$6= 4, 1, 0)) -> 0 | D16: =IF(ISBLANK(D14), 0, IF(D$6 = 4, 1, 0)) -> 0 | E16: =IF(ISBLANK(E14), 0, IF(E$6= 4, 1, 0)) -> 0 | F16: =IF(ISBLANK(F14), 0, IF(F$6 = 4, 1, 0)) -> 0 | G16: =IF(ISBLANK(G14), 0, IF(G$6= 4, 1, 0)) -> 1 | H16: =IF(ISBLANK(H14), 0, IF(H$6 = 4, 1, 0)) -> 0 | I16: =IF(ISBLANK(I14), 0, IF(I$6= 4, 1, 0)) -> 1 | J16: =IF(ISBLANK(J14), 0, IF(J$6 = 4, 1, 0)) -> 0 | K16: =IF(ISBLANK(K14), 0, IF(K$6= 4, 1, 0)) -> 1 | L16: =IF(ISBLANK(L14), 0, IF(L$6 = 4, 1, 0)) -> 0 | M16: =IF(ISBLANK(M14), 0, IF(M$6= 4, 1, 0)) -> 1 | N16: =IF(ISBLANK(N14), 0, IF(N$6 = 4, 1, 0)) -> 0 | O16: =IF(ISBLANK(O14), 0, IF(O$6= 4, 1, 0)) -> 1 | P16: =IF(ISBLANK(P14), 0, IF(P$6 = 4, 1, 0)) -> 0 | Q16: =IF(ISBLANK(Q14), 0, IF(Q$6= 4, 1, 0)) -> 0 | R16: =IF(ISBLANK(R14), 0, IF(R$6 = 4, 1, 0)) -> 1 | T16: =IF(ISBLANK(T14), 0, IF(T$6= 4, 1, 0)) -> 0 | U16: =IF(ISBLANK(U14), 0, IF(U$6 = 4, 1, 0)) -> 0 | V16: =IF(ISBLANK(V14), 0, IF(V$6= 4, 1, 0)) -> 1 | W16: =IF(ISBLANK(W14), 0, IF(W$6 = 4, 1, 0)) -> 0 | X16: =IF(ISBLANK(X14), 0, IF(X$6= 4, 1, 0)) -> 0 | Y16: =IF(ISBLANK(Y14), 0, IF(Y$6 = 4, 1, 0)) -> 1 | Z16: =IF(ISBLANK(Z14), 0, IF(Z$6= 4, 1, 0)) -> 1 | AA16: =IF(ISBLANK(AA14), 0, IF(AA$6 = 4, 1, 0)) -> 0 | AC16: =IF(ISBLANK(AC14), 0, IF(AC$6= 4, 1, 0)) -> 0 | AD16: =IF(ISBLANK(AD14), 0, IF(AD$6 = 4, 1, 0)) -> 1 | AE16: =IF(ISBLANK(AE14), 0, IF(AE$6= 4, 1, 0)) -> 0 | AF16: =IF(ISBLANK(AF14), 0, IF(AF$6 = 4, 1, 0)) -> 1 | AH16: =IF(ISBLANK(AH14), 0, IF(AH$6= 4, 1, 0)) -> 1 | AI16: =IF(ISBLANK(AI14), 0, IF(AI$6 = 4, 1, 0)) -> 0 | AK16: =SUM(C16:AI16) -> 12
B17: Prédiciton nb matchs | C17: =IF(C16 = 0, 0, IF(C14 = (C$6+D$6),1,0)) -> 0 | D17: =IF(D16 = 0, 0, IF(D14 = (C$6+D$6),1,0)) -> 0 | E17: =IF(E16 = 0, 0, IF(E14 = (E$6+F$6),1,0)) -> 0 | F17: =IF(F16 = 0, 0, IF(F14 = (E$6+F$6),1,0)) -> 0 | G17: =IF(G16 = 0, 0, IF(G14 = (G$6+H$6),1,0)) -> 0 | H17: =IF(H16 = 0, 0, IF(H14 = (G$6+H$6),1,0)) -> 0 | I17: =IF(I16 = 0, 0, IF(I14 = (I$6+J$6),1,0)) -> 0 | J17: =IF(J16 = 0, 0, IF(J14 = (I$6+J$6),1,0)) -> 0 | K17: =IF(K16 = 0, 0, IF(K14 = (K$6+L$6),1,0)) -> 0 | L17: =IF(L16 = 0, 0, IF(L14 = (K$6+L$6),1,0)) -> 0 | M17: =IF(M16 = 0, 0, IF(M14 = (M$6+N$6),1,0)) -> 0 | N17: =IF(N16 = 0, 0, IF(N14 = (M$6+N$6),1,0)) -> 0 | O17: =IF(O16 = 0, 0, IF(O14 = (O$6+P$6),1,0)) -> 0 | P17: =IF(P16 = 0, 0, IF(P14 = (O$6+P$6),1,0)) -> 0 | Q17: =IF(Q16 = 0, 0, IF(Q14 = (Q$6+R$6),1,0)) -> 0 | R17: =IF(R16 = 0, 0, IF(R14 = (Q$6+R$6),1,0)) -> 0 | T17: =IF(T16 = 0, 0, IF(T14 = (T$6+U$6),1,0)) -> 0 | U17: =IF(U16 = 0, 0, IF(U14 = (T$6+U$6),1,0)) -> 0 | V17: =IF(V16 = 0, 0, IF(V14 = (V$6+W$6),1,0)) -> 0 | W17: =IF(W16 = 0, 0, IF(W14 = (V$6+W$6),1,0)) -> 0 | X17: =IF(X16 = 0, 0, IF(X14 = (X$6+Y$6),1,0)) -> 0 | Y17: =IF(Y16 = 0, 0, IF(Y14 = (X$6+Y$6),1,0)) -> 1 | Z17: =IF(Z16 = 0, 0, IF(Z14 = (Z$6+AA$6),1,0)) -> 0 | AA17: =IF(AA16 = 0, 0, IF(AA14 = (Z$6+AA$6),1,0)) -> 0 | AC17: =IF(AC16 = 0, 0, IF(AC14 = (AC$6+AD$6),1,0)) -> 0 | AD17: =IF(AD16 = 0, 0, IF(AD14 = (AC$6+AD$6),1,0)) -> 0 | AE17: =IF(AE16 = 0, 0, IF(AE14 = (AE$6+AF$6),1,0)) -> 0 | AF17: =IF(AF16 = 0, 0, IF(AF14 = (AE$6+AF$6),1,0)) -> 0 | AH17: =IF(AH16 = 0, 0, IF(AH14 = (AH$6+AI$6),1,0)) -> 0 | AI17: =IF(AI16 = 0, 0, IF(AI14 = (AH$6+AI$6),1,0)) -> 0 | AK17: =SUM(C17:AI17) -> 1
A18: =RANK(AL18,$AL$10:$AL$82,) -> 3 | B18: Frédéric Lacerte | C18: 5 | E18: 7 | G18: 6 | I18: 7 | K18: 4 | M18: 5 | O18: 7 | R18: 5 | S18: =SUM(C19:R19) -> 80 | T18: 7 | V18: 7 | X18: 7 | Z18: 7 | AB18: =SUM(T19:AA19) -> 45 | AD18: 6 | AF18: 7 | AG18: =SUM(AC19:AF19) -> 38 | AI18: 6 | AJ18: =AH19 -> 1 | AK18: =MAX($AL$10:$AL$82) - AL18 -> 5 | AL18: =$S18+$AB18+$AG18+$AJ18 -> 164
A19: =RANK(AL19,$AL$10:$AL$82,) -> #N/A | C19: =(IF($C18<>"",($C$6*$O$92)+IF($C$6=4,($O$90)+IF($C18=$C$6+$D$6,$O$91,0),0),0)+IF($D18<>"",($D$6*$O$92)+IF($D$6=4,($O$90)+IF($D18=$C$6+$D$6,$O$91,0),0),0)) -> 11 | E19: =(IF($E18<>"",($E$6*$O$92)+IF($E$6=4,($O$90)+IF($E18=$E$6+$F$6,$O$91,0),0),0)+IF($F18<>"",($F$6*$O$92)+IF($F$6=4,($O$90)+IF($F18=$E$6+$F$6,$O$91,0),0),0)) -> 11 | G19: =(IF($G18<>"",($G$6*$O$92)+IF($G$6=4,($O$90)+IF($G18=$G$6+$H$6,$O$91,0),0),0)+IF($H18<>"",($H$6*$O$92)+IF($H$6=4,($O$90)+IF($H18=$G$6+$H$6,$O$91,0),0),0)) -> 11 | I19: =(IF($I18<>"",($I$6*$O$92)+IF($I$6=4,($O$90)+IF($I18=$I$6+$J$6,$O$91,0),0),0)+IF($J18<>"",($J$6*$O$92)+IF($J$6=4,($O$90)+IF($J18=$I$6+$J$6,$O$91,0),0),0)) -> 9 | K19: =(IF($K18<>"",($K$6*$O$92)+IF($K$6=4,($O$90)+IF($K18=$K$6+$L$6,$O$91,0),0),0)+IF($L18<>"",($L$6*$O$92)+IF($L$6=4,($O$90)+IF($L18=$K$6+$L$6,$O$91,0),0),0)) -> 9 | M19: =(IF($M18<>"",($M$6*$O$92)+IF($M$6=4,($O$90)+IF($M18=$M$6+$N$6,$O$91,0),0),0)+IF($N18<>"",($N$6*$O$92)+IF($N$6=4,($O$90)+IF($N18=$M$6+$N$6,$O$91,0),0),0)) -> 11 | O19: =(IF($O18<>"",($O$6*$O$92)+IF($O$6=4,($O$90)+IF($O18=$O$6+$P$6,$O$91,0),0),0)+IF($P18<>"",($P$6*$O$92)+IF($P$6=4,($O$90)+IF($P18=$O$6+$P$6,$O$91,0),0),0)) -> 9 | Q19: =(IF($Q18<>"",($Q$6*$O$92)+IF($Q$6=4,($O$90)+IF($Q18=$Q$6+$R$6,$O$91,0),0),0)+IF($R18<>"",($R$6*$O$92)+IF($R$6=4,($O$90)+IF($R18=$Q$6+$R$6,$O$91,0),0),0)) -> 9 | T19: =(IF($T18<>"",($T$6*$P$92)+IF($T$6=4,($P$90)+IF($T18=$T$6+$U$6,$P$91,0),0),0)+IF($U18<>"",($U$6*$P$92)+IF($U$6=4,($P$90)+IF($U18=$T$6+$U$6,$P$91,0),0),0)) -> 14 | V19: =(IF($V18<>"",($V$6*$P$92)+IF($V$6=4,($P$90)+IF($V18=$V$6+$W$6,$P$91,0),0),0)+IF($W18<>"",($W$6*$P$92)+IF($W$6=4,($P$90)+IF($W18=$V$6+$W$6,$P$91,0),0),0)) -> 14 | X19: =(IF($X18<>"",($X$6*$P$92)+IF($X$6=4,($P$90)+IF($X18=$X$6+$Y$6,$P$91,0),0),0)+IF($Y18<>"",($Y$6*$P$92)+IF($Y$6=4,($P$90)+IF($Y18=$X$6+$Y$6,$P$91,0),0),0)) -> 3 | Z19: =(IF($Z18<>"",($Z$6*$P$92)+IF($Z$6=4,($P$90)+IF($Z18=$Z$6+$AA$6,$P$91,0),0),0)+IF($AA18<>"",($AA$6*$P$92)+IF($AA$6=4,($P$90)+IF($AA18=$Z$6+$AA$6,$P$91,0),0),0)) -> 14 | AC19: =(IF($AC18<>"",($AC$6*$Q$92)+IF($AC$6=4,($Q$90)+IF($AC18=$AC$6+$AD$6,$Q$91,0),0),0)+IF($AD18<>"",($AD$6*$Q$92)+IF($AD$6=4,($Q$90)+IF($AD18=$AC$6+$AD$6,$Q$91,0),0),0)) -> 19 | AE19: =(IF($AE18<>"",($AE$6*$Q$92)+IF($AE$6=4,($Q$90)+IF($AE18=$AE$6+$AF$6,$Q$91,0),0),0)+IF($AF18<>"",($AF$6*$Q$92)+IF($AF$6=4,($Q$90)+IF($AF18=$AE$6+$AF$6,$Q$91,0),0),0)) -> 19 | AH19: =(IF($AH18<>"",($AH$6*$R$92)+IF($AH$6=4,($R$90)+IF($AH18=$AH$6+$AI$6,$R$91,0),0),0)+IF($AI18<>"",($AI$6*$R$92)+IF($AI$6=4,($R$90)+IF($AI18=$AH$6+$AI$6,$R$91,0),0),0)) -> 1 | AK19: =MAX($AL$10:$AL$82) - AL19 -> 169
B20: Prédiction équipe | C20: =IF(ISBLANK(C18), 0, IF(C$6= 4, 1, 0)) -> 1 | D20: =IF(ISBLANK(D18), 0, IF(D$6 = 4, 1, 0)) -> 0 | E20: =IF(ISBLANK(E18), 0, IF(E$6= 4, 1, 0)) -> 1 | F20: =IF(ISBLANK(F18), 0, IF(F$6 = 4, 1, 0)) -> 0 | G20: =IF(ISBLANK(G18), 0, IF(G$6= 4, 1, 0)) -> 1 | H20: =IF(ISBLANK(H18), 0, IF(H$6 = 4, 1, 0)) -> 0 | I20: =IF(ISBLANK(I18), 0, IF(I$6= 4, 1, 0)) -> 1 | J20: =IF(ISBLANK(J18), 0, IF(J$6 = 4, 1, 0)) -> 0 | K20: =IF(ISBLANK(K18), 0, IF(K$6= 4, 1, 0)) -> 1 | L20: =IF(ISBLANK(L18), 0, IF(L$6 = 4, 1, 0)) -> 0 | M20: =IF(ISBLANK(M18), 0, IF(M$6= 4, 1, 0)) -> 1 | N20: =IF(ISBLANK(N18), 0, IF(N$6 = 4, 1, 0)) -> 0 | O20: =IF(ISBLANK(O18), 0, IF(O$6= 4, 1, 0)) -> 1 | P20: =IF(ISBLANK(P18), 0, IF(P$6 = 4, 1, 0)) -> 0 | Q20: =IF(ISBLANK(Q18), 0, IF(Q$6= 4, 1, 0)) -> 0 | R20: =IF(ISBLANK(R18), 0, IF(R$6 = 4, 1, 0)) -> 1 | T20: =IF(ISBLANK(T18), 0, IF(T$6= 4, 1, 0)) -> 1 | U20: =IF(ISBLANK(U18), 0, IF(U$6 = 4, 1, 0)) -> 0 | V20: =IF(ISBLANK(V18), 0, IF(V$6= 4, 1, 0)) -> 1 | W20: =IF(ISBLANK(W18), 0, IF(W$6 = 4, 1, 0)) -> 0 | X20: =IF(ISBLANK(X18), 0, IF(X$6= 4, 1, 0)) -> 0 | Y20: =IF(ISBLANK(Y18), 0, IF(Y$6 = 4, 1, 0)) -> 0 | Z20: =IF(ISBLANK(Z18), 0, IF(Z$6= 4, 1, 0)) -> 1 | AA20: =IF(ISBLANK(AA18), 0, IF(AA$6 = 4, 1, 0)) -> 0 | AC20: =IF(ISBLANK(AC18), 0, IF(AC$6= 4, 1, 0)) -> 0 | AD20: =IF(ISBLANK(AD18), 0, IF(AD$6 = 4, 1, 0)) -> 1 | AE20: =IF(ISBLANK(AE18), 0, IF(AE$6= 4, 1, 0)) -> 0 | AF20: =IF(ISBLANK(AF18), 0, IF(AF$6 = 4, 1, 0)) -> 1 | AH20: =IF(ISBLANK(AH18), 0, IF(AH$6= 4, 1, 0)) -> 0 | AI20: =IF(ISBLANK(AI18), 0, IF(AI$6 = 4, 1, 0)) -> 0 | AK20: =SUM(C20:AI20) -> 13
B21: Prédiciton nb matchs | C21: =IF(C20 = 0, 0, IF(C18 = (C$6+D$6),1,0)) -> 1 | D21: =IF(D20 = 0, 0, IF(D18 = (C$6+D$6),1,0)) -> 0 | E21: =IF(E20 = 0, 0, IF(E18 = (E$6+F$6),1,0)) -> 1 | F21: =IF(F20 = 0, 0, IF(F18 = (E$6+F$6),1,0)) -> 0 | G21: =IF(G20 = 0, 0, IF(G18 = (G$6+H$6),1,0)) -> 1 | H21: =IF(H20 = 0, 0, IF(H18 = (G$6+H$6),1,0)) -> 0 | I21: =IF(I20 = 0, 0, IF(I18 = (I$6+J$6),1,0)) -> 0 | J21: =IF(J20 = 0, 0, IF(J18 = (I$6+J$6),1,0)) -> 0 | K21: =IF(K20 = 0, 0, IF(K18 = (K$6+L$6),1,0)) -> 0 | L21: =IF(L20 = 0, 0, IF(L18 = (K$6+L$6),1,0)) -> 0 | M21: =IF(M20 = 0, 0, IF(M18 = (M$6+N$6),1,0)) -> 1 | N21: =IF(N20 = 0, 0, IF(N18 = (M$6+N$6),1,0)) -> 0 | O21: =IF(O20 = 0, 0, IF(O18 = (O$6+P$6),1,0)) -> 0 | P21: =IF(P20 = 0, 0, IF(P18 = (O$6+P$6),1,0)) -> 0 | Q21: =IF(Q20 = 0, 0, IF(Q18 = (Q$6+R$6),1,0)) -> 0 | R21: =IF(R20 = 0, 0, IF(R18 = (Q$6+R$6),1,0)) -> 0 | T21: =IF(T20 = 0, 0, IF(T18 = (T$6+U$6),1,0)) -> 0 | U21: =IF(U20 = 0, 0, IF(U18 = (T$6+U$6),1,0)) -> 0 | V21: =IF(V20 = 0, 0, IF(V18 = (V$6+W$6),1,0)) -> 0 | W21: =IF(W20 = 0, 0, IF(W18 = (V$6+W$6),1,0)) -> 0 | X21: =IF(X20 = 0, 0, IF(X18 = (X$6+Y$6),1,0)) -> 0 | Y21: =IF(Y20 = 0, 0, IF(Y18 = (X$6+Y$6),1,0)) -> 0 | Z21: =IF(Z20 = 0, 0, IF(Z18 = (Z$6+AA$6),1,0)) -> 0 | AA21: =IF(AA20 = 0, 0, IF(AA18 = (Z$6+AA$6),1,0)) -> 0 | AC21: =IF(AC20 = 0, 0, IF(AC18 = (AC$6+AD$6),1,0)) -> 0 | AD21: =IF(AD20 = 0, 0, IF(AD18 = (AC$6+AD$6),1,0)) -> 0 | AE21: =IF(AE20 = 0, 0, IF(AE18 = (AE$6+AF$6),1,0)) -> 0 | AF21: =IF(AF20 = 0, 0, IF(AF18 = (AE$6+AF$6),1,0)) -> 0 | AH21: =IF(AH20 = 0, 0, IF(AH18 = (AH$6+AI$6),1,0)) -> 0 | AI21: =IF(AI20 = 0, 0, IF(AI18 = (AH$6+AI$6),1,0)) -> 0 | AK21: =SUM(C21:AI21) -> 4
A22: =RANK(AL22,$AL$10:$AL$82,) -> 4 | B22: Denis Desjardins | C22: 5 | E22: 7 | G22: 6 | I22: 5 | K22: 6 | M22: 5 | P22: 7 | R22: 7 | S22: =SUM(C23:R23) -> 73 | T22: 7 | W22: 6 | Y22: 7 | Z22: 7 | AB22: =SUM(T23:AA23) -> 48 | AC22: 6 | AE22: 7 | AG22: =SUM(AC23:AF23) -> 4 | AH22: 6 | AJ22: =AH23 -> 24 | AK22: =MAX($AL$10:$AL$82) - AL22 -> 20 | AL22: =$S22+$AB22+$AG22+$AJ22 -> 149
A23: =RANK(AL23,$AL$10:$AL$82,) -> #N/A | C23: =(IF($C22<>"",($C$6*$O$92)+IF($C$6=4,($O$90)+IF($C22=$C$6+$D$6,$O$91,0),0),0)+IF($D22<>"",($D$6*$O$92)+IF($D$6=4,($O$90)+IF($D22=$C$6+$D$6,$O$91,0),0),0)) -> 11 | E23: =(IF($E22<>"",($E$6*$O$92)+IF($E$6=4,($O$90)+IF($E22=$E$6+$F$6,$O$91,0),0),0)+IF($F22<>"",($F$6*$O$92)+IF($F$6=4,($O$90)+IF($F22=$E$6+$F$6,$O$91,0),0),0)) -> 11 | G23: =(IF($G22<>"",($G$6*$O$92)+IF($G$6=4,($O$90)+IF($G22=$G$6+$H$6,$O$91,0),0),0)+IF($H22<>"",($H$6*$O$92)+IF($H$6=4,($O$90)+IF($H22=$G$6+$H$6,$O$91,0),0),0)) -> 11 | I23: =(IF($I22<>"",($I$6*$O$92)+IF($I$6=4,($O$90)+IF($I22=$I$6+$J$6,$O$91,0),0),0)+IF($J22<>"",($J$6*$O$92)+IF($J$6=4,($O$90)+IF($J22=$I$6+$J$6,$O$91,0),0),0)) -> 9 | K23: =(IF($K22<>"",($K$6*$O$92)+IF($K$6=4,($O$90)+IF($K22=$K$6+$L$6,$O$91,0),0),0)+IF($L22<>"",($L$6*$O$92)+IF($L$6=4,($O$90)+IF($L22=$K$6+$L$6,$O$91,0),0),0)) -> 11 | M23: =(IF($M22<>"",($M$6*$O$92)+IF($M$6=4,($O$90)+IF($M22=$M$6+$N$6,$O$91,0),0),0)+IF($N22<>"",($N$6*$O$92)+IF($N$6=4,($O$90)+IF($N22=$M$6+$N$6,$O$91,0),0),0)) -> 11 | O23: =(IF($O22<>"",($O$6*$O$92)+IF($O$6=4,($O$90)+IF($O22=$O$6+$P$6,$O$91,0),0),0)+IF($P22<>"",($P$6*$O$92)+IF($P$6=4,($O$90)+IF($P22=$O$6+$P$6,$O$91,0),0),0)) -> 0 | Q23: =(IF($Q22<>"",($Q$6*$O$92)+IF($Q$6=4,($O$90)+IF($Q22=$Q$6+$R$6,$O$91,0),0),0)+IF($R22<>"",($R$6*$O$92)+IF($R$6=4,($O$90)+IF($R22=$Q$6+$R$6,$O$91,0),0),0)) -> 9 | T23: =(IF($T22<>"",($T$6*$P$92)+IF($T$6=4,($P$90)+IF($T22=$T$6+$U$6,$P$91,0),0),0)+IF($U22<>"",($U$6*$P$92)+IF($U$6=4,($P$90)+IF($U22=$T$6+$U$6,$P$91,0),0),0)) -> 14 | V23: =(IF($V22<>"",($V$6*$P$92)+IF($V$6=4,($P$90)+IF($V22=$V$6+$W$6,$P$91,0),0),0)+IF($W22<>"",($W$6*$P$92)+IF($W$6=4,($P$90)+IF($W22=$V$6+$W$6,$P$91,0),0),0)) -> 2 | X23: =(IF($X22<>"",($X$6*$P$92)+IF($X$6=4,($P$90)+IF($X22=$X$6+$Y$6,$P$91,0),0),0)+IF($Y22<>"",($Y$6*$P$92)+IF($Y$6=4,($P$90)+IF($Y22=$X$6+$Y$6,$P$91,0),0),0)) -> 18 | Z23: =(IF($Z22<>"",($Z$6*$P$92)+IF($Z$6=4,($P$90)+IF($Z22=$Z$6+$AA$6,$P$91,0),0),0)+IF($AA22<>"",($AA$6*$P$92)+IF($AA$6=4,($P$90)+IF($AA22=$Z$6+$AA$6,$P$91,0),0),0)) -> 14 | AC23: =(IF($AC22<>"",($AC$6*$Q$92)+IF($AC$6=4,($Q$90)+IF($AC22=$AC$6+$AD$6,$Q$91,0),0),0)+IF($AD22<>"",($AD$6*$Q$92)+IF($AD$6=4,($Q$90)+IF($AD22=$AC$6+$AD$6,$Q$91,0),0),0)) -> 3 | AE23: =(IF($AE22<>"",($AE$6*$Q$92)+IF($AE$6=4,($Q$90)+IF($AE22=$AE$6+$AF$6,$Q$91,0),0),0)+IF($AF22<>"",($AF$6*$Q$92)+IF($AF$6=4,($Q$90)+IF($AF22=$AE$6+$AF$6,$Q$91,0),0),0)) -> 1 | AH23: =(IF($AH22<>"",($AH$6*$R$92)+IF($AH$6=4,($R$90)+IF($AH22=$AH$6+$AI$6,$R$91,0),0),0)+IF($AI22<>"",($AI$6*$R$92)+IF($AI$6=4,($R$90)+IF($AI22=$AH$6+$AI$6,$R$91,0),0),0)) -> 24 | AK23: =MAX($AL$10:$AL$82) - AL23 -> 169
B24: Prédiction équipe | C24: =IF(ISBLANK(C22), 0, IF(C$6= 4, 1, 0)) -> 1 | D24: =IF(ISBLANK(D22), 0, IF(D$6 = 4, 1, 0)) -> 0 | E24: =IF(ISBLANK(E22), 0, IF(E$6= 4, 1, 0)) -> 1 | F24: =IF(ISBLANK(F22), 0, IF(F$6 = 4, 1, 0)) -> 0 | G24: =IF(ISBLANK(G22), 0, IF(G$6= 4, 1, 0)) -> 1 | H24: =IF(ISBLANK(H22), 0, IF(H$6 = 4, 1, 0)) -> 0 | I24: =IF(ISBLANK(I22), 0, IF(I$6= 4, 1, 0)) -> 1 | J24: =IF(ISBLANK(J22), 0, IF(J$6 = 4, 1, 0)) -> 0 | K24: =IF(ISBLANK(K22), 0, IF(K$6= 4, 1, 0)) -> 1 | L24: =IF(ISBLANK(L22), 0, IF(L$6 = 4, 1, 0)) -> 0 | M24: =IF(ISBLANK(M22), 0, IF(M$6= 4, 1, 0)) -> 1 | N24: =IF(ISBLANK(N22), 0, IF(N$6 = 4, 1, 0)) -> 0 | O24: =IF(ISBLANK(O22), 0, IF(O$6= 4, 1, 0)) -> 0 | P24: =IF(ISBLANK(P22), 0, IF(P$6 = 4, 1, 0)) -> 0 | Q24: =IF(ISBLANK(Q22), 0, IF(Q$6= 4, 1, 0)) -> 0 | R24: =IF(ISBLANK(R22), 0, IF(R$6 = 4, 1, 0)) -> 1 | T24: =IF(ISBLANK(T22), 0, IF(T$6= 4, 1, 0)) -> 1 | U24: =IF(ISBLANK(U22), 0, IF(U$6 = 4, 1, 0)) -> 0 | V24: =IF(ISBLANK(V22), 0, IF(V$6= 4, 1, 0)) -> 0 | W24: =IF(ISBLANK(W22), 0, IF(W$6 = 4, 1, 0)) -> 0 | X24: =IF(ISBLANK(X22), 0, IF(X$6= 4, 1, 0)) -> 0 | Y24: =IF(ISBLANK(Y22), 0, IF(Y$6 = 4, 1, 0)) -> 1 | Z24: =IF(ISBLANK(Z22), 0, IF(Z$6= 4, 1, 0)) -> 1 | AA24: =IF(ISBLANK(AA22), 0, IF(AA$6 = 4, 1, 0)) -> 0 | AC24: =IF(ISBLANK(AC22), 0, IF(AC$6= 4, 1, 0)) -> 0 | AD24: =IF(ISBLANK(AD22), 0, IF(AD$6 = 4, 1, 0)) -> 0 | AE24: =IF(ISBLANK(AE22), 0, IF(AE$6= 4, 1, 0)) -> 0 | AF24: =IF(ISBLANK(AF22), 0, IF(AF$6 = 4, 1, 0)) -> 0 | AH24: =IF(ISBLANK(AH22), 0, IF(AH$6= 4, 1, 0)) -> 1 | AI24: =IF(ISBLANK(AI22), 0, IF(AI$6 = 4, 1, 0)) -> 0 | AK24: =SUM(C24:AI24) -> 11
B25: Prédiciton nb matchs | C25: =IF(C24 = 0, 0, IF(C22 = (C$6+D$6),1,0)) -> 1 | D25: =IF(D24 = 0, 0, IF(D22 = (C$6+D$6),1,0)) -> 0 | E25: =IF(E24 = 0, 0, IF(E22 = (E$6+F$6),1,0)) -> 1 | F25: =IF(F24 = 0, 0, IF(F22 = (E$6+F$6),1,0)) -> 0 | G25: =IF(G24 = 0, 0, IF(G22 = (G$6+H$6),1,0)) -> 1 | H25: =IF(H24 = 0, 0, IF(H22 = (G$6+H$6),1,0)) -> 0 | I25: =IF(I24 = 0, 0, IF(I22 = (I$6+J$6),1,0)) -> 0 | J25: =IF(J24 = 0, 0, IF(J22 = (I$6+J$6),1,0)) -> 0 | K25: =IF(K24 = 0, 0, IF(K22 = (K$6+L$6),1,0)) -> 1 | L25: =IF(L24 = 0, 0, IF(L22 = (K$6+L$6),1,0)) -> 0 | M25: =IF(M24 = 0, 0, IF(M22 = (M$6+N$6),1,0)) -> 1 | N25: =IF(N24 = 0, 0, IF(N22 = (M$6+N$6),1,0)) -> 0 | O25: =IF(O24 = 0, 0, IF(O22 = (O$6+P$6),1,0)) -> 0 | P25: =IF(P24 = 0, 0, IF(P22 = (O$6+P$6),1,0)) -> 0 | Q25: =IF(Q24 = 0, 0, IF(Q22 = (Q$6+R$6),1,0)) -> 0 | R25: =IF(R24 = 0, 0, IF(R22 = (Q$6+R$6),1,0)) -> 0 | T25: =IF(T24 = 0, 0, IF(T22 = (T$6+U$6),1,0)) -> 0 | U25: =IF(U24 = 0, 0, IF(U22 = (T$6+U$6),1,0)) -> 0 | V25: =IF(V24 = 0, 0, IF(V22 = (V$6+W$6),1,0)) -> 0 | W25: =IF(W24 = 0, 0, IF(W22 = (V$6+W$6),1,0)) -> 0 | X25: =IF(X24 = 0, 0, IF(X22 = (X$6+Y$6),1,0)) -> 0 | Y25: =IF(Y24 = 0, 0, IF(Y22 = (X$6+Y$6),1,0)) -> 1 | Z25: =IF(Z24 = 0, 0, IF(Z22 = (Z$6+AA$6),1,0)) -> 0 | AA25: =IF(AA24 = 0, 0, IF(AA22 = (Z$6+AA$6),1,0)) -> 0 | AC25: =IF(AC24 = 0, 0, IF(AC22 = (AC$6+AD$6),1,0)) -> 0 | AD25: =IF(AD24 = 0, 0, IF(AD22 = (AC$6+AD$6),1,0)) -> 0 | AE25: =IF(AE24 = 0, 0, IF(AE22 = (AE$6+AF$6),1,0)) -> 0 | AF25: =IF(AF24 = 0, 0, IF(AF22 = (AE$6+AF$6),1,0)) -> 0 | AH25: =IF(AH24 = 0, 0, IF(AH22 = (AH$6+AI$6),1,0)) -> 0 | AI25: =IF(AI24 = 0, 0, IF(AI22 = (AH$6+AI$6),1,0)) -> 0 | AK25: =SUM(C25:AI25) -> 6
A26: =RANK(AL26,$AL$10:$AL$82,) -> 5 | B26: Thanh Vinh Nguyen | C26: 5 | E26: 7 | G26: 6 | I26: 6 | K26: 4 | N26: 7 | O26: 6 | Q26: 6 | S26: =SUM(C27:R27) -> 63 | T26: 7 | W26: 7 | X26: 7 | Z26: 6 | AB26: =SUM(T27:AA27) -> 37 | AD26: 7 | AF26: 6 | AG26: =SUM(AC27:AF27) -> 44 | AI26: 6 | AJ26: =AH27 -> 1 | AK26: =MAX($AL$10:$AL$82) - AL26 -> 24 | AL26: =$S26+$AB26+$AG26+$AJ26 -> 145
A27: =RANK(AL27,$AL$10:$AL$82,) -> #N/A | C27: =(IF($C26<>"",($C$6*$O$92)+IF($C$6=4,($O$90)+IF($C26=$C$6+$D$6,$O$91,0),0),0)+IF($D26<>"",($D$6*$O$92)+IF($D$6=4,($O$90)+IF($D26=$C$6+$D$6,$O$91,0),0),0)) -> 11 | E27: =(IF($E26<>"",($E$6*$O$92)+IF($E$6=4,($O$90)+IF($E26=$E$6+$F$6,$O$91,0),0),0)+IF($F26<>"",($F$6*$O$92)+IF($F$6=4,($O$90)+IF($F26=$E$6+$F$6,$O$91,0),0),0)) -> 11 | G27: =(IF($G26<>"",($G$6*$O$92)+IF($G$6=4,($O$90)+IF($G26=$G$6+$H$6,$O$91,0),0),0)+IF($H26<>"",($H$6*$O$92)+IF($H$6=4,($O$90)+IF($H26=$G$6+$H$6,$O$91,0),0),0)) -> 11 | I27: =(IF($I26<>"",($I$6*$O$92)+IF($I$6=4,($O$90)+IF($I26=$I$6+$J$6,$O$91,0),0),0)+IF($J26<>"",($J$6*$O$92)+IF($J$6=4,($O$90)+IF($J26=$I$6+$J$6,$O$91,0),0),0)) -> 11 | K27: =(IF($K26<>"",($K$6*$O$92)+IF($K$6=4,($O$90)+IF($K26=$K$6+$L$6,$O$91,0),0),0)+IF($L26<>"",($L$6*$O$92)+IF($L$6=4,($O$90)+IF($L26=$K$6+$L$6,$O$91,0),0),0)) -> 9 | M27: =(IF($M26<>"",($M$6*$O$92)+IF($M$6=4,($O$90)+IF($M26=$M$6+$N$6,$O$91,0),0),0)+IF($N26<>"",($N$6*$O$92)+IF($N$6=4,($O$90)+IF($N26=$M$6+$N$6,$O$91,0),0),0)) -> 1 | O27: =(IF($O26<>"",($O$6*$O$92)+IF($O$6=4,($O$90)+IF($O26=$O$6+$P$6,$O$91,0),0),0)+IF($P26<>"",($P$6*$O$92)+IF($P$6=4,($O$90)+IF($P26=$O$6+$P$6,$O$91,0),0),0)) -> 9 | Q27: =(IF($Q26<>"",($Q$6*$O$92)+IF($Q$6=4,($O$90)+IF($Q26=$Q$6+$R$6,$O$91,0),0),0)+IF($R26<>"",($R$6*$O$92)+IF($R$6=4,($O$90)+IF($R26=$Q$6+$R$6,$O$91,0),0),0)) -> 0 | T27: =(IF($T26<>"",($T$6*$P$92)+IF($T$6=4,($P$90)+IF($T26=$T$6+$U$6,$P$91,0),0),0)+IF($U26<>"",($U$6*$P$92)+IF($U$6=4,($P$90)+IF($U26=$T$6+$U$6,$P$91,0),0),0)) -> 14 | V27: =(IF($V26<>"",($V$6*$P$92)+IF($V$6=4,($P$90)+IF($V26=$V$6+$W$6,$P$91,0),0),0)+IF($W26<>"",($W$6*$P$92)+IF($W$6=4,($P$90)+IF($W26=$V$6+$W$6,$P$91,0),0),0)) -> 2 | X27: =(IF($X26<>"",($X$6*$P$92)+IF($X$6=4,($P$90)+IF($X26=$X$6+$Y$6,$P$91,0),0),0)+IF($Y26<>"",($Y$6*$P$92)+IF($Y$6=4,($P$90)+IF($Y26=$X$6+$Y$6,$P$91,0),0),0)) -> 3 | Z27: =(IF($Z26<>"",($Z$6*$P$92)+IF($Z$6=4,($P$90)+IF($Z26=$Z$6+$AA$6,$P$91,0),0),0)+IF($AA26<>"",($AA$6*$P$92)+IF($AA$6=4,($P$90)+IF($AA26=$Z$6+$AA$6,$P$91,0),0),0)) -> 18 | AC27: =(IF($AC26<>"",($AC$6*$Q$92)+IF($AC$6=4,($Q$90)+IF($AC26=$AC$6+$AD$6,$Q$91,0),0),0)+IF($AD26<>"",($AD$6*$Q$92)+IF($AD$6=4,($Q$90)+IF($AD26=$AC$6+$AD$6,$Q$91,0),0),0)) -> 25 | AE27: =(IF($AE26<>"",($AE$6*$Q$92)+IF($AE$6=4,($Q$90)+IF($AE26=$AE$6+$AF$6,$Q$91,0),0),0)+IF($AF26<>"",($AF$6*$Q$92)+IF($AF$6=4,($Q$90)+IF($AF26=$AE$6+$AF$6,$Q$91,0),0),0)) -> 19 | AH27: =(IF($AH26<>"",($AH$6*$R$92)+IF($AH$6=4,($R$90)+IF($AH26=$AH$6+$AI$6,$R$91,0),0),0)+IF($AI26<>"",($AI$6*$R$92)+IF($AI$6=4,($R$90)+IF($AI26=$AH$6+$AI$6,$R$91,0),0),0)) -> 1 | AK27: =MAX($AL$10:$AL$82) - AL27 -> 169
B28: Prédiction équipe | C28: =IF(ISBLANK(C26), 0, IF(C$6= 4, 1, 0)) -> 1 | D28: =IF(ISBLANK(D26), 0, IF(D$6 = 4, 1, 0)) -> 0 | E28: =IF(ISBLANK(E26), 0, IF(E$6= 4, 1, 0)) -> 1 | F28: =IF(ISBLANK(F26), 0, IF(F$6 = 4, 1, 0)) -> 0 | G28: =IF(ISBLANK(G26), 0, IF(G$6= 4, 1, 0)) -> 1 | H28: =IF(ISBLANK(H26), 0, IF(H$6 = 4, 1, 0)) -> 0 | I28: =IF(ISBLANK(I26), 0, IF(I$6= 4, 1, 0)) -> 1 | J28: =IF(ISBLANK(J26), 0, IF(J$6 = 4, 1, 0)) -> 0 | K28: =IF(ISBLANK(K26), 0, IF(K$6= 4, 1, 0)) -> 1 | L28: =IF(ISBLANK(L26), 0, IF(L$6 = 4, 1, 0)) -> 0 | M28: =IF(ISBLANK(M26), 0, IF(M$6= 4, 1, 0)) -> 0 | N28: =IF(ISBLANK(N26), 0, IF(N$6 = 4, 1, 0)) -> 0 | O28: =IF(ISBLANK(O26), 0, IF(O$6= 4, 1, 0)) -> 1 | P28: =IF(ISBLANK(P26), 0, IF(P$6 = 4, 1, 0)) -> 0 | Q28: =IF(ISBLANK(Q26), 0, IF(Q$6= 4, 1, 0)) -> 0 | R28: =IF(ISBLANK(R26), 0, IF(R$6 = 4, 1, 0)) -> 0 | T28: =IF(ISBLANK(T26), 0, IF(T$6= 4, 1, 0)) -> 1 | U28: =IF(ISBLANK(U26), 0, IF(U$6 = 4, 1, 0)) -> 0 | V28: =IF(ISBLANK(V26), 0, IF(V$6= 4, 1, 0)) -> 0 | W28: =IF(ISBLANK(W26), 0, IF(W$6 = 4, 1, 0)) -> 0 | X28: =IF(ISBLANK(X26), 0, IF(X$6= 4, 1, 0)) -> 0 | Y28: =IF(ISBLANK(Y26), 0, IF(Y$6 = 4, 1, 0)) -> 0 | Z28: =IF(ISBLANK(Z26), 0, IF(Z$6= 4, 1, 0)) -> 1 | AA28: =IF(ISBLANK(AA26), 0, IF(AA$6 = 4, 1, 0)) -> 0 | AC28: =IF(ISBLANK(AC26), 0, IF(AC$6= 4, 1, 0)) -> 0 | AD28: =IF(ISBLANK(AD26), 0, IF(AD$6 = 4, 1, 0)) -> 1 | AE28: =IF(ISBLANK(AE26), 0, IF(AE$6= 4, 1, 0)) -> 0 | AF28: =IF(ISBLANK(AF26), 0, IF(AF$6 = 4, 1, 0)) -> 1 | AH28: =IF(ISBLANK(AH26), 0, IF(AH$6= 4, 1, 0)) -> 0 | AI28: =IF(ISBLANK(AI26), 0, IF(AI$6 = 4, 1, 0)) -> 0 | AK28: =SUM(C28:AI28) -> 10
B29: Prédiciton nb matchs | C29: =IF(C28 = 0, 0, IF(C26 = (C$6+D$6),1,0)) -> 1 | D29: =IF(D28 = 0, 0, IF(D26 = (C$6+D$6),1,0)) -> 0 | E29: =IF(E28 = 0, 0, IF(E26 = (E$6+F$6),1,0)) -> 1 | F29: =IF(F28 = 0, 0, IF(F26 = (E$6+F$6),1,0)) -> 0 | G29: =IF(G28 = 0, 0, IF(G26 = (G$6+H$6),1,0)) -> 1 | H29: =IF(H28 = 0, 0, IF(H26 = (G$6+H$6),1,0)) -> 0 | I29: =IF(I28 = 0, 0, IF(I26 = (I$6+J$6),1,0)) -> 1 | J29: =IF(J28 = 0, 0, IF(J26 = (I$6+J$6),1,0)) -> 0 | K29: =IF(K28 = 0, 0, IF(K26 = (K$6+L$6),1,0)) -> 0 | L29: =IF(L28 = 0, 0, IF(L26 = (K$6+L$6),1,0)) -> 0 | M29: =IF(M28 = 0, 0, IF(M26 = (M$6+N$6),1,0)) -> 0 | N29: =IF(N28 = 0, 0, IF(N26 = (M$6+N$6),1,0)) -> 0 | O29: =IF(O28 = 0, 0, IF(O26 = (O$6+P$6),1,0)) -> 0 | P29: =IF(P28 = 0, 0, IF(P26 = (O$6+P$6),1,0)) -> 0 | Q29: =IF(Q28 = 0, 0, IF(Q26 = (Q$6+R$6),1,0)) -> 0 | R29: =IF(R28 = 0, 0, IF(R26 = (Q$6+R$6),1,0)) -> 0 | T29: =IF(T28 = 0, 0, IF(T26 = (T$6+U$6),1,0)) -> 0 | U29: =IF(U28 = 0, 0, IF(U26 = (T$6+U$6),1,0)) -> 0 | V29: =IF(V28 = 0, 0, IF(V26 = (V$6+W$6),1,0)) -> 0 | W29: =IF(W28 = 0, 0, IF(W26 = (V$6+W$6),1,0)) -> 0 | X29: =IF(X28 = 0, 0, IF(X26 = (X$6+Y$6),1,0)) -> 0 | Y29: =IF(Y28 = 0, 0, IF(Y26 = (X$6+Y$6),1,0)) -> 0 | Z29: =IF(Z28 = 0, 0, IF(Z26 = (Z$6+AA$6),1,0)) -> 1 | AA29: =IF(AA28 = 0, 0, IF(AA26 = (Z$6+AA$6),1,0)) -> 0 | AC29: =IF(AC28 = 0, 0, IF(AC26 = (AC$6+AD$6),1,0)) -> 0 | AD29: =IF(AD28 = 0, 0, IF(AD26 = (AC$6+AD$6),1,0)) -> 1 | AE29: =IF(AE28 = 0, 0, IF(AE26 = (AE$6+AF$6),1,0)) -> 0 | AF29: =IF(AF28 = 0, 0, IF(AF26 = (AE$6+AF$6),1,0)) -> 0 | AH29: =IF(AH28 = 0, 0, IF(AH26 = (AH$6+AI$6),1,0)) -> 0 | AI29: =IF(AI28 = 0, 0, IF(AI26 = (AH$6+AI$6),1,0)) -> 0 | AK29: =SUM(C29:AI29) -> 6
A30: =RANK(AL30,$AL$10:$AL$82,) -> 6 | B30: Alexandre Levac | C30: 6 | E30: 5 | G30: 7 | I30: 6 | K30: 5 | M30: 7 | P30: 6 | Q30: 7 | S30: =SUM(C31:R31) -> 56 | T30: 7 | V30: 7 | Y30: 6 | AA30: 6 | AB30: =SUM(T31:AA31) -> 44 | AD30: 6 | AE30: 7 | AG30: =SUM(AC31:AF31) -> 20 | AH30: 4 | AJ30: =AH31 -> 24 | AK30: =MAX($AL$10:$AL$82) - AL30 -> 25 | AL30: =$S30+$AB30+$AG30+$AJ30 -> 144
A31: =RANK(AL31,$AL$10:$AL$82,) -> #N/A | C31: =(IF($C30<>"",($C$6*$O$92)+IF($C$6=4,($O$90)+IF($C30=$C$6+$D$6,$O$91,0),0),0)+IF($D30<>"",($D$6*$O$92)+IF($D$6=4,($O$90)+IF($D30=$C$6+$D$6,$O$91,0),0),0)) -> 9 | E31: =(IF($E30<>"",($E$6*$O$92)+IF($E$6=4,($O$90)+IF($E30=$E$6+$F$6,$O$91,0),0),0)+IF($F30<>"",($F$6*$O$92)+IF($F$6=4,($O$90)+IF($F30=$E$6+$F$6,$O$91,0),0),0)) -> 9 | G31: =(IF($G30<>"",($G$6*$O$92)+IF($G$6=4,($O$90)+IF($G30=$G$6+$H$6,$O$91,0),0),0)+IF($H30<>"",($H$6*$O$92)+IF($H$6=4,($O$90)+IF($H30=$G$6+$H$6,$O$91,0),0),0)) -> 9 | I31: =(IF($I30<>"",($I$6*$O$92)+IF($I$6=4,($O$90)+IF($I30=$I$6+$J$6,$O$91,0),0),0)+IF($J30<>"",($J$6*$O$92)+IF($J$6=4,($O$90)+IF($J30=$I$6+$J$6,$O$91,0),0),0)) -> 11 | K31: =(IF($K30<>"",($K$6*$O$92)+IF($K$6=4,($O$90)+IF($K30=$K$6+$L$6,$O$91,0),0),0)+IF($L30<>"",($L$6*$O$92)+IF($L$6=4,($O$90)+IF($L30=$K$6+$L$6,$O$91,0),0),0)) -> 9 | M31: =(IF($M30<>"",($M$6*$O$92)+IF($M$6=4,($O$90)+IF($M30=$M$6+$N$6,$O$91,0),0),0)+IF($N30<>"",($N$6*$O$92)+IF($N$6=4,($O$90)+IF($N30=$M$6+$N$6,$O$91,0),0),0)) -> 9 | O31: =(IF($O30<>"",($O$6*$O$92)+IF($O$6=4,($O$90)+IF($O30=$O$6+$P$6,$O$91,0),0),0)+IF($P30<>"",($P$6*$O$92)+IF($P$6=4,($O$90)+IF($P30=$O$6+$P$6,$O$91,0),0),0)) -> 0 | Q31: =(IF($Q30<>"",($Q$6*$O$92)+IF($Q$6=4,($O$90)+IF($Q30=$Q$6+$R$6,$O$91,0),0),0)+IF($R30<>"",($R$6*$O$92)+IF($R$6=4,($O$90)+IF($R30=$Q$6+$R$6,$O$91,0),0),0)) -> 0 | T31: =(IF($T30<>"",($T$6*$P$92)+IF($T$6=4,($P$90)+IF($T30=$T$6+$U$6,$P$91,0),0),0)+IF($U30<>"",($U$6*$P$92)+IF($U$6=4,($P$90)+IF($U30=$T$6+$U$6,$P$91,0),0),0)) -> 14 | V31: =(IF($V30<>"",($V$6*$P$92)+IF($V$6=4,($P$90)+IF($V30=$V$6+$W$6,$P$91,0),0),0)+IF($W30<>"",($W$6*$P$92)+IF($W$6=4,($P$90)+IF($W30=$V$6+$W$6,$P$91,0),0),0)) -> 14 | X31: =(IF($X30<>"",($X$6*$P$92)+IF($X$6=4,($P$90)+IF($X30=$X$6+$Y$6,$P$91,0),0),0)+IF($Y30<>"",($Y$6*$P$92)+IF($Y$6=4,($P$90)+IF($Y30=$X$6+$Y$6,$P$91,0),0),0)) -> 14 | Z31: =(IF($Z30<>"",($Z$6*$P$92)+IF($Z$6=4,($P$90)+IF($Z30=$Z$6+$AA$6,$P$91,0),0),0)+IF($AA30<>"",($AA$6*$P$92)+IF($AA$6=4,($P$90)+IF($AA30=$Z$6+$AA$6,$P$91,0),0),0)) -> 2 | AC31: =(IF($AC30<>"",($AC$6*$Q$92)+IF($AC$6=4,($Q$90)+IF($AC30=$AC$6+$AD$6,$Q$91,0),0),0)+IF($AD30<>"",($AD$6*$Q$92)+IF($AD$6=4,($Q$90)+IF($AD30=$AC$6+$AD$6,$Q$91,0),0),0)) -> 19 | AE31: =(IF($AE30<>"",($AE$6*$Q$92)+IF($AE$6=4,($Q$90)+IF($AE30=$AE$6+$AF$6,$Q$91,0),0),0)+IF($AF30<>"",($AF$6*$Q$92)+IF($AF$6=4,($Q$90)+IF($AF30=$AE$6+$AF$6,$Q$91,0),0),0)) -> 1 | AH31: =(IF($AH30<>"",($AH$6*$R$92)+IF($AH$6=4,($R$90)+IF($AH30=$AH$6+$AI$6,$R$91,0),0),0)+IF($AI30<>"",($AI$6*$R$92)+IF($AI$6=4,($R$90)+IF($AI30=$AH$6+$AI$6,$R$91,0),0),0)) -> 24 | AK31: =MAX($AL$10:$AL$82) - AL31 -> 169
B32: Prédiction équipe | C32: =IF(ISBLANK(C30), 0, IF(C$6= 4, 1, 0)) -> 1 | D32: =IF(ISBLANK(D30), 0, IF(D$6 = 4, 1, 0)) -> 0 | E32: =IF(ISBLANK(E30), 0, IF(E$6= 4, 1, 0)) -> 1 | F32: =IF(ISBLANK(F30), 0, IF(F$6 = 4, 1, 0)) -> 0 | G32: =IF(ISBLANK(G30), 0, IF(G$6= 4, 1, 0)) -> 1 | H32: =IF(ISBLANK(H30), 0, IF(H$6 = 4, 1, 0)) -> 0 | I32: =IF(ISBLANK(I30), 0, IF(I$6= 4, 1, 0)) -> 1 | J32: =IF(ISBLANK(J30), 0, IF(J$6 = 4, 1, 0)) -> 0 | K32: =IF(ISBLANK(K30), 0, IF(K$6= 4, 1, 0)) -> 1 | L32: =IF(ISBLANK(L30), 0, IF(L$6 = 4, 1, 0)) -> 0 | M32: =IF(ISBLANK(M30), 0, IF(M$6= 4, 1, 0)) -> 1 | N32: =IF(ISBLANK(N30), 0, IF(N$6 = 4, 1, 0)) -> 0 | O32: =IF(ISBLANK(O30), 0, IF(O$6= 4, 1, 0)) -> 0 | P32: =IF(ISBLANK(P30), 0, IF(P$6 = 4, 1, 0)) -> 0 | Q32: =IF(ISBLANK(Q30), 0, IF(Q$6= 4, 1, 0)) -> 0 | R32: =IF(ISBLANK(R30), 0, IF(R$6 = 4, 1, 0)) -> 0 | T32: =IF(ISBLANK(T30), 0, IF(T$6= 4, 1, 0)) -> 1 | U32: =IF(ISBLANK(U30), 0, IF(U$6 = 4, 1, 0)) -> 0 | V32: =IF(ISBLANK(V30), 0, IF(V$6= 4, 1, 0)) -> 1 | W32: =IF(ISBLANK(W30), 0, IF(W$6 = 4, 1, 0)) -> 0 | X32: =IF(ISBLANK(X30), 0, IF(X$6= 4, 1, 0)) -> 0 | Y32: =IF(ISBLANK(Y30), 0, IF(Y$6 = 4, 1, 0)) -> 1 | Z32: =IF(ISBLANK(Z30), 0, IF(Z$6= 4, 1, 0)) -> 0 | AA32: =IF(ISBLANK(AA30), 0, IF(AA$6 = 4, 1, 0)) -> 0 | AC32: =IF(ISBLANK(AC30), 0, IF(AC$6= 4, 1, 0)) -> 0 | AD32: =IF(ISBLANK(AD30), 0, IF(AD$6 = 4, 1, 0)) -> 1 | AE32: =IF(ISBLANK(AE30), 0, IF(AE$6= 4, 1, 0)) -> 0 | AF32: =IF(ISBLANK(AF30), 0, IF(AF$6 = 4, 1, 0)) -> 0 | AH32: =IF(ISBLANK(AH30), 0, IF(AH$6= 4, 1, 0)) -> 1 | AI32: =IF(ISBLANK(AI30), 0, IF(AI$6 = 4, 1, 0)) -> 0 | AK32: =SUM(C32:AI32) -> 11
B33: Prédiciton nb matchs | C33: =IF(C32 = 0, 0, IF(C30 = (C$6+D$6),1,0)) -> 0 | D33: =IF(D32 = 0, 0, IF(D30 = (C$6+D$6),1,0)) -> 0 | E33: =IF(E32 = 0, 0, IF(E30 = (E$6+F$6),1,0)) -> 0 | F33: =IF(F32 = 0, 0, IF(F30 = (E$6+F$6),1,0)) -> 0 | G33: =IF(G32 = 0, 0, IF(G30 = (G$6+H$6),1,0)) -> 0 | H33: =IF(H32 = 0, 0, IF(H30 = (G$6+H$6),1,0)) -> 0 | I33: =IF(I32 = 0, 0, IF(I30 = (I$6+J$6),1,0)) -> 1 | J33: =IF(J32 = 0, 0, IF(J30 = (I$6+J$6),1,0)) -> 0 | K33: =IF(K32 = 0, 0, IF(K30 = (K$6+L$6),1,0)) -> 0 | L33: =IF(L32 = 0, 0, IF(L30 = (K$6+L$6),1,0)) -> 0 | M33: =IF(M32 = 0, 0, IF(M30 = (M$6+N$6),1,0)) -> 0 | N33: =IF(N32 = 0, 0, IF(N30 = (M$6+N$6),1,0)) -> 0 | O33: =IF(O32 = 0, 0, IF(O30 = (O$6+P$6),1,0)) -> 0 | P33: =IF(P32 = 0, 0, IF(P30 = (O$6+P$6),1,0)) -> 0 | Q33: =IF(Q32 = 0, 0, IF(Q30 = (Q$6+R$6),1,0)) -> 0 | R33: =IF(R32 = 0, 0, IF(R30 = (Q$6+R$6),1,0)) -> 0 | T33: =IF(T32 = 0, 0, IF(T30 = (T$6+U$6),1,0)) -> 0 | U33: =IF(U32 = 0, 0, IF(U30 = (T$6+U$6),1,0)) -> 0 | V33: =IF(V32 = 0, 0, IF(V30 = (V$6+W$6),1,0)) -> 0 | W33: =IF(W32 = 0, 0, IF(W30 = (V$6+W$6),1,0)) -> 0 | X33: =IF(X32 = 0, 0, IF(X30 = (X$6+Y$6),1,0)) -> 0 | Y33: =IF(Y32 = 0, 0, IF(Y30 = (X$6+Y$6),1,0)) -> 0 | Z33: =IF(Z32 = 0, 0, IF(Z30 = (Z$6+AA$6),1,0)) -> 0 | AA33: =IF(AA32 = 0, 0, IF(AA30 = (Z$6+AA$6),1,0)) -> 0 | AC33: =IF(AC32 = 0, 0, IF(AC30 = (AC$6+AD$6),1,0)) -> 0 | AD33: =IF(AD32 = 0, 0, IF(AD30 = (AC$6+AD$6),1,0)) -> 0 | AE33: =IF(AE32 = 0, 0, IF(AE30 = (AE$6+AF$6),1,0)) -> 0 | AF33: =IF(AF32 = 0, 0, IF(AF30 = (AE$6+AF$6),1,0)) -> 0 | AH33: =IF(AH32 = 0, 0, IF(AH30 = (AH$6+AI$6),1,0)) -> 0 | AI33: =IF(AI32 = 0, 0, IF(AI30 = (AH$6+AI$6),1,0)) -> 0 | AK33: =SUM(C33:AI33) -> 1
A34: =RANK(AL34,$AL$10:$AL$82,) -> 7 | B34: Olivier Paris | C34: 6 | E34: 7 | G34: 6 | I34: 5 | K34: 4 | M34: 5 | O34: 7 | R34: 7 | S34: =SUM(C35:R35) -> 78 | T34: 6 | W34: 6 | X34: 6 | Z34: 6 | AB34: =SUM(T35:AA35) -> 37 | AC34: 6 | AE34: 7 | AG34: =SUM(AC35:AF35) -> 4 | AH34: 7 | AJ34: =AH35 -> 24 | AK34: =MAX($AL$10:$AL$82) - AL34 -> 26 | AL34: =$S34+$AB34+$AG34+$AJ34 -> 143
A35: =RANK(AL35,$AL$10:$AL$82,) -> #N/A | C35: =(IF($C34<>"",($C$6*$O$92)+IF($C$6=4,($O$90)+IF($C34=$C$6+$D$6,$O$91,0),0),0)+IF($D34<>"",($D$6*$O$92)+IF($D$6=4,($O$90)+IF($D34=$C$6+$D$6,$O$91,0),0),0)) -> 9 | E35: =(IF($E34<>"",($E$6*$O$92)+IF($E$6=4,($O$90)+IF($E34=$E$6+$F$6,$O$91,0),0),0)+IF($F34<>"",($F$6*$O$92)+IF($F$6=4,($O$90)+IF($F34=$E$6+$F$6,$O$91,0),0),0)) -> 11 | G35: =(IF($G34<>"",($G$6*$O$92)+IF($G$6=4,($O$90)+IF($G34=$G$6+$H$6,$O$91,0),0),0)+IF($H34<>"",($H$6*$O$92)+IF($H$6=4,($O$90)+IF($H34=$G$6+$H$6,$O$91,0),0),0)) -> 11 | I35: =(IF($I34<>"",($I$6*$O$92)+IF($I$6=4,($O$90)+IF($I34=$I$6+$J$6,$O$91,0),0),0)+IF($J34<>"",($J$6*$O$92)+IF($J$6=4,($O$90)+IF($J34=$I$6+$J$6,$O$91,0),0),0)) -> 9 | K35: =(IF($K34<>"",($K$6*$O$92)+IF($K$6=4,($O$90)+IF($K34=$K$6+$L$6,$O$91,0),0),0)+IF($L34<>"",($L$6*$O$92)+IF($L$6=4,($O$90)+IF($L34=$K$6+$L$6,$O$91,0),0),0)) -> 9 | M35: =(IF($M34<>"",($M$6*$O$92)+IF($M$6=4,($O$90)+IF($M34=$M$6+$N$6,$O$91,0),0),0)+IF($N34<>"",($N$6*$O$92)+IF($N$6=4,($O$90)+IF($N34=$M$6+$N$6,$O$91,0),0),0)) -> 11 | O35: =(IF($O34<>"",($O$6*$O$92)+IF($O$6=4,($O$90)+IF($O34=$O$6+$P$6,$O$91,0),0),0)+IF($P34<>"",($P$6*$O$92)+IF($P$6=4,($O$90)+IF($P34=$O$6+$P$6,$O$91,0),0),0)) -> 9 | Q35: =(IF($Q34<>"",($Q$6*$O$92)+IF($Q$6=4,($O$90)+IF($Q34=$Q$6+$R$6,$O$91,0),0),0)+IF($R34<>"",($R$6*$O$92)+IF($R$6=4,($O$90)+IF($R34=$Q$6+$R$6,$O$91,0),0),0)) -> 9 | T35: =(IF($T34<>"",($T$6*$P$92)+IF($T$6=4,($P$90)+IF($T34=$T$6+$U$6,$P$91,0),0),0)+IF($U34<>"",($U$6*$P$92)+IF($U$6=4,($P$90)+IF($U34=$T$6+$U$6,$P$91,0),0),0)) -> 14 | V35: =(IF($V34<>"",($V$6*$P$92)+IF($V$6=4,($P$90)+IF($V34=$V$6+$W$6,$P$91,0),0),0)+IF($W34<>"",($W$6*$P$92)+IF($W$6=4,($P$90)+IF($W34=$V$6+$W$6,$P$91,0),0),0)) -> 2 | X35: =(IF($X34<>"",($X$6*$P$92)+IF($X$6=4,($P$90)+IF($X34=$X$6+$Y$6,$P$91,0),0),0)+IF($Y34<>"",($Y$6*$P$92)+IF($Y$6=4,($P$90)+IF($Y34=$X$6+$Y$6,$P$91,0),0),0)) -> 3 | Z35: =(IF($Z34<>"",($Z$6*$P$92)+IF($Z$6=4,($P$90)+IF($Z34=$Z$6+$AA$6,$P$91,0),0),0)+IF($AA34<>"",($AA$6*$P$92)+IF($AA$6=4,($P$90)+IF($AA34=$Z$6+$AA$6,$P$91,0),0),0)) -> 18 | AC35: =(IF($AC34<>"",($AC$6*$Q$92)+IF($AC$6=4,($Q$90)+IF($AC34=$AC$6+$AD$6,$Q$91,0),0),0)+IF($AD34<>"",($AD$6*$Q$92)+IF($AD$6=4,($Q$90)+IF($AD34=$AC$6+$AD$6,$Q$91,0),0),0)) -> 3 | AE35: =(IF($AE34<>"",($AE$6*$Q$92)+IF($AE$6=4,($Q$90)+IF($AE34=$AE$6+$AF$6,$Q$91,0),0),0)+IF($AF34<>"",($AF$6*$Q$92)+IF($AF$6=4,($Q$90)+IF($AF34=$AE$6+$AF$6,$Q$91,0),0),0)) -> 1 | AH35: =(IF($AH34<>"",($AH$6*$R$92)+IF($AH$6=4,($R$90)+IF($AH34=$AH$6+$AI$6,$R$91,0),0),0)+IF($AI34<>"",($AI$6*$R$92)+IF($AI$6=4,($R$90)+IF($AI34=$AH$6+$AI$6,$R$91,0),0),0)) -> 24 | AK35: =MAX($AL$10:$AL$82) - AL35 -> 169
B36: Prédiction équipe | C36: =IF(ISBLANK(C34), 0, IF(C$6= 4, 1, 0)) -> 1 | D36: =IF(ISBLANK(D34), 0, IF(D$6 = 4, 1, 0)) -> 0 | E36: =IF(ISBLANK(E34), 0, IF(E$6= 4, 1, 0)) -> 1 | F36: =IF(ISBLANK(F34), 0, IF(F$6 = 4, 1, 0)) -> 0 | G36: =IF(ISBLANK(G34), 0, IF(G$6= 4, 1, 0)) -> 1 | H36: =IF(ISBLANK(H34), 0, IF(H$6 = 4, 1, 0)) -> 0 | I36: =IF(ISBLANK(I34), 0, IF(I$6= 4, 1, 0)) -> 1 | J36: =IF(ISBLANK(J34), 0, IF(J$6 = 4, 1, 0)) -> 0 | K36: =IF(ISBLANK(K34), 0, IF(K$6= 4, 1, 0)) -> 1 | L36: =IF(ISBLANK(L34), 0, IF(L$6 = 4, 1, 0)) -> 0 | M36: =IF(ISBLANK(M34), 0, IF(M$6= 4, 1, 0)) -> 1 | N36: =IF(ISBLANK(N34), 0, IF(N$6 = 4, 1, 0)) -> 0 | O36: =IF(ISBLANK(O34), 0, IF(O$6= 4, 1, 0)) -> 1 | P36: =IF(ISBLANK(P34), 0, IF(P$6 = 4, 1, 0)) -> 0 | Q36: =IF(ISBLANK(Q34), 0, IF(Q$6= 4, 1, 0)) -> 0 | R36: =IF(ISBLANK(R34), 0, IF(R$6 = 4, 1, 0)) -> 1 | T36: =IF(ISBLANK(T34), 0, IF(T$6= 4, 1, 0)) -> 1 | U36: =IF(ISBLANK(U34), 0, IF(U$6 = 4, 1, 0)) -> 0 | V36: =IF(ISBLANK(V34), 0, IF(V$6= 4, 1, 0)) -> 0 | W36: =IF(ISBLANK(W34), 0, IF(W$6 = 4, 1, 0)) -> 0 | X36: =IF(ISBLANK(X34), 0, IF(X$6= 4, 1, 0)) -> 0 | Y36: =IF(ISBLANK(Y34), 0, IF(Y$6 = 4, 1, 0)) -> 0 | Z36: =IF(ISBLANK(Z34), 0, IF(Z$6= 4, 1, 0)) -> 1 | AA36: =IF(ISBLANK(AA34), 0, IF(AA$6 = 4, 1, 0)) -> 0 | AC36: =IF(ISBLANK(AC34), 0, IF(AC$6= 4, 1, 0)) -> 0 | AD36: =IF(ISBLANK(AD34), 0, IF(AD$6 = 4, 1, 0)) -> 0 | AE36: =IF(ISBLANK(AE34), 0, IF(AE$6= 4, 1, 0)) -> 0 | AF36: =IF(ISBLANK(AF34), 0, IF(AF$6 = 4, 1, 0)) -> 0 | AH36: =IF(ISBLANK(AH34), 0, IF(AH$6= 4, 1, 0)) -> 1 | AI36: =IF(ISBLANK(AI34), 0, IF(AI$6 = 4, 1, 0)) -> 0 | AK36: =SUM(C36:AI36) -> 11
B37: Prédiciton nb matchs | C37: =IF(C36 = 0, 0, IF(C34 = (C$6+D$6),1,0)) -> 0 | D37: =IF(D36 = 0, 0, IF(D34 = (C$6+D$6),1,0)) -> 0 | E37: =IF(E36 = 0, 0, IF(E34 = (E$6+F$6),1,0)) -> 1 | F37: =IF(F36 = 0, 0, IF(F34 = (E$6+F$6),1,0)) -> 0 | G37: =IF(G36 = 0, 0, IF(G34 = (G$6+H$6),1,0)) -> 1 | H37: =IF(H36 = 0, 0, IF(H34 = (G$6+H$6),1,0)) -> 0 | I37: =IF(I36 = 0, 0, IF(I34 = (I$6+J$6),1,0)) -> 0 | J37: =IF(J36 = 0, 0, IF(J34 = (I$6+J$6),1,0)) -> 0 | K37: =IF(K36 = 0, 0, IF(K34 = (K$6+L$6),1,0)) -> 0 | L37: =IF(L36 = 0, 0, IF(L34 = (K$6+L$6),1,0)) -> 0 | M37: =IF(M36 = 0, 0, IF(M34 = (M$6+N$6),1,0)) -> 1 | N37: =IF(N36 = 0, 0, IF(N34 = (M$6+N$6),1,0)) -> 0 | O37: =IF(O36 = 0, 0, IF(O34 = (O$6+P$6),1,0)) -> 0 | P37: =IF(P36 = 0, 0, IF(P34 = (O$6+P$6),1,0)) -> 0 | Q37: =IF(Q36 = 0, 0, IF(Q34 = (Q$6+R$6),1,0)) -> 0 | R37: =IF(R36 = 0, 0, IF(R34 = (Q$6+R$6),1,0)) -> 0 | T37: =IF(T36 = 0, 0, IF(T34 = (T$6+U$6),1,0)) -> 0 | U37: =IF(U36 = 0, 0, IF(U34 = (T$6+U$6),1,0)) -> 0 | V37: =IF(V36 = 0, 0, IF(V34 = (V$6+W$6),1,0)) -> 0 | W37: =IF(W36 = 0, 0, IF(W34 = (V$6+W$6),1,0)) -> 0 | X37: =IF(X36 = 0, 0, IF(X34 = (X$6+Y$6),1,0)) -> 0 | Y37: =IF(Y36 = 0, 0, IF(Y34 = (X$6+Y$6),1,0)) -> 0 | Z37: =IF(Z36 = 0, 0, IF(Z34 = (Z$6+AA$6),1,0)) -> 1 | AA37: =IF(AA36 = 0, 0, IF(AA34 = (Z$6+AA$6),1,0)) -> 0 | AC37: =IF(AC36 = 0, 0, IF(AC34 = (AC$6+AD$6),1,0)) -> 0 | AD37: =IF(AD36 = 0, 0, IF(AD34 = (AC$6+AD$6),1,0)) -> 0 | AE37: =IF(AE36 = 0, 0, IF(AE34 = (AE$6+AF$6),1,0)) -> 0 | AF37: =IF(AF36 = 0, 0, IF(AF34 = (AE$6+AF$6),1,0)) -> 0 | AH37: =IF(AH36 = 0, 0, IF(AH34 = (AH$6+AI$6),1,0)) -> 0 | AI37: =IF(AI36 = 0, 0, IF(AI34 = (AH$6+AI$6),1,0)) -> 0 | AK37: =SUM(C37:AI37) -> 4
A38: =RANK(AL38,$AL$10:$AL$82,) -> 8 | B38: Michaël Tremblay | C38: 5 | F38: 6 | H38: 6 | I38: 6 | K38: 5 | M38: 6 | P38: 6 | Q38: 7 | S38: =SUM(C39:R39) -> 45 | T38: 7 | W38: 6 | Y38: 6 | Z38: 5 | AB38: =SUM(T39:AA39) -> 44 | AD38: 6 | AE38: 6 | AG38: =SUM(AC39:AF39) -> 20 | AH38: 5 | AJ38: =AH39 -> 32 | AK38: =MAX($AL$10:$AL$82) - AL38 -> 28 | AL38: =$S38+$AB38+$AG38+$AJ38 -> 141
A39: =RANK(AL39,$AL$10:$AL$82,) -> #N/A | C39: =(IF($C38<>"",($C$6*$O$92)+IF($C$6=4,($O$90)+IF($C38=$C$6+$D$6,$O$91,0),0),0)+IF($D38<>"",($D$6*$O$92)+IF($D$6=4,($O$90)+IF($D38=$C$6+$D$6,$O$91,0),0),0)) -> 11 | E39: =(IF($E38<>"",($E$6*$O$92)+IF($E$6=4,($O$90)+IF($E38=$E$6+$F$6,$O$91,0),0),0)+IF($F38<>"",($F$6*$O$92)+IF($F$6=4,($O$90)+IF($F38=$E$6+$F$6,$O$91,0),0),0)) -> 3 | G39: =(IF($G38<>"",($G$6*$O$92)+IF($G$6=4,($O$90)+IF($G38=$G$6+$H$6,$O$91,0),0),0)+IF($H38<>"",($H$6*$O$92)+IF($H$6=4,($O$90)+IF($H38=$G$6+$H$6,$O$91,0),0),0)) -> 2 | I39: =(IF($I38<>"",($I$6*$O$92)+IF($I$6=4,($O$90)+IF($I38=$I$6+$J$6,$O$91,0),0),0)+IF($J38<>"",($J$6*$O$92)+IF($J$6=4,($O$90)+IF($J38=$I$6+$J$6,$O$91,0),0),0)) -> 11 | K39: =(IF($K38<>"",($K$6*$O$92)+IF($K$6=4,($O$90)+IF($K38=$K$6+$L$6,$O$91,0),0),0)+IF($L38<>"",($L$6*$O$92)+IF($L$6=4,($O$90)+IF($L38=$K$6+$L$6,$O$91,0),0),0)) -> 9 | M39: =(IF($M38<>"",($M$6*$O$92)+IF($M$6=4,($O$90)+IF($M38=$M$6+$N$6,$O$91,0),0),0)+IF($N38<>"",($N$6*$O$92)+IF($N$6=4,($O$90)+IF($N38=$M$6+$N$6,$O$91,0),0),0)) -> 9 | O39: =(IF($O38<>"",($O$6*$O$92)+IF($O$6=4,($O$90)+IF($O38=$O$6+$P$6,$O$91,0),0),0)+IF($P38<>"",($P$6*$O$92)+IF($P$6=4,($O$90)+IF($P38=$O$6+$P$6,$O$91,0),0),0)) -> 0 | Q39: =(IF($Q38<>"",($Q$6*$O$92)+IF($Q$6=4,($O$90)+IF($Q38=$Q$6+$R$6,$O$91,0),0),0)+IF($R38<>"",($R$6*$O$92)+IF($R$6=4,($O$90)+IF($R38=$Q$6+$R$6,$O$91,0),0),0)) -> 0 | T39: =(IF($T38<>"",($T$6*$P$92)+IF($T$6=4,($P$90)+IF($T38=$T$6+$U$6,$P$91,0),0),0)+IF($U38<>"",($U$6*$P$92)+IF($U$6=4,($P$90)+IF($U38=$T$6+$U$6,$P$91,0),0),0)) -> 14 | V39: =(IF($V38<>"",($V$6*$P$92)+IF($V$6=4,($P$90)+IF($V38=$V$6+$W$6,$P$91,0),0),0)+IF($W38<>"",($W$6*$P$92)+IF($W$6=4,($P$90)+IF($W38=$V$6+$W$6,$P$91,0),0),0)) -> 2 | X39: =(IF($X38<>"",($X$6*$P$92)+IF($X$6=4,($P$90)+IF($X38=$X$6+$Y$6,$P$91,0),0),0)+IF($Y38<>"",($Y$6*$P$92)+IF($Y$6=4,($P$90)+IF($Y38=$X$6+$Y$6,$P$91,0),0),0)) -> 14 | Z39: =(IF($Z38<>"",($Z$6*$P$92)+IF($Z$6=4,($P$90)+IF($Z38=$Z$6+$AA$6,$P$91,0),0),0)+IF($AA38<>"",($AA$6*$P$92)+IF($AA$6=4,($P$90)+IF($AA38=$Z$6+$AA$6,$P$91,0),0),0)) -> 14 | AC39: =(IF($AC38<>"",($AC$6*$Q$92)+IF($AC$6=4,($Q$90)+IF($AC38=$AC$6+$AD$6,$Q$91,0),0),0)+IF($AD38<>"",($AD$6*$Q$92)+IF($AD$6=4,($Q$90)+IF($AD38=$AC$6+$AD$6,$Q$91,0),0),0)) -> 19 | AE39: =(IF($AE38<>"",($AE$6*$Q$92)+IF($AE$6=4,($Q$90)+IF($AE38=$AE$6+$AF$6,$Q$91,0),0),0)+IF($AF38<>"",($AF$6*$Q$92)+IF($AF$6=4,($Q$90)+IF($AF38=$AE$6+$AF$6,$Q$91,0),0),0)) -> 1 | AH39: =(IF($AH38<>"",($AH$6*$R$92)+IF($AH$6=4,($R$90)+IF($AH38=$AH$6+$AI$6,$R$91,0),0),0)+IF($AI38<>"",($AI$6*$R$92)+IF($AI$6=4,($R$90)+IF($AI38=$AH$6+$AI$6,$R$91,0),0),0)) -> 32 | AK39: =MAX($AL$10:$AL$82) - AL39 -> 169
B40: Prédiction équipe | C40: =IF(ISBLANK(C38), 0, IF(C$6= 4, 1, 0)) -> 1 | D40: =IF(ISBLANK(D38), 0, IF(D$6 = 4, 1, 0)) -> 0 | E40: =IF(ISBLANK(E38), 0, IF(E$6= 4, 1, 0)) -> 0 | F40: =IF(ISBLANK(F38), 0, IF(F$6 = 4, 1, 0)) -> 0 | G40: =IF(ISBLANK(G38), 0, IF(G$6= 4, 1, 0)) -> 0 | H40: =IF(ISBLANK(H38), 0, IF(H$6 = 4, 1, 0)) -> 0 | I40: =IF(ISBLANK(I38), 0, IF(I$6= 4, 1, 0)) -> 1 | J40: =IF(ISBLANK(J38), 0, IF(J$6 = 4, 1, 0)) -> 0 | K40: =IF(ISBLANK(K38), 0, IF(K$6= 4, 1, 0)) -> 1 | L40: =IF(ISBLANK(L38), 0, IF(L$6 = 4, 1, 0)) -> 0 | M40: =IF(ISBLANK(M38), 0, IF(M$6= 4, 1, 0)) -> 1 | N40: =IF(ISBLANK(N38), 0, IF(N$6 = 4, 1, 0)) -> 0 | O40: =IF(ISBLANK(O38), 0, IF(O$6= 4, 1, 0)) -> 0 | P40: =IF(ISBLANK(P38), 0, IF(P$6 = 4, 1, 0)) -> 0 | Q40: =IF(ISBLANK(Q38), 0, IF(Q$6= 4, 1, 0)) -> 0 | R40: =IF(ISBLANK(R38), 0, IF(R$6 = 4, 1, 0)) -> 0 | T40: =IF(ISBLANK(T38), 0, IF(T$6= 4, 1, 0)) -> 1 | U40: =IF(ISBLANK(U38), 0, IF(U$6 = 4, 1, 0)) -> 0 | V40: =IF(ISBLANK(V38), 0, IF(V$6= 4, 1, 0)) -> 0 | W40: =IF(ISBLANK(W38), 0, IF(W$6 = 4, 1, 0)) -> 0 | X40: =IF(ISBLANK(X38), 0, IF(X$6= 4, 1, 0)) -> 0 | Y40: =IF(ISBLANK(Y38), 0, IF(Y$6 = 4, 1, 0)) -> 1 | Z40: =IF(ISBLANK(Z38), 0, IF(Z$6= 4, 1, 0)) -> 1 | AA40: =IF(ISBLANK(AA38), 0, IF(AA$6 = 4, 1, 0)) -> 0 | AC40: =IF(ISBLANK(AC38), 0, IF(AC$6= 4, 1, 0)) -> 0 | AD40: =IF(ISBLANK(AD38), 0, IF(AD$6 = 4, 1, 0)) -> 1 | AE40: =IF(ISBLANK(AE38), 0, IF(AE$6= 4, 1, 0)) -> 0 | AF40: =IF(ISBLANK(AF38), 0, IF(AF$6 = 4, 1, 0)) -> 0 | AH40: =IF(ISBLANK(AH38), 0, IF(AH$6= 4, 1, 0)) -> 1 | AI40: =IF(ISBLANK(AI38), 0, IF(AI$6 = 4, 1, 0)) -> 0 | AK40: =SUM(C40:AI40) -> 9
B41: Prédiciton nb matchs | C41: =IF(C40 = 0, 0, IF(C38 = (C$6+D$6),1,0)) -> 1 | D41: =IF(D40 = 0, 0, IF(D38 = (C$6+D$6),1,0)) -> 0 | E41: =IF(E40 = 0, 0, IF(E38 = (E$6+F$6),1,0)) -> 0 | F41: =IF(F40 = 0, 0, IF(F38 = (E$6+F$6),1,0)) -> 0 | G41: =IF(G40 = 0, 0, IF(G38 = (G$6+H$6),1,0)) -> 0 | H41: =IF(H40 = 0, 0, IF(H38 = (G$6+H$6),1,0)) -> 0 | I41: =IF(I40 = 0, 0, IF(I38 = (I$6+J$6),1,0)) -> 1 | J41: =IF(J40 = 0, 0, IF(J38 = (I$6+J$6),1,0)) -> 0 | K41: =IF(K40 = 0, 0, IF(K38 = (K$6+L$6),1,0)) -> 0 | L41: =IF(L40 = 0, 0, IF(L38 = (K$6+L$6),1,0)) -> 0 | M41: =IF(M40 = 0, 0, IF(M38 = (M$6+N$6),1,0)) -> 0 | N41: =IF(N40 = 0, 0, IF(N38 = (M$6+N$6),1,0)) -> 0 | O41: =IF(O40 = 0, 0, IF(O38 = (O$6+P$6),1,0)) -> 0 | P41: =IF(P40 = 0, 0, IF(P38 = (O$6+P$6),1,0)) -> 0 | Q41: =IF(Q40 = 0, 0, IF(Q38 = (Q$6+R$6),1,0)) -> 0 | R41: =IF(R40 = 0, 0, IF(R38 = (Q$6+R$6),1,0)) -> 0 | T41: =IF(T40 = 0, 0, IF(T38 = (T$6+U$6),1,0)) -> 0 | U41: =IF(U40 = 0, 0, IF(U38 = (T$6+U$6),1,0)) -> 0 | V41: =IF(V40 = 0, 0, IF(V38 = (V$6+W$6),1,0)) -> 0 | W41: =IF(W40 = 0, 0, IF(W38 = (V$6+W$6),1,0)) -> 0 | X41: =IF(X40 = 0, 0, IF(X38 = (X$6+Y$6),1,0)) -> 0 | Y41: =IF(Y40 = 0, 0, IF(Y38 = (X$6+Y$6),1,0)) -> 0 | Z41: =IF(Z40 = 0, 0, IF(Z38 = (Z$6+AA$6),1,0)) -> 0 | AA41: =IF(AA40 = 0, 0, IF(AA38 = (Z$6+AA$6),1,0)) -> 0 | AC41: =IF(AC40 = 0, 0, IF(AC38 = (AC$6+AD$6),1,0)) -> 0 | AD41: =IF(AD40 = 0, 0, IF(AD38 = (AC$6+AD$6),1,0)) -> 0 | AE41: =IF(AE40 = 0, 0, IF(AE38 = (AE$6+AF$6),1,0)) -> 0 | AF41: =IF(AF40 = 0, 0, IF(AF38 = (AE$6+AF$6),1,0)) -> 0 | AH41: =IF(AH40 = 0, 0, IF(AH38 = (AH$6+AI$6),1,0)) -> 1 | AI41: =IF(AI40 = 0, 0, IF(AI38 = (AH$6+AI$6),1,0)) -> 0 | AK41: =SUM(C41:AI41) -> 3
A42: =RANK(AL42,$AL$10:$AL$82,) -> 9 | B42: Michel Guérin | C42: 6 | F42: 6 | H42: 7 | I42: 6 | K42: 5 | M42: 6 | P42: 7 | Q42: 7 | S42: =SUM(C43:R43) -> 43 | T42: 7 | W42: 7 | Y42: 6 | Z42: 7 | AB42: =SUM(T43:AA43) -> 44 | AD42: 6 | AE42: 6 | AG42: =SUM(AC43:AF43) -> 20 | AH42: 5 | AJ42: =AH43 -> 32 | AK42: =MAX($AL$10:$AL$82) - AL42 -> 30 | AL42: =$S42+$AB42+$AG42+$AJ42 -> 139
...

Sheet Résultats
A3: M1 | B3: TAMPA BAY | C3: 5 | D3: 5 | E3: 2 | F3: 3 | G3: 3 | J3: =IF(C3>C4,1,0)+IF(D3>D4,1,0)+IF(E3>E4,1,0)+IF(F3>F4,1,0)+IF(G3>G4,1,0)+IF(H3>H4,1,0)+IF(I3>I4,1,0) -> 4
A4: WC | B4: NEW JERSEY | C4: 2 | D4: 3 | E4: 5 | F4: 1 | G4: 1 | J4: =IF(C4>C3,1,0)+IF(D4>D3,1,0)+IF(E4>E3,1,0)+IF(F4>F3,1,0)+IF(G4>G3,1,0)+IF(H4>H3,1,0)+IF(I4>I3,1,0) -> 1
A6: M2 | B6: BOSTON | C6: 5 | D6: 7 | E6: 2 | F6: 3 | G6: 3 | H6: 1 | I6: 7 | J6: =IF(C6>C7,1,0)+IF(D6>D7,1,0)+IF(E6>E7,1,0)+IF(F6>F7,1,0)+IF(G6>G7,1,0)+IF(H6>H7,1,0)+IF(I6>I7,1,0) -> 4 | M6: M1 | N6: TAMPA BAY | O6: 2 | P6: 4 | Q6: 4 | R6: 4 | S6: 3 | V6: =IF(O6>O7,1,0)+IF(P6>P7,1,0)+IF(Q6>Q7,1,0)+IF(R6>R7,1,0)+IF(S6>S7,1,0)+IF(T6>T7,1,0)+IF(U6>U7,1,0) -> 4
A7: M3 | B7: TORONTO | C7: 1 | D7: 3 | E7: 4 | F7: 1 | G7: 4 | H7: 3 | I7: 4 | J7: =IF(C7>C6,1,0)+IF(D7>D6,1,0)+IF(E7>E6,1,0)+IF(F7>F6,1,0)+IF(G7>G6,1,0)+IF(H7>H6,1,0)+IF(I7>I6,1,0) -> 3 | M7: M2 | N7: BOSTON | O7: 6 | P7: 2 | Q7: 1 | R7: 3 | S7: 1 | V7: =IF(O7>O6,1,0)+IF(P7>P6,1,0)+IF(Q7>Q6,1,0)+IF(R7>R6,1,0)+IF(S7>S6,1,0)+IF(T7>T6,1,0)+IF(U7>U6,1,0) -> 1
Y8: M1 | Z8: TAMPA BAY | AA8: 2 | AB8: 2 | AC8: 4 | AD8: 4 | AE8: 3 | AF8: 0 | AG8: 0 | AH8: =IF(AA8>AA9,1,0)+IF(AB8>AB9,1,0)+IF(AC8>AC9,1,0)+IF(AD8>AD9,1,0)+IF(AE8>AE9,1,0)+IF(AF8>AF9,1,0)+IF(AG8>AG9,1,0) -> 3
Y9: A1 | Z9: WASHINGTON | AA9: 4 | AB9: 6 | AC9: 2 | AD9: 2 | AE9: 2 | AF9: 3 | AG9: 4 | AH9: =IF(AA9>AA8,1,0)+IF(AB9>AB8,1,0)+IF(AC9>AC8,1,0)+IF(AD9>AD8,1,0)+IF(AE9>AE8,1,0)+IF(AF9>AF8,1,0)+IF(AG9>AG8,1,0) -> 4
A10: A1 | B10: WASHINGTON | C10: 3 | D10: 4 | E10: 3 | F10: 4 | G10: 4 | H10: 6 | J10: =IF(C10>C11,1,0)+IF(D10>D11,1,0)+IF(E10>E11,1,0)+IF(F10>F11,1,0)+IF(G10>G11,1,0)+IF(H10>H11,1,0)+IF(I10>I11,1,0) -> 4 | M10: A1 | N10: WASHINGTON | O10: 2 | P10: 4 | Q10: 4 | R10: 1 | S10: 6 | T10: 2 | V10: =IF(O10>O11,1,0)+IF(P10>P11,1,0)+IF(Q10>Q11,1,0)+IF(R10>R11,1,0)+IF(S10>S11,1,0)+IF(T10>T11,1,0)+IF(U10>U11,1,0) -> 4
A11: WC | B11: COLOMBUS | C11: 4 | D11: 5 | E11: 2 | F11: 1 | G11: 3 | H11: 3 | J11: =IF(C11>C10,1,0)+IF(D11>D10,1,0)+IF(E11>E10,1,0)+IF(F11>F10,1,0)+IF(G11>G10,1,0)+IF(H11>H10,1,0)+IF(I11>I10,1,0) -> 2 | M11: A2 | N11: PITTSBURGH | O11: 3 | P11: 1 | Q11: 3 | R11: 3 | S11: 3 | T11: 1 | V11: =IF(O11>O10,1,0)+IF(P11>P10,1,0)+IF(Q11>Q10,1,0)+IF(R11>R10,1,0)+IF(S11>S10,1,0)+IF(T11>T10,1,0)+IF(U11>U10,1,0) -> 2
A13: A2 | B13: PITTSBURGH | C13: 7 | D13: 1 | E13: 5 | F13: 5 | G13: 2 | H13: 8 | J13: =IF(C13>C14,1,0)+IF(D13>D14,1,0)+IF(E13>E14,1,0)+IF(F13>F14,1,0)+IF(G13>G14,1,0)+IF(H13>H14,1,0)+IF(I13>I14,1,0) -> 4
A14: A3 | B14: PHILADELPHIE | C14: 0 | D14: 5 | E14: 1 | F14: 0 | G14: 4 | H14: 5 | J14: =IF(C14>C13,1,0)+IF(D14>D13,1,0)+IF(E14>E13,1,0)+IF(F14>F13,1,0)+IF(G14>G13,1,0)+IF(H14>H13,1,0)+IF(I14>I13,1,0) -> 2
Y15: A1 | Z15: WASHINGTON | AA15: 4 | AB15: 3 | AC15: 3 | AD15: 6 | AE15: 4 | AH15: =IF(AA15>AA16,1,0)+IF(AB15>AB16,1,0)+IF(AC15>AC16,1,0)+IF(AD15>AD16,1,0)+IF(AE15>AE16,1,0)+IF(AF15>AF16,1,0)+IF(AG15>AG16,1,0) -> 4
Y16: P1 | Z16: VEGAS | AA16: 6 | AB16: 2 | AC16: 1 | AD16: 2 | AE16: 3 | AH16: =IF(AA16>AA15,1,0)+IF(AB16>AB15,1,0)+IF(AC16>AC15,1,0)+IF(AD16>AD15,1,0)+IF(AE16>AE15,1,0)+IF(AF16>AF15,1,0)+IF(AG16>AG15,1,0) -> 1
A17: C1 | B17: NASHVILLE | C17: 5 | D17: 5 | E17: 3 | F17: 3 | G17: 1 | H17: 5 | J17: =IF(C17>C18,1,0)+IF(D17>D18,1,0)+IF(E17>E18,1,0)+IF(F17>F18,1,0)+IF(G17>G18,1,0)+IF(H17>H18,1,0)+IF(I17>I18,1,0) -> 4
A18: WC | B18: COLORADO | C18: 2 | D18: 4 | E18: 5 | F18: 2 | G18: 2 | H18: 0 | J18: =IF(C18>C17,1,0)+IF(D18>D17,1,0)+IF(E18>E17,1,0)+IF(F18>F17,1,0)+IF(G18>G17,1,0)+IF(H18>H17,1,0)+IF(I18>I17,1,0) -> 2
A20: C2 | B20: WINNIPEG | C20: 3 | D20: 4 | E20: 2 | F20: 2 | G20: 5 | J20: =IF(C20>C21,1,0)+IF(D20>D21,1,0)+IF(E20>E21,1,0)+IF(F20>F21,1,0)+IF(G20>G21,1,0)+IF(H20>H21,1,0)+IF(I20>I21,1,0) -> 4 | M20: C1 | N20: NASHVILLE | O20: 1 | P20: 5 | Q20: 4 | R20: 2 | S20: 2 | T20: 4 | U20: 1 | V20: =IF(O20>O21,1,0)+IF(P20>P21,1,0)+IF(Q20>Q21,1,0)+IF(R20>R21,1,0)+IF(S20>S21,1,0)+IF(T20>T21,1,0)+IF(U20>U21,1,0) -> 3
A21: C3 | B21: MINNESOTA | C21: 2 | D21: 1 | E21: 6 | F21: 0 | G21: 0 | J21: =IF(C21>C20,1,0)+IF(D21>D20,1,0)+IF(E21>E20,1,0)+IF(F21>F20,1,0)+IF(G21>G20,1,0)+IF(H21>H20,1,0)+IF(I21>I20,1,0) -> 1 | M21: C2 | N21: WINNIPEG | O21: 4 | P21: 4 | Q21: 7 | R21: 1 | S21: 6 | T21: 0 | U21: 5 | V21: =IF(O21>O20,1,0)+IF(P21>P20,1,0)+IF(Q21>Q20,1,0)+IF(R21>R20,1,0)+IF(S21>S20,1,0)+IF(T21>T20,1,0)+IF(U21>U20,1,0) -> 4
Y22: C2 | Z22: WINNIPEG | AA22: 4 | AB22: 1 | AC22: 2 | AD22: 2 | AE22: 1 | AH22: =IF(AA22>AA23,1,0)+IF(AB22>AB23,1,0)+IF(AC22>AC23,1,0)+IF(AD22>AD23,1,0)+IF(AE22>AE23,1,0)+IF(AF22>AF23,1,0)+IF(AG22>AG23,1,0) -> 1
Y23: P1 | Z23: VEGAS | AA23: 2 | AB23: 3 | AC23: 4 | AD23: 3 | AE23: 2 | AH23: =IF(AA23>AA22,1,0)+IF(AB23>AB22,1,0)+IF(AC23>AC22,1,0)+IF(AD23>AD22,1,0)+IF(AE23>AE22,1,0)+IF(AF23>AF22,1,0)+IF(AG23>AG22,1,0) -> 4
