Workbook
Name PT_PREDICTION_EQUIPE_R1: Pool!$O$103
Name PT_PREDICTION_EQUIPE_R2: Pool!$P$103
Name PT_PREDICTION_EQUIPE_R3: Pool!$Q$103
Name PT_PREDICTION_EQUIPE_R4: Pool!$R$103
Name PT_PREDICTION_NB_PARTIES_R1: Pool!$O$104
Name PT_PREDICTION_NB_PARTIES_R2: Pool!$P$104
Name PT_PREDICTION_NB_PARTIES_R3: Pool!$Q$104
Name PT_PREDICTION_NB_PARTIES_R4: Pool!$R$104
Name PT_VICTOIRE_R1: Pool!$O$105
Name PT_VICTOIRE_R2: Pool!$P$105
Name PT_VICTOIRE_R3: Pool!$Q$105
Name PT_VICTOIRE_R4: Pool!$R$105

Sheet Pool
C2: Résultats complets disponibles à l'adresse suivante : | Q2: https://staker4.github.io/pool/laval.pdf
C3: Bracket : | Q3: https://staker4.github.io/pool/bracket.pdf
C5: RONDE 1 | T5: RONDE 2 | AC5: RONDE 3 | AH5: R4
C6: EST | K6: OUEST | S6: Sous-total - RONDE 1 | T6: EST | X6: OUEST | AB6: Sous-total - RONDE 2 | AC6: EST | AE6: OUEST | AG6: Sous-total - RONDE 3 | AJ6: Sous-total - RONDE 4
C7: =Résultats!$J$3 -> 0 | D7: =Résultats!$J$4 -> 4 | E7: =Résultats!$J$6 -> 4 | F7: =Résultats!$J$7 -> 3 | G7: =Résultats!$J$10 -> 3 | H7: =Résultats!$J$11 -> 4 | I7: =Résultats!$J$13 -> 4 | J7: =Résultats!$J$14 -> 0 | K7: =Résultats!$J$17 -> 1 | L7: =Résultats!$J$18 -> 4 | M7: =Résultats!$J$20 -> 2 | N7: =Résultats!$J$21 -> 4 | O7: =Résultats!$J$24 -> 2 | P7: =Résultats!$J$25 -> 4 | Q7: =Résultats!$J$27 -> 4 | R7: =Résultats!$J$28 -> 3 | T7: =Résultats!$V$6 -> 4 | U7: =Résultats!$V$7 -> 2 | V7: =Résultats!$V$10 -> 0 | W7: =Résultats!$V$11 -> 4 | X7: =Résultats!$V$20 -> 4 | Y7: =Résultats!$V$21 -> 3 | Z7: =Résultats!$V$24 -> 4 | AA7: =Résultats!$V$25 -> 3 | AC7: =Résultats!$AH$8 -> 4 | AD7: =Résultats!$AH$9 -> 0 | AE7: =Résultats!$AH$22 -> 2 | AF7: =Résultats!$AH$23 -> 4 | AH7: =Résultats!$AH$15 -> 3 | AI7: =Résultats!$AH$16 -> 4
C8: =IF(ISBLANK($C11),0,($C$7*PT_VICTOIRE_R1)+IF($C$7=4,PT_PREDICTION_EQUIPE_R1+IF($C11=$C$7+$D$7,PT_PREDICTION_NB_PARTIES_R1,0),0)) +IF(ISBLANK($D11),0,($D$7*PT_VICTOIRE_R1)+IF($D$7=4,PT_PREDICTION_EQUIPE_R1+IF($D11=$C$7+$D$7,PT_PREDICTION_NB_PARTIES_R1,0),0)) -> 0
C9: =Résultats!$B$3 -> TAMPA BAY | D9: =Résultats!$B$4 -> COLUMBUS | E9: =Résultats!$B$6 -> BOSTON | F9: =Résultats!$B$7 -> TORONTO | G9: =Résultats!$B$10 -> WASHINGTON | H9: =Résultats!$B$11 -> CAROLINE | I9: =Résultats!$B$13 -> NEW YORK I. | J9: =Résultats!$B$14 -> PITTSBURGH | K9: =Résultats!$B$17 -> CALGARY | L9: =Résultats!$B$18 -> COLORADO | M9: =Résultats!$B$20 -> WINNIPEG | N9: =Résultats!$B$21 -> ST-LOUIS | O9: =Résultats!$B$24 -> NASHVILLE | P9: =Résultats!$B$25 -> DALLAS | Q9: =Résultats!$B$27 -> SAN JOSE | R9: =Résultats!$B$28 -> VEGAS | T9: =Résultats!$N$6 -> BOSTON | U9: =Résultats!$N$7 -> COLUMBUS | V9: =Résultats!$N$10 -> NEW YORK I. | W9: =Résultats!$N$11 -> CAROLINE | X9: =Résultats!$N$20 -> SAN JOSE | Y9: =Résultats!$N$21 -> COLORADO | Z9: =Résultats!$N$24 -> ST-LOUIS | AA9: =Résultats!$N$25 -> DALLAS | AC9: =Résultats!$Z$8 -> BOSTON | AD9: =Résultats!$Z$9 -> CAROLINE | AE9: =Résultats!$Z$22 -> SAN JOSE | AF9: =Résultats!$Z$23 -> ST-LOUIS | AH9: =Résultats!$Z$15 -> BOSTON | AI9: =Résultats!$Z$16 -> ST-LOUIS
A10: # | B10: NOM | C10: =Résultats!$A$3 -> A1 | D10: =Résultats!$A$4 -> WC2 | E10: =Résultats!$A$6 -> A2 | F10: =Résultats!$A$7 -> A3 | G10: =Résultats!$A$10 -> M1 | H10: =Résultats!$A$11 -> WC1 | I10: =Résultats!$A$13 -> M2 | J10: =Résultats!$A$14 -> M3 | K10: =Résultats!$A$17 -> C1 | L10: =Résultats!$A$18 -> WC2 | M10: =Résultats!$A$20 -> C2 | N10: =Résultats!$A$21 -> C3 | O10: =Résultats!$A$24 -> P1 | P10: =Résultats!$A$25 -> WC1 | Q10: =Résultats!$A$27 -> P2 | R10: =Résultats!$A$28 -> P3 | T10: =Résultats!$M$6 -> A2 | U10: =Résultats!$M$7 -> WC2 | V10: =Résultats!$M$10 -> M2 | W10: =Résultats!$M$11 -> WC1 | X10: =Résultats!$M$20 -> P2 | Y10: =Résultats!$M$21 -> WC2 | Z10: =Résultats!$M$24 -> C3 | AA10: =Résultats!$M$25 -> WC1 | AC10: =Résultats!$Y$8 -> A2 | AD10: =Résultats!$Y$9 -> WC1 | AE10: =Résultats!$Y$22 -> P2 | AF10: =Résultats!$Y$23 -> C3 | AH10: =Résultats!$Y$15 -> A2 | AI10: =Résultats!$Y$16 -> C3 | AK10: ÉCART | AL10: TOTAL
A11: =RANK(AL11,$AL$11:$AL$98,) -> 1 | B11: Julien Belvisi | C11: 5 | E11: 7 | G11: 4 | J11: 6 | K11: 5 | N11: 6 | O11: 7 | Q11: 6 | S11: =SUM(C12:R12) -> 37 | T11: 6 | W11: 6 | X11: 5 | AA11: 7 | AB11: =SUM(T12:AA12) -> 49 | AD11: 6 | AF11: 7 | AG11: =SUM(AC12:AF12) -> 19 | AI11: 7 | AJ11: =AH12 -> 32 | AK11: =MAX($AL$11:$AL$98) - AL11 -> 0 | AL11: =$S11+$AB11+$AG11+$AJ11 -> 137
A12: =RANK(AL12,$AL$11:$AL$98,) -> #N/A | C12: =(IF($C11<>"",($C$7*$O$105)+IF($C$7=4,($O$103)+IF($C11=$C$7+$D$7,$O$104,0),0),0)+IF($D11<>"",($D$7*$O$105)+IF($D$7=4,($O$103)+IF($D11=$C$7+$D$7,$O$104,0),0),0)) -> 0 | E12: =(IF($E11<>"",($E$7*$O$105)+IF($E$7=4,($O$103)+IF($E11=$E$7+$F$7,$O$104,0),0),0)+IF($F11<>"",($F$7*$O$105)+IF($F$7=4,($O$103)+IF($F11=$E$7+$F$7,$O$104,0),0),0)) -> 11 | G12: =(IF($G11<>"",($G$7*$O$105)+IF($G$7=4,($O$103)+IF($G11=$G$7+$H$7,$O$104,0),0),0)+IF($H11<>"",($H$7*$O$105)+IF($H$7=4,($O$103)+IF($H11=$G$7+$H$7,$O$104,0),0),0)) -> 3 | I12: =(IF($I11<>"",($I$7*$O$105)+IF($I$7=4,($O$103)+IF($I11=$I$7+$J$7,$O$104,0),0),0)+IF($J11<>"",($J$7*$O$105)+IF($J$7=4,($O$103)+IF($J11=$I$7+$J$7,$O$104,0),0),0)) -> 0 | K12: =(IF($K11<>"",($K$7*$O$105)+IF($K$7=4,($O$103)+IF($K11=$K$7+$L$7,$O$104,0),0),0)+IF($L11<>"",($L$7*$O$105)+IF($L$7=4,($O$103)+IF($L11=$K$7+$L$7,$O$104,0),0),0)) -> 1 | M12: =(IF($M11<>"",($M$7*$O$105)+IF($M$7=4,($O$103)+IF($M11=$M$7+$N$7,$O$104,0),0),0)+IF($N11<>"",($N$7*$O$105)+IF($N$7=4,($O$103)+IF($N11=$M$7+$N$7,$O$104,0),0),0)) -> 11 | O12: =(IF($O11<>"",($O$7*$O$105)+IF($O$7=4,($O$103)+IF($O11=$O$7+$P$7,$O$104,0),0),0)+IF($P11<>"",($P$7*$O$105)+IF($P$7=4,($O$103)+IF($P11=$O$7+$P$7,$O$104,0),0),0)) -> 2 | Q12: =(IF($Q11<>"",($Q$7*$O$105)+IF($Q$7=4,($O$103)+IF($Q11=$Q$7+$R$7,$O$104,0),0),0)+IF($R11<>"",($R$7*$O$105)+IF($R$7=4,($O$103)+IF($R11=$Q$7+$R$7,$O$104,0),0),0)) -> 9 | T12: =(IF($T11<>"",($T$7*$P$105)+IF($T$7=4,($P$103)+IF($T11=$T$7+$U$7,$P$104,0),0),0)+IF($U11<>"",($U$7*$P$105)+IF($U$7=4,($P$103)+IF($U11=$T$7+$U$7,$P$104,0),0),0)) -> 18 | V12: =(IF($V11<>"",($V$7*$P$105)+IF($V$7=4,($P$103)+IF($V11=$V$7+$W$7,$P$104,0),0),0)+IF($W11<>"",($W$7*$P$105)+IF($W$7=4,($P$103)+IF($W11=$V$7+$W$7,$P$104,0),0),0)) -> 14 | X12: =(IF($X11<>"",($X$7*$P$105)+IF($X$7=4,($P$103)+IF($X11=$X$7+$Y$7,$P$104,0),0),0)+IF($Y11<>"",($Y$7*$P$105)+IF($Y$7=4,($P$103)+IF($Y11=$X$7+$Y$7,$P$104,0),0),0)) -> 14 | Z12: =(IF($Z11<>"",($Z$7*$P$105)+IF($Z$7=4,($P$103)+IF($Z11=$Z$7+$AA$7,$P$104,0),0),0)+IF($AA11<>"",($AA$7*$P$105)+IF($AA$7=4,($P$103)+IF($AA11=$Z$7+$AA$7,$P$104,0),0),0)) -> 3 | AC12: =(IF($AC11<>"",($AC$7*$Q$105)+IF($AC$7=4,($Q$103)+IF($AC11=$AC$7+$AD$7,$Q$104,0),0),0)+IF($AD11<>"",($AD$7*$Q$105)+IF($AD$7=4,($Q$103)+IF($AD11=$AC$7+$AD$7,$Q$104,0),0),0)) -> 0 | AE12: =(IF($AE11<>"",($AE$7*$Q$105)+IF($AE$7=4,($Q$103)+IF($AE11=$AE$7+$AF$7,$Q$104,0),0),0)+IF($AF11<>"",($AF$7*$Q$105)+IF($AF$7=4,($Q$103)+IF($AF11=$AE$7+$AF$7,$Q$104,0),0),0)) -> 19 | AH12: =(IF($AH11<>"",($AH$7*$Q$105)+IF($AH$7=4,($R$103)+IF($AH11=$AH$7+$AI$7,$R$104,0),0),0)+IF($AI11<>"",($AI$7*$R$105)+IF($AI$7=4,($R$103)+IF($AI11=$AH$7+$AI$7,$R$104,0),0),0)) -> 32
B13: Prédiction équipe | C13: =IF(ISBLANK(C11), 0, IF(C$7= 4, 1, 0)) -> 0 | D13: =IF(ISBLANK(D11), 0, IF(D$7 = 4, 1, 0)) -> 0 | E13: =IF(ISBLANK(E11), 0, IF(E$7= 4, 1, 0)) -> 1 | F13: =IF(ISBLANK(F11), 0, IF(F$7 = 4, 1, 0)) -> 0 | G13: =IF(ISBLANK(G11), 0, IF(G$7= 4, 1, 0)) -> 0 | H13: =IF(ISBLANK(H11), 0, IF(H$7 = 4, 1, 0)) -> 0 | I13: =IF(ISBLANK(I11), 0, IF(I$7= 4, 1, 0)) -> 0 | J13: =IF(ISBLANK(J11), 0, IF(J$7 = 4, 1, 0)) -> 0 | K13: =IF(ISBLANK(K11), 0, IF(K$7= 4, 1, 0)) -> 0 | L13: =IF(ISBLANK(L11), 0, IF(L$7 = 4, 1, 0)) -> 0 | M13: =IF(ISBLANK(M11), 0, IF(M$7= 4, 1, 0)) -> 0 | N13: =IF(ISBLANK(N11), 0, IF(N$7 = 4, 1, 0)) -> 1 | O13: =IF(ISBLANK(O11), 0, IF(O$7= 4, 1, 0)) -> 0 | P13: =IF(ISBLANK(P11), 0, IF(P$7 = 4, 1, 0)) -> 0 | Q13: =IF(ISBLANK(Q11), 0, IF(Q$7= 4, 1, 0)) -> 1 | R13: =IF(ISBLANK(R11), 0, IF(R$7 = 4, 1, 0)) -> 0 | T13: =IF(ISBLANK(T11), 0, IF(T$7= 4, 1, 0)) -> 1 | U13: =IF(ISBLANK(U11), 0, IF(U$7 = 4, 1, 0)) -> 0 | V13: =IF(ISBLANK(V11), 0, IF(V$7= 4, 1, 0)) -> 0 | W13: =IF(ISBLANK(W11), 0, IF(W$7 = 4, 1, 0)) -> 1 | X13: =IF(ISBLANK(X11), 0, IF(X$7= 4, 1, 0)) -> 1 | Y13: =IF(ISBLANK(Y11), 0, IF(Y$7 = 4, 1, 0)) -> 0 | Z13: =IF(ISBLANK(Z11), 0, IF(Z$7= 4, 1, 0)) -> 0 | AA13: =IF(ISBLANK(AA11), 0, IF(AA$7 = 4, 1, 0)) -> 0 | AC13: =IF(ISBLANK(AC11), 0, IF(AC$7= 4, 1, 0)) -> 0 | AD13: =IF(ISBLANK(AD11), 0, IF(AD$7 = 4, 1, 0)) -> 0 | AE13: =IF(ISBLANK(AE11), 0, IF(AE$7= 4, 1, 0)) -> 0 | AF13: =IF(ISBLANK(AF11), 0, IF(AF$7 = 4, 1, 0)) -> 1 | AH13: =IF(ISBLANK(AH11), 0, IF(AH$7= 4, 1, 0)) -> 0 | AI13: =IF(ISBLANK(AI11), 0, IF(AI$7 = 4, 1, 0)) -> 1 | AK13: =SUM(C13:AI13) -> 8
B14: Prédiciton nb matchs | C14: =IF(C13 = 0, 0, IF(C11 = (C$7+D$7),1,0)) -> 0 | D14: =IF(D13 = 0, 0, IF(D11 = (C$7+D$7),1,0)) -> 0 | E14: =IF(E13 = 0, 0, IF(E11 = (E$7+F$7),1,0)) -> 1 | F14: =IF(F13 = 0, 0, IF(F11 = (E$7+F$7),1,0)) -> 0 | G14: =IF(G13 = 0, 0, IF(G11 = (G$7+H$7),1,0)) -> 0 | H14: =IF(H13 = 0, 0, IF(H11 = (G$7+H$7),1,0)) -> 0 | I14: =IF(I13 = 0, 0, IF(I11 = (I$7+J$7),1,0)) -> 0 | J14: =IF(J13 = 0, 0, IF(J11 = (I$7+J$7),1,0)) -> 0 | K14: =IF(K13 = 0, 0, IF(K11 = (K$7+L$7),1,0)) -> 0 | L14: =IF(L13 = 0, 0, IF(L11 = (K$7+L$7),1,0)) -> 0 | M14: =IF(M13 = 0, 0, IF(M11 = (M$7+N$7),1,0)) -> 0 | N14: =IF(N13 = 0, 0, IF(N11 = (M$7+N$7),1,0)) -> 1 | O14: =IF(O13 = 0, 0, IF(O11 = (O$7+P$7),1,0)) -> 0 | P14: =IF(P13 = 0, 0, IF(P11 = (O$7+P$7),1,0)) -> 0 | Q14: =IF(Q13 = 0, 0, IF(Q11 = (Q$7+R$7),1,0)) -> 0 | R14: =IF(R13 = 0, 0, IF(R11 = (Q$7+R$7),1,0)) -> 0 | T14: =IF(T13 = 0, 0, IF(T11 = (T$7+U$7),1,0)) -> 1 | U14: =IF(U13 = 0, 0, IF(U11 = (T$7+U$7),1,0)) -> 0 | V14: =IF(V13 = 0, 0, IF(V11 = (V$7+W$7),1,0)) -> 0 | W14: =IF(W13 = 0, 0, IF(W11 = (V$7+W$7),1,0)) -> 0 | X14: =IF(X13 = 0, 0, IF(X11 = (X$7+Y$7),1,0)) -> 0 | Y14: =IF(Y13 = 0, 0, IF(Y11 = (X$7+Y$7),1,0)) -> 0 | Z14: =IF(Z13 = 0, 0, IF(Z11 = (Z$7+AA$7),1,0)) -> 0 | AA14: =IF(AA13 = 0, 0, IF(AA11 = (Z$7+AA$7),1,0)) -> 0 | AC14: =IF(AC13 = 0, 0, IF(AC11 = (AC$7+AD$7),1,0)) -> 0 | AD14: =IF(AD13 = 0, 0, IF(AD11 = (AC$7+AD$7),1,0)) -> 0 | AE14: =IF(AE13 = 0, 0, IF(AE11 = (AE$7+AF$7),1,0)) -> 0 | AF14: =IF(AF13 = 0, 0, IF(AF11 = (AE$7+AF$7),1,0)) -> 0 | AH14: =IF(AH13 = 0, 0, IF(AH11 = (AH$7+AI$7),1,0)) -> 0 | AI14: =IF(AI13 = 0, 0, IF(AI11 = (AH$7+AI$7),1,0)) -> 1 | AK14: =SUM(C14:AI14) -> 4
A15: =RANK(AL15,$AL$11:$AL$98,) -> 2 | B15: Jean-Christophe Pichot | C15: 5 | E15: 5 | G15: 5 | J15: 6 | K15: 5 | N15: 6 | O15: 5 | R15: 6 | S15: =SUM(C16:R16) -> 29 | U15: 6 | V15: 5 | X15: 7 | Z15: 7 | AB15: =SUM(T16:AA16) -> 38 | AC15: 6 | AF15: 6 | AG15: =SUM(AC16:AF16) -> 44 | AI15: 6 | AJ15: =AH16 -> 24 | AK15: =MAX($AL$11:$AL$98) - AL15 -> 2 | AL15: =$S15+$AB15+$AG15+$AJ15 -> 135
A16: =RANK(AL16,$AL$11:$AL$98,) -> #N/A | C16: =(IF($C15<>"",($C$7*$O$105)+IF($C$7=4,($O$103)+IF($C15=$C$7+$D$7,$O$104,0),0),0)+IF($D15<>"",($D$7*$O$105)+IF($D$7=4,($O$103)+IF($D15=$C$7+$D$7,$O$104,0),0),0)) -> 0 | E16: =(IF($E15<>"",($E$7*$O$105)+IF($E$7=4,($O$103)+IF($E15=$E$7+$F$7,$O$104,0),0),0)+IF($F15<>"",($F$7*$O$105)+IF($F$7=4,($O$103)+IF($F15=$E$7+$F$7,$O$104,0),0),0)) -> 9 | G16: =(IF($G15<>"",($G$7*$O$105)+IF($G$7=4,($O$103)+IF($G15=$G$7+$H$7,$O$104,0),0),0)+IF($H15<>"",($H$7*$O$105)+IF($H$7=4,($O$103)+IF($H15=$G$7+$H$7,$O$104,0),0),0)) -> 3 | I16: =(IF($I15<>"",($I$7*$O$105)+IF($I$7=4,($O$103)+IF($I15=$I$7+$J$7,$O$104,0),0),0)+IF($J15<>"",($J$7*$O$105)+IF($J$7=4,($O$103)+IF($J15=$I$7+$J$7,$O$104,0),0),0)) -> 0 | K16: =(IF($K15<>"",($K$7*$O$105)+IF($K$7=4,($O$103)+IF($K15=$K$7+$L$7,$O$104,0),0),0)+IF($L15<>"",($L$7*$O$105)+IF($L$7=4,($O$103)+IF($L15=$K$7+$L$7,$O$104,0),0),0)) -> 1 | M16: =(IF($M15<>"",($M$7*$O$105)+IF($M$7=4,($O$103)+IF($M15=$M$7+$N$7,$O$104,0),0),0)+IF($N15<>"",($N$7*$O$105)+IF($N$7=4,($O$103)+IF($N15=$M$7+$N$7,$O$104,0),0),0)) -> 11 | O16: =(IF($O15<>"",($O$7*$O$105)+IF($O$7=4,($O$103)+IF($O15=$O$7+$P$7,$O$104,0),0),0)+IF($P15<>"",($P$7*$O$105)+IF($P$7=4,($O$103)+IF($P15=$O$7+$P$7,$O$104,0),0),0)) -> 2 | Q16: =(IF($Q15<>"",($Q$7*$O$105)+IF($Q$7=4,($O$103)+IF($Q15=$Q$7+$R$7,$O$104,0),0),0)+IF($R15<>"",($R$7*$O$105)+IF($R$7=4,($O$103)+IF($R15=$Q$7+$R$7,$O$104,0),0),0)) -> 3 | T16: =(IF($T15<>"",($T$7*$P$105)+IF($T$7=4,($P$103)+IF($T15=$T$7+$U$7,$P$104,0),0),0)+IF($U15<>"",($U$7*$P$105)+IF($U$7=4,($P$103)+IF($U15=$T$7+$U$7,$P$104,0),0),0)) -> 2 | V16: =(IF($V15<>"",($V$7*$P$105)+IF($V$7=4,($P$103)+IF($V15=$V$7+$W$7,$P$104,0),0),0)+IF($W15<>"",($W$7*$P$105)+IF($W$7=4,($P$103)+IF($W15=$V$7+$W$7,$P$104,0),0),0)) -> 0 | X16: =(IF($X15<>"",($X$7*$P$105)+IF($X$7=4,($P$103)+IF($X15=$X$7+$Y$7,$P$104,0),0),0)+IF($Y15<>"",($Y$7*$P$105)+IF($Y$7=4,($P$103)+IF($Y15=$X$7+$Y$7,$P$104,0),0),0)) -> 18 | Z16: =(IF($Z15<>"",($Z$7*$P$105)+IF($Z$7=4,($P$103)+IF($Z15=$Z$7+$AA$7,$P$104,0),0),0)+IF($AA15<>"",($AA$7*$P$105)+IF($AA$7=4,($P$103)+IF($AA15=$Z$7+$AA$7,$P$104,0),0),0)) -> 18 | AC16: =(IF($AC15<>"",($AC$7*$Q$105)+IF($AC$7=4,($Q$103)+IF($AC15=$AC$7+$AD$7,$Q$104,0),0),0)+IF($AD15<>"",($AD$7*$Q$105)+IF($AD$7=4,($Q$103)+IF($AD15=$AC$7+$AD$7,$Q$104,0),0),0)) -> 19 | AE16: =(IF($AE15<>"",($AE$7*$Q$105)+IF($AE$7=4,($Q$103)+IF($AE15=$AE$7+$AF$7,$Q$104,0),0),0)+IF($AF15<>"",($AF$7*$Q$105)+IF($AF$7=4,($Q$103)+IF($AF15=$AE$7+$AF$7,$Q$104,0),0),0)) -> 25 | AH16: =(IF($AH15<>"",($AH$7*$Q$105)+IF($AH$7=4,($R$103)+IF($AH15=$AH$7+$AI$7,$R$104,0),0),0)+IF($AI15<>"",($AI$7*$R$105)+IF($AI$7=4,($R$103)+IF($AI15=$AH$7+$AI$7,$R$104,0),0),0)) -> 24 | AK16: =MAX($AL$11:$AL$98) - AL16 -> 137
B17: Prédiction équipe | C17: =IF(ISBLANK(C15), 0, IF(C$7= 4, 1, 0)) -> 0 | D17: =IF(ISBLANK(D15), 0, IF(D$7 = 4, 1, 0)) -> 0 | E17: =IF(ISBLANK(E15), 0, IF(E$7= 4, 1, 0)) -> 1 | F17: =IF(ISBLANK(F15), 0, IF(F$7 = 4, 1, 0)) -> 0 | G17: =IF(ISBLANK(G15), 0, IF(G$7= 4, 1, 0)) -> 0 | H17: =IF(ISBLANK(H15), 0, IF(H$7 = 4, 1, 0)) -> 0 | I17: =IF(ISBLANK(I15), 0, IF(I$7= 4, 1, 0)) -> 0 | J17: =IF(ISBLANK(J15), 0, IF(J$7 = 4, 1, 0)) -> 0 | K17: =IF(ISBLANK(K15), 0, IF(K$7= 4, 1, 0)) -> 0 | L17: =IF(ISBLANK(L15), 0, IF(L$7 = 4, 1, 0)) -> 0 | M17: =IF(ISBLANK(M15), 0, IF(M$7= 4, 1, 0)) -> 0 | N17: =IF(ISBLANK(N15), 0, IF(N$7 = 4, 1, 0)) -> 1 | O17: =IF(ISBLANK(O15), 0, IF(O$7= 4, 1, 0)) -> 0 | P17: =IF(ISBLANK(P15), 0, IF(P$7 = 4, 1, 0)) -> 0 | Q17: =IF(ISBLANK(Q15), 0, IF(Q$7= 4, 1, 0)) -> 0 | R17: =IF(ISBLANK(R15), 0, IF(R$7 = 4, 1, 0)) -> 0 | T17: =IF(ISBLANK(T15), 0, IF(T$7= 4, 1, 0)) -> 0 | U17: =IF(ISBLANK(U15), 0, IF(U$7 = 4, 1, 0)) -> 0 | V17: =IF(ISBLANK(V15), 0, IF(V$7= 4, 1, 0)) -> 0 | W17: =IF(ISBLANK(W15), 0, IF(W$7 = 4, 1, 0)) -> 0 | X17: =IF(ISBLANK(X15), 0, IF(X$7= 4, 1, 0)) -> 1 | Y17: =IF(ISBLANK(Y15), 0, IF(Y$7 = 4, 1, 0)) -> 0 | Z17: =IF(ISBLANK(Z15), 0, IF(Z$7= 4, 1, 0)) -> 1 | AA17: =IF(ISBLANK(AA15), 0, IF(AA$7 = 4, 1, 0)) -> 0 | AC17: =IF(ISBLANK(AC15), 0, IF(AC$7= 4, 1, 0)) -> 1 | AD17: =IF(ISBLANK(AD15), 0, IF(AD$7 = 4, 1, 0)) -> 0 | AE17: =IF(ISBLANK(AE15), 0, IF(AE$7= 4, 1, 0)) -> 0 | AF17: =IF(ISBLANK(AF15), 0, IF(AF$7 = 4, 1, 0)) -> 1 | AH17: =IF(ISBLANK(AH15), 0, IF(AH$7= 4, 1, 0)) -> 0 | AI17: =IF(ISBLANK(AI15), 0, IF(AI$7 = 4, 1, 0)) -> 1 | AK17: =SUM(C17:AI17) -> 7
B18: Prédiciton nb matchs | C18: =IF(C17 = 0, 0, IF(C15 = (C$7+D$7),1,0)) -> 0 | D18: =IF(D17 = 0, 0, IF(D15 = (C$7+D$7),1,0)) -> 0 | E18: =IF(E17 = 0, 0, IF(E15 = (E$7+F$7),1,0)) -> 0 | F18: =IF(F17 = 0, 0, IF(F15 = (E$7+F$7),1,0)) -> 0 | G18: =IF(G17 = 0, 0, IF(G15 = (G$7+H$7),1,0)) -> 0 | H18: =IF(H17 = 0, 0, IF(H15 = (G$7+H$7),1,0)) -> 0 | I18: =IF(I17 = 0, 0, IF(I15 = (I$7+J$7),1,0)) -> 0 | J18: =IF(J17 = 0, 0, IF(J15 = (I$7+J$7),1,0)) -> 0 | K18: =IF(K17 = 0, 0, IF(K15 = (K$7+L$7),1,0)) -> 0 | L18: =IF(L17 = 0, 0, IF(L15 = (K$7+L$7),1,0)) -> 0 | M18: =IF(M17 = 0, 0, IF(M15 = (M$7+N$7),1,0)) -> 0 | N18: =IF(N17 = 0, 0, IF(N15 = (M$7+N$7),1,0)) -> 1 | O18: =IF(O17 = 0, 0, IF(O15 = (O$7+P$7),1,0)) -> 0 | P18: =IF(P17 = 0, 0, IF(P15 = (O$7+P$7),1,0)) -> 0 | Q18: =IF(Q17 = 0, 0, IF(Q15 = (Q$7+R$7),1,0)) -> 0 | R18: =IF(R17 = 0, 0, IF(R15 = (Q$7+R$7),1,0)) -> 0 | T18: =IF(T17 = 0, 0, IF(T15 = (T$7+U$7),1,0)) -> 0 | U18: =IF(U17 = 0, 0, IF(U15 = (T$7+U$7),1,0)) -> 0 | V18: =IF(V17 = 0, 0, IF(V15 = (V$7+W$7),1,0)) -> 0 | W18: =IF(W17 = 0, 0, IF(W15 = (V$7+W$7),1,0)) -> 0 | X18: =IF(X17 = 0, 0, IF(X15 = (X$7+Y$7),1,0)) -> 1 | Y18: =IF(Y17 = 0, 0, IF(Y15 = (X$7+Y$7),1,0)) -> 0 | Z18: =IF(Z17 = 0, 0, IF(Z15 = (Z$7+AA$7),1,0)) -> 1 | AA18: =IF(AA17 = 0, 0, IF(AA15 = (Z$7+AA$7),1,0)) -> 0 | AC18: =IF(AC17 = 0, 0, IF(AC15 = (AC$7+AD$7),1,0)) -> 0 | AD18: =IF(AD17 = 0, 0, IF(AD15 = (AC$7+AD$7),1,0)) -> 0 | AE18: =IF(AE17 = 0, 0, IF(AE15 = (AE$7+AF$7),1,0)) -> 0 | AF18: =IF(AF17 = 0, 0, IF(AF15 = (AE$7+AF$7),1,0)) -> 1 | AH18: =IF(AH17 = 0, 0, IF(AH15 = (AH$7+AI$7),1,0)) -> 0 | AI18: =IF(AI17 = 0, 0, IF(AI15 = (AH$7+AI$7),1,0)) -> 0 | AK18: =SUM(C18:AI18) -> 4
A19: =RANK(AL19,$AL$11:$AL$98,) -> 3 | B19: Alex Levac | C19: 7 | E19: 6 | H19: 6 | J19: 7 | K19: 5 | M19: 7 | O19: 6 | Q19: 6 | S19: =SUM(C20:R20) -> 32 | U19: 7 | W19: 6 | X19: 7 | Z19: 6 | AB19: =SUM(T20:AA20) -> 48 | AC19: 5 | AF19: 6 | AG19: =SUM(AC20:AF20) -> 44 | AH19: 6 | AJ19: =AH20 -> 3 | AK19: =MAX($AL$11:$AL$98) - AL19 -> 10 | AL19: =$S19+$AB19+$AG19+$AJ19 -> 127
A20: =RANK(AL20,$AL$11:$AL$98,) -> #N/A | C20: =(IF($C19<>"",($C$7*$O$105)+IF($C$7=4,($O$103)+IF($C19=$C$7+$D$7,$O$104,0),0),0)+IF($D19<>"",($D$7*$O$105)+IF($D$7=4,($O$103)+IF($D19=$C$7+$D$7,$O$104,0),0),0)) -> 0 | E20: =(IF($E19<>"",($E$7*$O$105)+IF($E$7=4,($O$103)+IF($E19=$E$7+$F$7,$O$104,0),0),0)+IF($F19<>"",($F$7*$O$105)+IF($F$7=4,($O$103)+IF($F19=$E$7+$F$7,$O$104,0),0),0)) -> 9 | G20: =(IF($G19<>"",($G$7*$O$105)+IF($G$7=4,($O$103)+IF($G19=$G$7+$H$7,$O$104,0),0),0)+IF($H19<>"",($H$7*$O$105)+IF($H$7=4,($O$103)+IF($H19=$G$7+$H$7,$O$104,0),0),0)) -> 9 | I20: =(IF($I19<>"",($I$7*$O$105)+IF($I$7=4,($O$103)+IF($I19=$I$7+$J$7,$O$104,0),0),0)+IF($J19<>"",($J$7*$O$105)+IF($J$7=4,($O$103)+IF($J19=$I$7+$J$7,$O$104,0),0),0)) -> 0 | K20: =(IF($K19<>"",($K$7*$O$105)+IF($K$7=4,($O$103)+IF($K19=$K$7+$L$7,$O$104,0),0),0)+IF($L19<>"",($L$7*$O$105)+IF($L$7=4,($O$103)+IF($L19=$K$7+$L$7,$O$104,0),0),0)) -> 1 | M20: =(IF($M19<>"",($M$7*$O$105)+IF($M$7=4,($O$103)+IF($M19=$M$7+$N$7,$O$104,0),0),0)+IF($N19<>"",($N$7*$O$105)+IF($N$7=4,($O$103)+IF($N19=$M$7+$N$7,$O$104,0),0),0)) -> 2 | O20: =(IF($O19<>"",($O$7*$O$105)+IF($O$7=4,($O$103)+IF($O19=$O$7+$P$7,$O$104,0),0),0)+IF($P19<>"",($P$7*$O$105)+IF($P$7=4,($O$103)+IF($P19=$O$7+$P$7,$O$104,0),0),0)) -> 2 | Q20: =(IF($Q19<>"",($Q$7*$O$105)+IF($Q$7=4,($O$103)+IF($Q19=$Q$7+$R$7,$O$104,0),0),0)+IF($R19<>"",($R$7*$O$105)+IF($R$7=4,($O$103)+IF($R19=$Q$7+$R$7,$O$104,0),0),0)) -> 9 | T20: =(IF($T19<>"",($T$7*$P$105)+IF($T$7=4,($P$103)+IF($T19=$T$7+$U$7,$P$104,0),0),0)+IF($U19<>"",($U$7*$P$105)+IF($U$7=4,($P$103)+IF($U19=$T$7+$U$7,$P$104,0),0),0)) -> 2 | V20: =(IF($V19<>"",($V$7*$P$105)+IF($V$7=4,($P$103)+IF($V19=$V$7+$W$7,$P$104,0),0),0)+IF($W19<>"",($W$7*$P$105)+IF($W$7=4,($P$103)+IF($W19=$V$7+$W$7,$P$104,0),0),0)) -> 14 | X20: =(IF($X19<>"",($X$7*$P$105)+IF($X$7=4,($P$103)+IF($X19=$X$7+$Y$7,$P$104,0),0),0)+IF($Y19<>"",($Y$7*$P$105)+IF($Y$7=4,($P$103)+IF($Y19=$X$7+$Y$7,$P$104,0),0),0)) -> 18 | Z20: =(IF($Z19<>"",($Z$7*$P$105)+IF($Z$7=4,($P$103)+IF($Z19=$Z$7+$AA$7,$P$104,0),0),0)+IF($AA19<>"",($AA$7*$P$105)+IF($AA$7=4,($P$103)+IF($AA19=$Z$7+$AA$7,$P$104,0),0),0)) -> 14 | AC20: =(IF($AC19<>"",($AC$7*$Q$105)+IF($AC$7=4,($Q$103)+IF($AC19=$AC$7+$AD$7,$Q$104,0),0),0)+IF($AD19<>"",($AD$7*$Q$105)+IF($AD$7=4,($Q$103)+IF($AD19=$AC$7+$AD$7,$Q$104,0),0),0)) -> 19 | AE20: =(IF($AE19<>"",($AE$7*$Q$105)+IF($AE$7=4,($Q$103)+IF($AE19=$AE$7+$AF$7,$Q$104,0),0),0)+IF($AF19<>"",($AF$7*$Q$105)+IF($AF$7=4,($Q$103)+IF($AF19=$AE$7+$AF$7,$Q$104,0),0),0)) -> 25 | AH20: =(IF($AH19<>"",($AH$7*$Q$105)+IF($AH$7=4,($R$103)+IF($AH19=$AH$7+$AI$7,$R$104,0),0),0)+IF($AI19<>"",($AI$7*$R$105)+IF($AI$7=4,($R$103)+IF($AI19=$AH$7+$AI$7,$R$104,0),0),0)) -> 3 | AK20: =MAX($AL$11:$AL$98) - AL20 -> 137
B21: Prédiction équipe | C21: =IF(ISBLANK(C19), 0, IF(C$7= 4, 1, 0)) -> 0 | D21: =IF(ISBLANK(D19), 0, IF(D$7 = 4, 1, 0)) -> 0 | E21: =IF(ISBLANK(E19), 0, IF(E$7= 4, 1, 0)) -> 1 | F21: =IF(ISBLANK(F19), 0, IF(F$7 = 4, 1, 0)) -> 0 | G21: =IF(ISBLANK(G19), 0, IF(G$7= 4, 1, 0)) -> 0 | H21: =IF(ISBLANK(H19), 0, IF(H$7 = 4, 1, 0)) -> 1 | I21: =IF(ISBLANK(I19), 0, IF(I$7= 4, 1, 0)) -> 0 | J21: =IF(ISBLANK(J19), 0, IF(J$7 = 4, 1, 0)) -> 0 | K21: =IF(ISBLANK(K19), 0, IF(K$7= 4, 1, 0)) -> 0 | L21: =IF(ISBLANK(L19), 0, IF(L$7 = 4, 1, 0)) -> 0 | M21: =IF(ISBLANK(M19), 0, IF(M$7= 4, 1, 0)) -> 0 | N21: =IF(ISBLANK(N19), 0, IF(N$7 = 4, 1, 0)) -> 0 | O21: =IF(ISBLANK(O19), 0, IF(O$7= 4, 1, 0)) -> 0 | P21: =IF(ISBLANK(P19), 0, IF(P$7 = 4, 1, 0)) -> 0 | Q21: =IF(ISBLANK(Q19), 0, IF(Q$7= 4, 1, 0)) -> 1 | R21: =IF(ISBLANK(R19), 0, IF(R$7 = 4, 1, 0)) -> 0 | T21: =IF(ISBLANK(T19), 0, IF(T$7= 4, 1, 0)) -> 0 | U21: =IF(ISBLANK(U19), 0, IF(U$7 = 4, 1, 0)) -> 0 | V21: =IF(ISBLANK(V19), 0, IF(V$7= 4, 1, 0)) -> 0 | W21: =IF(ISBLANK(W19), 0, IF(W$7 = 4, 1, 0)) -> 1 | X21: =IF(ISBLANK(X19), 0, IF(X$7= 4, 1, 0)) -> 1 | Y21: =IF(ISBLANK(Y19), 0, IF(Y$7 = 4, 1, 0)) -> 0 | Z21: =IF(ISBLANK(Z19), 0, IF(Z$7= 4, 1, 0)) -> 1 | AA21: =IF(ISBLANK(AA19), 0, IF(AA$7 = 4, 1, 0)) -> 0 | AC21: =IF(ISBLANK(AC19), 0, IF(AC$7= 4, 1, 0)) -> 1 | AD21: =IF(ISBLANK(AD19), 0, IF(AD$7 = 4, 1, 0)) -> 0 | AE21: =IF(ISBLANK(AE19), 0, IF(AE$7= 4, 1, 0)) -> 0 | AF21: =IF(ISBLANK(AF19), 0, IF(AF$7 = 4, 1, 0)) -> 1 | AH21: =IF(ISBLANK(AH19), 0, IF(AH$7= 4, 1, 0)) -> 0 | AI21: =IF(ISBLANK(AI19), 0, IF(AI$7 = 4, 1, 0)) -> 0 | AK21: =SUM(C21:AI21) -> 8
B22: Prédiciton nb matchs | C22: =IF(C21 = 0, 0, IF(C19 = (C$7+D$7),1,0)) -> 0 | D22: =IF(D21 = 0, 0, IF(D19 = (C$7+D$7),1,0)) -> 0 | E22: =IF(E21 = 0, 0, IF(E19 = (E$7+F$7),1,0)) -> 0 | F22: =IF(F21 = 0, 0, IF(F19 = (E$7+F$7),1,0)) -> 0 | G22: =IF(G21 = 0, 0, IF(G19 = (G$7+H$7),1,0)) -> 0 | H22: =IF(H21 = 0, 0, IF(H19 = (G$7+H$7),1,0)) -> 0 | I22: =IF(I21 = 0, 0, IF(I19 = (I$7+J$7),1,0)) -> 0 | J22: =IF(J21 = 0, 0, IF(J19 = (I$7+J$7),1,0)) -> 0 | K22: =IF(K21 = 0, 0, IF(K19 = (K$7+L$7),1,0)) -> 0 | L22: =IF(L21 = 0, 0, IF(L19 = (K$7+L$7),1,0)) -> 0 | M22: =IF(M21 = 0, 0, IF(M19 = (M$7+N$7),1,0)) -> 0 | N22: =IF(N21 = 0, 0, IF(N19 = (M$7+N$7),1,0)) -> 0 | O22: =IF(O21 = 0, 0, IF(O19 = (O$7+P$7),1,0)) -> 0 | P22: =IF(P21 = 0, 0, IF(P19 = (O$7+P$7),1,0)) -> 0 | Q22: =IF(Q21 = 0, 0, IF(Q19 = (Q$7+R$7),1,0)) -> 0 | R22: =IF(R21 = 0, 0, IF(R19 = (Q$7+R$7),1,0)) -> 0 | T22: =IF(T21 = 0, 0, IF(T19 = (T$7+U$7),1,0)) -> 0 | U22: =IF(U21 = 0, 0, IF(U19 = (T$7+U$7),1,0)) -> 0 | V22: =IF(V21 = 0, 0, IF(V19 = (V$7+W$7),1,0)) -> 0 | W22: =IF(W21 = 0, 0, IF(W19 = (V$7+W$7),1,0)) -> 0 | X22: =IF(X21 = 0, 0, IF(X19 = (X$7+Y$7),1,0)) -> 1 | Y22: =IF(Y21 = 0, 0, IF(Y19 = (X$7+Y$7),1,0)) -> 0 | Z22: =IF(Z21 = 0, 0, IF(Z19 = (Z$7+AA$7),1,0)) -> 0 | AA22: =IF(AA21 = 0, 0, IF(AA19 = (Z$7+AA$7),1,0)) -> 0 | AC22: =IF(AC21 = 0, 0, IF(AC19 = (AC$7+AD$7),1,0)) -> 0 | AD22: =IF(AD21 = 0, 0, IF(AD19 = (AC$7+AD$7),1,0)) -> 0 | AE22: =IF(AE21 = 0, 0, IF(AE19 = (AE$7+AF$7),1,0)) -> 0 | AF22: =IF(AF21 = 0, 0, IF(AF19 = (AE$7+AF$7),1,0)) -> 1 | AH22: =IF(AH21 = 0, 0, IF(AH19 = (AH$7+AI$7),1,0)) -> 0 | AI22: =IF(AI21 = 0, 0, IF(AI19 = (AH$7+AI$7),1,0)) -> 0 | AK22: =SUM(C22:AI22) -> 2
A23: =RANK(AL23,$AL$11:$AL$98,) -> 4 | B23: Pierre Daoust | C23: 5 | E23: 6 | H23: 7 | J23: 6 | K23: 5 | N23: 7 | O23: 5 | R23: 6 | S23: =SUM(C24:R24) -> 35 | U23: 7 | W23: 7 | X23: 6 | Z23: 6 | AB23: =SUM(T24:AA24) -> 44 | AC23: 7 | AF23: 7 | AG23: =SUM(AC24:AF24) -> 38 | AH23: 6 | AJ23: =AH24 -> 3 | AK23: =MAX($AL$11:$AL$98) - AL23 -> 17 | AL23: =$S23+$AB23+$AG23+$AJ23 -> 120
A24: =RANK(AL24,$AL$11:$AL$98,) -> #N/A | C24: =(IF($C23<>"",($C$7*$O$105)+IF($C$7=4,($O$103)+IF($C23=$C$7+$D$7,$O$104,0),0),0)+IF($D23<>"",($D$7*$O$105)+IF($D$7=4,($O$103)+IF($D23=$C$7+$D$7,$O$104,0),0),0)) -> 0 | E24: =(IF($E23<>"",($E$7*$O$105)+IF($E$7=4,($O$103)+IF($E23=$E$7+$F$7,$O$104,0),0),0)+IF($F23<>"",($F$7*$O$105)+IF($F$7=4,($O$103)+IF($F23=$E$7+$F$7,$O$104,0),0),0)) -> 9 | G24: =(IF($G23<>"",($G$7*$O$105)+IF($G$7=4,($O$103)+IF($G23=$G$7+$H$7,$O$104,0),0),0)+IF($H23<>"",($H$7*$O$105)+IF($H$7=4,($O$103)+IF($H23=$G$7+$H$7,$O$104,0),0),0)) -> 11 | I24: =(IF($I23<>"",($I$7*$O$105)+IF($I$7=4,($O$103)+IF($I23=$I$7+$J$7,$O$104,0),0),0)+IF($J23<>"",($J$7*$O$105)+IF($J$7=4,($O$103)+IF($J23=$I$7+$J$7,$O$104,0),0),0)) -> 0 | K24: =(IF($K23<>"",($K$7*$O$105)+IF($K$7=4,($O$103)+IF($K23=$K$7+$L$7,$O$104,0),0),0)+IF($L23<>"",($L$7*$O$105)+IF($L$7=4,($O$103)+IF($L23=$K$7+$L$7,$O$104,0),0),0)) -> 1 | M24: =(IF($M23<>"",($M$7*$O$105)+IF($M$7=4,($O$103)+IF($M23=$M$7+$N$7,$O$104,0),0),0)+IF($N23<>"",($N$7*$O$105)+IF($N$7=4,($O$103)+IF($N23=$M$7+$N$7,$O$104,0),0),0)) -> 9 | O24: =(IF($O23<>"",($O$7*$O$105)+IF($O$7=4,($O$103)+IF($O23=$O$7+$P$7,$O$104,0),0),0)+IF($P23<>"",($P$7*$O$105)+IF($P$7=4,($O$103)+IF($P23=$O$7+$P$7,$O$104,0),0),0)) -> 2 | Q24: =(IF($Q23<>"",($Q$7*$O$105)+IF($Q$7=4,($O$103)+IF($Q23=$Q$7+$R$7,$O$104,0),0),0)+IF($R23<>"",($R$7*$O$105)+IF($R$7=4,($O$103)+IF($R23=$Q$7+$R$7,$O$104,0),0),0)) -> 3 | T24: =(IF($T23<>"",($T$7*$P$105)+IF($T$7=4,($P$103)+IF($T23=$T$7+$U$7,$P$104,0),0),0)+IF($U23<>"",($U$7*$P$105)+IF($U$7=4,($P$103)+IF($U23=$T$7+$U$7,$P$104,0),0),0)) -> 2 | V24: =(IF($V23<>"",($V$7*$P$105)+IF($V$7=4,($P$103)+IF($V23=$V$7+$W$7,$P$104,0),0),0)+IF($W23<>"",($W$7*$P$105)+IF($W$7=4,($P$103)+IF($W23=$V$7+$W$7,$P$104,0),0),0)) -> 14 | X24: =(IF($X23<>"",($X$7*$P$105)+IF($X$7=4,($P$103)+IF($X23=$X$7+$Y$7,$P$104,0),0),0)+IF($Y23<>"",($Y$7*$P$105)+IF($Y$7=4,($P$103)+IF($Y23=$X$7+$Y$7,$P$104,0),0),0)) -> 14 | Z24: =(IF($Z23<>"",($Z$7*$P$105)+IF($Z$7=4,($P$103)+IF($Z23=$Z$7+$AA$7,$P$104,0),0),0)+IF($AA23<>"",($AA$7*$P$105)+IF($AA$7=4,($P$103)+IF($AA23=$Z$7+$AA$7,$P$104,0),0),0)) -> 14 | AC24: =(IF($AC23<>"",($AC$7*$Q$105)+IF($AC$7=4,($Q$103)+IF($AC23=$AC$7+$AD$7,$Q$104,0),0),0)+IF($AD23<>"",($AD$7*$Q$105)+IF($AD$7=4,($Q$103)+IF($AD23=$AC$7+$AD$7,$Q$104,0),0),0)) -> 19 | AE24: =(IF($AE23<>"",($AE$7*$Q$105)+IF($AE$7=4,($Q$103)+IF($AE23=$AE$7+$AF$7,$Q$104,0),0),0)+IF($AF23<>"",($AF$7*$Q$105)+IF($AF$7=4,($Q$103)+IF($AF23=$AE$7+$AF$7,$Q$104,0),0),0)) -> 19 | AH24: =(IF($AH23<>"",($AH$7*$Q$105)+IF($AH$7=4,($R$103)+IF($AH23=$AH$7+$AI$7,$R$104,0),0),0)+IF($AI23<>"",($AI$7*$R$105)+IF($AI$7=4,($R$103)+IF($AI23=$AH$7+$AI$7,$R$104,0),0),0)) -> 3 | AK24: =MAX($AL$11:$AL$98) - AL24 -> 137
B25: Prédiction équipe | C25: =IF(ISBLANK(C23), 0, IF(C$7= 4, 1, 0)) -> 0 | D25: =IF(ISBLANK(D23), 0, IF(D$7 = 4, 1, 0)) -> 0 | E25: =IF(ISBLANK(E23), 0, IF(E$7= 4, 1, 0)) -> 1 | F25: =IF(ISBLANK(F23), 0, IF(F$7 = 4, 1, 0)) -> 0 | G25: =IF(ISBLANK(G23), 0, IF(G$7= 4, 1, 0)) -> 0 | H25: =IF(ISBLANK(H23), 0, IF(H$7 = 4, 1, 0)) -> 1 | I25: =IF(ISBLANK(I23), 0, IF(I$7= 4, 1, 0)) -> 0 | J25: =IF(ISBLANK(J23), 0, IF(J$7 = 4, 1, 0)) -> 0 | K25: =IF(ISBLANK(K23), 0, IF(K$7= 4, 1, 0)) -> 0 | L25: =IF(ISBLANK(L23), 0, IF(L$7 = 4, 1, 0)) -> 0 | M25: =IF(ISBLANK(M23), 0, IF(M$7= 4, 1, 0)) -> 0 | N25: =IF(ISBLANK(N23), 0, IF(N$7 = 4, 1, 0)) -> 1 | O25: =IF(ISBLANK(O23), 0, IF(O$7= 4, 1, 0)) -> 0 | P25: =IF(ISBLANK(P23), 0, IF(P$7 = 4, 1, 0)) -> 0 | Q25: =IF(ISBLANK(Q23), 0, IF(Q$7= 4, 1, 0)) -> 0 | R25: =IF(ISBLANK(R23), 0, IF(R$7 = 4, 1, 0)) -> 0 | T25: =IF(ISBLANK(T23), 0, IF(T$7= 4, 1, 0)) -> 0 | U25: =IF(ISBLANK(U23), 0, IF(U$7 = 4, 1, 0)) -> 0 | V25: =IF(ISBLANK(V23), 0, IF(V$7= 4, 1, 0)) -> 0 | W25: =IF(ISBLANK(W23), 0, IF(W$7 = 4, 1, 0)) -> 1 | X25: =IF(ISBLANK(X23), 0, IF(X$7= 4, 1, 0)) -> 1 | Y25: =IF(ISBLANK(Y23), 0, IF(Y$7 = 4, 1, 0)) -> 0 | Z25: =IF(ISBLANK(Z23), 0, IF(Z$7= 4, 1, 0)) -> 1 | AA25: =IF(ISBLANK(AA23), 0, IF(AA$7 = 4, 1, 0)) -> 0 | AC25: =IF(ISBLANK(AC23), 0, IF(AC$7= 4, 1, 0)) -> 1 | AD25: =IF(ISBLANK(AD23), 0, IF(AD$7 = 4, 1, 0)) -> 0 | AE25: =IF(ISBLANK(AE23), 0, IF(AE$7= 4, 1, 0)) -> 0 | AF25: =IF(ISBLANK(AF23), 0, IF(AF$7 = 4, 1, 0)) -> 1 | AH25: =IF(ISBLANK(AH23), 0, IF(AH$7= 4, 1, 0)) -> 0 | AI25: =IF(ISBLANK(AI23), 0, IF(AI$7 = 4, 1, 0)) -> 0 | AK25: =SUM(C25:AI25) -> 8
B26: Prédiciton nb matchs | C26: =IF(C25 = 0, 0, IF(C23 = (C$7+D$7),1,0)) -> 0 | D26: =IF(D25 = 0, 0, IF(D23 = (C$7+D$7),1,0)) -> 0 | E26: =IF(E25 = 0, 0, IF(E23 = (E$7+F$7),1,0)) -> 0 | F26: =IF(F25 = 0, 0, IF(F23 = (E$7+F$7),1,0)) -> 0 | G26: =IF(G25 = 0, 0, IF(G23 = (G$7+H$7),1,0)) -> 0 | H26: =IF(H25 = 0, 0, IF(H23 = (G$7+H$7),1,0)) -> 1 | I26: =IF(I25 = 0, 0, IF(I23 = (I$7+J$7),1,0)) -> 0 | J26: =IF(J25 = 0, 0, IF(J23 = (I$7+J$7),1,0)) -> 0 | K26: =IF(K25 = 0, 0, IF(K23 = (K$7+L$7),1,0)) -> 0 | L26: =IF(L25 = 0, 0, IF(L23 = (K$7+L$7),1,0)) -> 0 | M26: =IF(M25 = 0, 0, IF(M23 = (M$7+N$7),1,0)) -> 0 | N26: =IF(N25 = 0, 0, IF(N23 = (M$7+N$7),1,0)) -> 0 | O26: =IF(O25 = 0, 0, IF(O23 = (O$7+P$7),1,0)) -> 0 | P26: =IF(P25 = 0, 0, IF(P23 = (O$7+P$7),1,0)) -> 0 | Q26: =IF(Q25 = 0, 0, IF(Q23 = (Q$7+R$7),1,0)) -> 0 | R26: =IF(R25 = 0, 0, IF(R23 = (Q$7+R$7),1,0)) -> 0 | T26: =IF(T25 = 0, 0, IF(T23 = (T$7+U$7),1,0)) -> 0 | U26: =IF(U25 = 0, 0, IF(U23 = (T$7+U$7),1,0)) -> 0 | V26: =IF(V25 = 0, 0, IF(V23 = (V$7+W$7),1,0)) -> 0 | W26: =IF(W25 = 0, 0, IF(W23 = (V$7+W$7),1,0)) -> 0 | X26: =IF(X25 = 0, 0, IF(X23 = (X$7+Y$7),1,0)) -> 0 | Y26: =IF(Y25 = 0, 0, IF(Y23 = (X$7+Y$7),1,0)) -> 0 | Z26: =IF(Z25 = 0, 0, IF(Z23 = (Z$7+AA$7),1,0)) -> 0 | AA26: =IF(AA25 = 0, 0, IF(AA23 = (Z$7+AA$7),1,0)) -> 0 | AC26: =IF(AC25 = 0, 0, IF(AC23 = (AC$7+AD$7),1,0)) -> 0 | AD26: =IF(AD25 = 0, 0, IF(AD23 = (AC$7+AD$7),1,0)) -> 0 | AE26: =IF(AE25 = 0, 0, IF(AE23 = (AE$7+AF$7),1,0)) -> 0 | AF26: =IF(AF25 = 0, 0, IF(AF23 = (AE$7+AF$7),1,0)) -> 0 | AH26: =IF(AH25 = 0, 0, IF(AH23 = (AH$7+AI$7),1,0)) -> 0 | AI26: =IF(AI25 = 0, 0, IF(AI23 = (AH$7+AI$7),1,0)) -> 0 | AK26: =SUM(C26:AI26) -> 1
A27: =RANK(AL27,$AL$11:$AL$98,) -> 5 | B27: Pierre Trépanier | C27: 5 | E27: 6 | G27: 6 | J27: 7 | K27: 5 | N27: 6 | O27: 7 | R27: 6 | S27: =SUM(C28:R28) -> 29 | U27: 6 | V27: 5 | Y27: 5 | Z27: 6 | AB27: =SUM(T28:AA28) -> 19 | AC27: 6 | AF27: 6 | AG27: =SUM(AC28:AF28) -> 44 | AI27: 5 | AJ27: =AH28 -> 24 | AK27: =MAX($AL$11:$AL$98) - AL27 -> 21 | AL27: =$S27+$AB27+$AG27+$AJ27 -> 116
A28: =RANK(AL28,$AL$11:$AL$98,) -> #N/A | C28: =(IF($C27<>"",($C$7*$O$105)+IF($C$7=4,($O$103)+IF($C27=$C$7+$D$7,$O$104,0),0),0)+IF($D27<>"",($D$7*$O$105)+IF($D$7=4,($O$103)+IF($D27=$C$7+$D$7,$O$104,0),0),0)) -> 0 | E28: =(IF($E27<>"",($E$7*$O$105)+IF($E$7=4,($O$103)+IF($E27=$E$7+$F$7,$O$104,0),0),0)+IF($F27<>"",($F$7*$O$105)+IF($F$7=4,($O$103)+IF($F27=$E$7+$F$7,$O$104,0),0),0)) -> 9 | G28: =(IF($G27<>"",($G$7*$O$105)+IF($G$7=4,($O$103)+IF($G27=$G$7+$H$7,$O$104,0),0),0)+IF($H27<>"",($H$7*$O$105)+IF($H$7=4,($O$103)+IF($H27=$G$7+$H$7,$O$104,0),0),0)) -> 3 | I28: =(IF($I27<>"",($I$7*$O$105)+IF($I$7=4,($O$103)+IF($I27=$I$7+$J$7,$O$104,0),0),0)+IF($J27<>"",($J$7*$O$105)+IF($J$7=4,($O$103)+IF($J27=$I$7+$J$7,$O$104,0),0),0)) -> 0 | K28: =(IF($K27<>"",($K$7*$O$105)+IF($K$7=4,($O$103)+IF($K27=$K$7+$L$7,$O$104,0),0),0)+IF($L27<>"",($L$7*$O$105)+IF($L$7=4,($O$103)+IF($L27=$K$7+$L$7,$O$104,0),0),0)) -> 1 | M28: =(IF($M27<>"",($M$7*$O$105)+IF($M$7=4,($O$103)+IF($M27=$M$7+$N$7,$O$104,0),0),0)+IF($N27<>"",($N$7*$O$105)+IF($N$7=4,($O$103)+IF($N27=$M$7+$N$7,$O$104,0),0),0)) -> 11 | O28: =(IF($O27<>"",($O$7*$O$105)+IF($O$7=4,($O$103)+IF($O27=$O$7+$P$7,$O$104,0),0),0)+IF($P27<>"",($P$7*$O$105)+IF($P$7=4,($O$103)+IF($P27=$O$7+$P$7,$O$104,0),0),0)) -> 2 | Q28: =(IF($Q27<>"",($Q$7*$O$105)+IF($Q$7=4,($O$103)+IF($Q27=$Q$7+$R$7,$O$104,0),0),0)+IF($R27<>"",($R$7*$O$105)+IF($R$7=4,($O$103)+IF($R27=$Q$7+$R$7,$O$104,0),0),0)) -> 3 | T28: =(IF($T27<>"",($T$7*$P$105)+IF($T$7=4,($P$103)+IF($T27=$T$7+$U$7,$P$104,0),0),0)+IF($U27<>"",($U$7*$P$105)+IF($U$7=4,($P$103)+IF($U27=$T$7+$U$7,$P$104,0),0),0)) -> 2 | V28: =(IF($V27<>"",($V$7*$P$105)+IF($V$7=4,($P$103)+IF($V27=$V$7+$W$7,$P$104,0),0),0)+IF($W27<>"",($W$7*$P$105)+IF($W$7=4,($P$103)+IF($W27=$V$7+$W$7,$P$104,0),0),0)) -> 0 | X28: =(IF($X27<>"",($X$7*$P$105)+IF($X$7=4,($P$103)+IF($X27=$X$7+$Y$7,$P$104,0),0),0)+IF($Y27<>"",($Y$7*$P$105)+IF($Y$7=4,($P$103)+IF($Y27=$X$7+$Y$7,$P$104,0),0),0)) -> 3 | Z28: =(IF($Z27<>"",($Z$7*$P$105)+IF($Z$7=4,($P$103)+IF($Z27=$Z$7+$AA$7,$P$104,0),0),0)+IF($AA27<>"",($AA$7*$P$105)+IF($AA$7=4,($P$103)+IF($AA27=$Z$7+$AA$7,$P$104,0),0),0)) -> 14 | AC28: =(IF($AC27<>"",($AC$7*$Q$105)+IF($AC$7=4,($Q$103)+IF($AC27=$AC$7+$AD$7,$Q$104,0),0),0)+IF($AD27<>"",($AD$7*$Q$105)+IF($AD$7=4,($Q$103)+IF($AD27=$AC$7+$AD$7,$Q$104,0),0),0)) -> 19 | AE28: =(IF($AE27<>"",($AE$7*$Q$105)+IF($AE$7=4,($Q$103)+IF($AE27=$AE$7+$AF$7,$Q$104,0),0),0)+IF($AF27<>"",($AF$7*$Q$105)+IF($AF$7=4,($Q$103)+IF($AF27=$AE$7+$AF$7,$Q$104,0),0),0)) -> 25 | AH28: =(IF($AH27<>"",($AH$7*$Q$105)+IF($AH$7=4,($R$103)+IF($AH27=$AH$7+$AI$7,$R$104,0),0),0)+IF($AI27<>"",($AI$7*$R$105)+IF($AI$7=4,($R$103)+IF($AI27=$AH$7+$AI$7,$R$104,0),0),0)) -> 24 | AK28: =MAX($AL$11:$AL$98) - AL28 -> 137
B29: Prédiction équipe | C29: =IF(ISBLANK(C27), 0, IF(C$7= 4, 1, 0)) -> 0 | D29: =IF(ISBLANK(D27), 0, IF(D$7 = 4, 1, 0)) -> 0 | E29: =IF(ISBLANK(E27), 0, IF(E$7= 4, 1, 0)) -> 1 | F29: =IF(ISBLANK(F27), 0, IF(F$7 = 4, 1, 0)) -> 0 | G29: =IF(ISBLANK(G27), 0, IF(G$7= 4, 1, 0)) -> 0 | H29: =IF(ISBLANK(H27), 0, IF(H$7 = 4, 1, 0)) -> 0 | I29: =IF(ISBLANK(I27), 0, IF(I$7= 4, 1, 0)) -> 0 | J29: =IF(ISBLANK(J27), 0, IF(J$7 = 4, 1, 0)) -> 0 | K29: =IF(ISBLANK(K27), 0, IF(K$7= 4, 1, 0)) -> 0 | L29: =IF(ISBLANK(L27), 0, IF(L$7 = 4, 1, 0)) -> 0 | M29: =IF(ISBLANK(M27), 0, IF(M$7= 4, 1, 0)) -> 0 | N29: =IF(ISBLANK(N27), 0, IF(N$7 = 4, 1, 0)) -> 1 | O29: =IF(ISBLANK(O27), 0, IF(O$7= 4, 1, 0)) -> 0 | P29: =IF(ISBLANK(P27), 0, IF(P$7 = 4, 1, 0)) -> 0 | Q29: =IF(ISBLANK(Q27), 0, IF(Q$7= 4, 1, 0)) -> 0 | R29: =IF(ISBLANK(R27), 0, IF(R$7 = 4, 1, 0)) -> 0 | T29: =IF(ISBLANK(T27), 0, IF(T$7= 4, 1, 0)) -> 0 | U29: =IF(ISBLANK(U27), 0, IF(U$7 = 4, 1, 0)) -> 0 | V29: =IF(ISBLANK(V27), 0, IF(V$7= 4, 1, 0)) -> 0 | W29: =IF(ISBLANK(W27), 0, IF(W$7 = 4, 1, 0)) -> 0 | X29: =IF(ISBLANK(X27), 0, IF(X$7= 4, 1, 0)) -> 0 | Y29: =IF(ISBLANK(Y27), 0, IF(Y$7 = 4, 1, 0)) -> 0 | Z29: =IF(ISBLANK(Z27), 0, IF(Z$7= 4, 1, 0)) -> 1 | AA29: =IF(ISBLANK(AA27), 0, IF(AA$7 = 4, 1, 0)) -> 0 | AC29: =IF(ISBLANK(AC27), 0, IF(AC$7= 4, 1, 0)) -> 1 | AD29: =IF(ISBLANK(AD27), 0, IF(AD$7 = 4, 1, 0)) -> 0 | AE29: =IF(ISBLANK(AE27), 0, IF(AE$7= 4, 1, 0)) -> 0 | AF29: =IF(ISBLANK(AF27), 0, IF(AF$7 = 4, 1, 0)) -> 1 | AH29: =IF(ISBLANK(AH27), 0, IF(AH$7= 4, 1, 0)) -> 0 | AI29: =IF(ISBLANK(AI27), 0, IF(AI$7 = 4, 1, 0)) -> 1 | AK29: =SUM(C29:AI29) -> 6
B30: Prédiciton nb matchs | C30: =IF(C29 = 0, 0, IF(C27 = (C$7+D$7),1,0)) -> 0 | D30: =IF(D29 = 0, 0, IF(D27 = (C$7+D$7),1,0)) -> 0 | E30: =IF(E29 = 0, 0, IF(E27 = (E$7+F$7),1,0)) -> 0 | F30: =IF(F29 = 0, 0, IF(F27 = (E$7+F$7),1,0)) -> 0 | G30: =IF(G29 = 0, 0, IF(G27 = (G$7+H$7),1,0)) -> 0 | H30: =IF(H29 = 0, 0, IF(H27 = (G$7+H$7),1,0)) -> 0 | I30: =IF(I29 = 0, 0, IF(I27 = (I$7+J$7),1,0)) -> 0 | J30: =IF(J29 = 0, 0, IF(J27 = (I$7+J$7),1,0)) -> 0 | K30: =IF(K29 = 0, 0, IF(K27 = (K$7+L$7),1,0)) -> 0 | L30: =IF(L29 = 0, 0, IF(L27 = (K$7+L$7),1,0)) -> 0 | M30: =IF(M29 = 0, 0, IF(M27 = (M$7+N$7),1,0)) -> 0 | N30: =IF(N29 = 0, 0, IF(N27 = (M$7+N$7),1,0)) -> 1 | O30: =IF(O29 = 0, 0, IF(O27 = (O$7+P$7),1,0)) -> 0 | P30: =IF(P29 = 0, 0, IF(P27 = (O$7+P$7),1,0)) -> 0 | Q30: =IF(Q29 = 0, 0, IF(Q27 = (Q$7+R$7),1,0)) -> 0 | R30: =IF(R29 = 0, 0, IF(R27 = (Q$7+R$7),1,0)) -> 0 | T30: =IF(T29 = 0, 0, IF(T27 = (T$7+U$7),1,0)) -> 0 | U30: =IF(U29 = 0, 0, IF(U27 = (T$7+U$7),1,0)) -> 0 | V30: =IF(V29 = 0, 0, IF(V27 = (V$7+W$7),1,0)) -> 0 | W30: =IF(W29 = 0, 0, IF(W27 = (V$7+W$7),1,0)) -> 0 | X30: =IF(X29 = 0, 0, IF(X27 = (X$7+Y$7),1,0)) -> 0 | Y30: =IF(Y29 = 0, 0, IF(Y27 = (X$7+Y$7),1,0)) -> 0 | Z30: =IF(Z29 = 0, 0, IF(Z27 = (Z$7+AA$7),1,0)) -> 0 | AA30: =IF(AA29 = 0, 0, IF(AA27 = (Z$7+AA$7),1,0)) -> 0 | AC30: =IF(AC29 = 0, 0, IF(AC27 = (AC$7+AD$7),1,0)) -> 0 | AD30: =IF(AD29 = 0, 0, IF(AD27 = (AC$7+AD$7),1,0)) -> 0 | AE30: =IF(AE29 = 0, 0, IF(AE27 = (AE$7+AF$7),1,0)) -> 0 | AF30: =IF(AF29 = 0, 0, IF(AF27 = (AE$7+AF$7),1,0)) -> 1 | AH30: =IF(AH29 = 0, 0, IF(AH27 = (AH$7+AI$7),1,0)) -> 0 | AI30: =IF(AI29 = 0, 0, IF(AI27 = (AH$7+AI$7),1,0)) -> 0 | AK30: =SUM(C30:AI30) -> 2
A31: =RANK(AL31,$AL$11:$AL$98,) -> 6 | B31: Daniel Amyot | C31: 5 | E31: 6 | H31: 7 | J31: 6 | K31: 5 | N31: 6 | O31: 6 | Q31: 6 | S31: =SUM(C32:R32) -> 43 | U31: 6 | V31: 6 | X31: 5 | AA31: 7 | AB31: =SUM(T32:AA32) -> 19 | AC31: 6 | AE31: 6 | AG31: =SUM(AC32:AF32) -> 21 | AI31: 7 | AJ31: =AH32 -> 32 | AK31: =MAX($AL$11:$AL$98) - AL31 -> 22 | AL31: =$S31+$AB31+$AG31+$AJ31 -> 115
A32: =RANK(AL32,$AL$11:$AL$98,) -> #N/A | C32: =(IF($C31<>"",($C$7*$O$105)+IF($C$7=4,($O$103)+IF($C31=$C$7+$D$7,$O$104,0),0),0)+IF($D31<>"",($D$7*$O$105)+IF($D$7=4,($O$103)+IF($D31=$C$7+$D$7,$O$104,0),0),0)) -> 0 | E32: =(IF($E31<>"",($E$7*$O$105)+IF($E$7=4,($O$103)+IF($E31=$E$7+$F$7,$O$104,0),0),0)+IF($F31<>"",($F$7*$O$105)+IF($F$7=4,($O$103)+IF($F31=$E$7+$F$7,$O$104,0),0),0)) -> 9 | G32: =(IF($G31<>"",($G$7*$O$105)+IF($G$7=4,($O$103)+IF($G31=$G$7+$H$7,$O$104,0),0),0)+IF($H31<>"",($H$7*$O$105)+IF($H$7=4,($O$103)+IF($H31=$G$7+$H$7,$O$104,0),0),0)) -> 11 | I32: =(IF($I31<>"",($I$7*$O$105)+IF($I$7=4,($O$103)+IF($I31=$I$7+$J$7,$O$104,0),0),0)+IF($J31<>"",($J$7*$O$105)+IF($J$7=4,($O$103)+IF($J31=$I$7+$J$7,$O$104,0),0),0)) -> 0 | K32: =(IF($K31<>"",($K$7*$O$105)+IF($K$7=4,($O$103)+IF($K31=$K$7+$L$7,$O$104,0),0),0)+IF($L31<>"",($L$7*$O$105)+IF($L$7=4,($O$103)+IF($L31=$K$7+$L$7,$O$104,0),0),0)) -> 1 | M32: =(IF($M31<>"",($M$7*$O$105)+IF($M$7=4,($O$103)+IF($M31=$M$7+$N$7,$O$104,0),0),0)+IF($N31<>"",($N$7*$O$105)+IF($N$7=4,($O$103)+IF($N31=$M$7+$N$7,$O$104,0),0),0)) -> 11 | O32: =(IF($O31<>"",($O$7*$O$105)+IF($O$7=4,($O$103)+IF($O31=$O$7+$P$7,$O$104,0),0),0)+IF($P31<>"",($P$7*$O$105)+IF($P$7=4,($O$103)+IF($P31=$O$7+$P$7,$O$104,0),0),0)) -> 2 | Q32: =(IF($Q31<>"",($Q$7*$O$105)+IF($Q$7=4,($O$103)+IF($Q31=$Q$7+$R$7,$O$104,0),0),0)+IF($R31<>"",($R$7*$O$105)+IF($R$7=4,($O$103)+IF($R31=$Q$7+$R$7,$O$104,0),0),0)) -> 9 | T32: =(IF($T31<>"",($T$7*$P$105)+IF($T$7=4,($P$103)+IF($T31=$T$7+$U$7,$P$104,0),0),0)+IF($U31<>"",($U$7*$P$105)+IF($U$7=4,($P$103)+IF($U31=$T$7+$U$7,$P$104,0),0),0)) -> 2 | V32: =(IF($V31<>"",($V$7*$P$105)+IF($V$7=4,($P$103)+IF($V31=$V$7+$W$7,$P$104,0),0),0)+IF($W31<>"",($W$7*$P$105)+IF($W$7=4,($P$103)+IF($W31=$V$7+$W$7,$P$104,0),0),0)) -> 0 | X32: =(IF($X31<>"",($X$7*$P$105)+IF($X$7=4,($P$103)+IF($X31=$X$7+$Y$7,$P$104,0),0),0)+IF($Y31<>"",($Y$7*$P$105)+IF($Y$7=4,($P$103)+IF($Y31=$X$7+$Y$7,$P$104,0),0),0)) -> 14 | Z32: =(IF($Z31<>"",($Z$7*$P$105)+IF($Z$7=4,($P$103)+IF($Z31=$Z$7+$AA$7,$P$104,0),0),0)+IF($AA31<>"",($AA$7*$P$105)+IF($AA$7=4,($P$103)+IF($AA31=$Z$7+$AA$7,$P$104,0),0),0)) -> 3 | AC32: =(IF($AC31<>"",($AC$7*$Q$105)+IF($AC$7=4,($Q$103)+IF($AC31=$AC$7+$AD$7,$Q$104,0),0),0)+IF($AD31<>"",($AD$7*$Q$105)+IF($AD$7=4,($Q$103)+IF($AD31=$AC$7+$AD$7,$Q$104,0),0),0)) -> 19 | AE32: =(IF($AE31<>"",($AE$7*$Q$105)+IF($AE$7=4,($Q$103)+IF($AE31=$AE$7+$AF$7,$Q$104,0),0),0)+IF($AF31<>"",($AF$7*$Q$105)+IF($AF$7=4,($Q$103)+IF($AF31=$AE$7+$AF$7,$Q$104,0),0),0)) -> 2 | AH32: =(IF($AH31<>"",($AH$7*$Q$105)+IF($AH$7=4,($R$103)+IF($AH31=$AH$7+$AI$7,$R$104,0),0),0)+IF($AI31<>"",($AI$7*$R$105)+IF($AI$7=4,($R$103)+IF($AI31=$AH$7+$AI$7,$R$104,0),0),0)) -> 32 | AK32: =MAX($AL$11:$AL$98) - AL32 -> 137
B33: Prédiction équipe | C33: =IF(ISBLANK(C31), 0, IF(C$7= 4, 1, 0)) -> 0 | D33: =IF(ISBLANK(D31), 0, IF(D$7 = 4, 1, 0)) -> 0 | E33: =IF(ISBLANK(E31), 0, IF(E$7= 4, 1, 0)) -> 1 | F33: =IF(ISBLANK(F31), 0, IF(F$7 = 4, 1, 0)) -> 0 | G33: =IF(ISBLANK(G31), 0, IF(G$7= 4, 1, 0)) -> 0 | H33: =IF(ISBLANK(H31), 0, IF(H$7 = 4, 1, 0)) -> 1 | I33: =IF(ISBLANK(I31), 0, IF(I$7= 4, 1, 0)) -> 0 | J33: =IF(ISBLANK(J31), 0, IF(J$7 = 4, 1, 0)) -> 0 | K33: =IF(ISBLANK(K31), 0, IF(K$7= 4, 1, 0)) -> 0 | L33: =IF(ISBLANK(L31), 0, IF(L$7 = 4, 1, 0)) -> 0 | M33: =IF(ISBLANK(M31), 0, IF(M$7= 4, 1, 0)) -> 0 | N33: =IF(ISBLANK(N31), 0, IF(N$7 = 4, 1, 0)) -> 1 | O33: =IF(ISBLANK(O31), 0, IF(O$7= 4, 1, 0)) -> 0 | P33: =IF(ISBLANK(P31), 0, IF(P$7 = 4, 1, 0)) -> 0 | Q33: =IF(ISBLANK(Q31), 0, IF(Q$7= 4, 1, 0)) -> 1 | R33: =IF(ISBLANK(R31), 0, IF(R$7 = 4, 1, 0)) -> 0 | T33: =IF(ISBLANK(T31), 0, IF(T$7= 4, 1, 0)) -> 0 | U33: =IF(ISBLANK(U31), 0, IF(U$7 = 4, 1, 0)) -> 0 | V33: =IF(ISBLANK(V31), 0, IF(V$7= 4, 1, 0)) -> 0 | W33: =IF(ISBLANK(W31), 0, IF(W$7 = 4, 1, 0)) -> 0 | X33: =IF(ISBLANK(X31), 0, IF(X$7= 4, 1, 0)) -> 1 | Y33: =IF(ISBLANK(Y31), 0, IF(Y$7 = 4, 1, 0)) -> 0 | Z33: =IF(ISBLANK(Z31), 0, IF(Z$7= 4, 1, 0)) -> 0 | AA33: =IF(ISBLANK(AA31), 0, IF(AA$7 = 4, 1, 0)) -> 0 | AC33: =IF(ISBLANK(AC31), 0, IF(AC$7= 4, 1, 0)) -> 1 | AD33: =IF(ISBLANK(AD31), 0, IF(AD$7 = 4, 1, 0)) -> 0 | AE33: =IF(ISBLANK(AE31), 0, IF(AE$7= 4, 1, 0)) -> 0 | AF33: =IF(ISBLANK(AF31), 0, IF(AF$7 = 4, 1, 0)) -> 0 | AH33: =IF(ISBLANK(AH31), 0, IF(AH$7= 4, 1, 0)) -> 0 | AI33: =IF(ISBLANK(AI31), 0, IF(AI$7 = 4, 1, 0)) -> 1 | AK33: =SUM(C33:AI33) -> 7
B34: Prédiciton nb matchs | C34: =IF(C33 = 0, 0, IF(C31 = (C$7+D$7),1,0)) -> 0 | D34: =IF(D33 = 0, 0, IF(D31 = (C$7+D$7),1,0)) -> 0 | E34: =IF(E33 = 0, 0, IF(E31 = (E$7+F$7),1,0)) -> 0 | F34: =IF(F33 = 0, 0, IF(F31 = (E$7+F$7),1,0)) -> 0 | G34: =IF(G33 = 0, 0, IF(G31 = (G$7+H$7),1,0)) -> 0 | H34: =IF(H33 = 0, 0, IF(H31 = (G$7+H$7),1,0)) -> 1 | I34: =IF(I33 = 0, 0, IF(I31 = (I$7+J$7),1,0)) -> 0 | J34: =IF(J33 = 0, 0, IF(J31 = (I$7+J$7),1,0)) -> 0 | K34: =IF(K33 = 0, 0, IF(K31 = (K$7+L$7),1,0)) -> 0 | L34: =IF(L33 = 0, 0, IF(L31 = (K$7+L$7),1,0)) -> 0 | M34: =IF(M33 = 0, 0, IF(M31 = (M$7+N$7),1,0)) -> 0 | N34: =IF(N33 = 0, 0, IF(N31 = (M$7+N$7),1,0)) -> 1 | O34: =IF(O33 = 0, 0, IF(O31 = (O$7+P$7),1,0)) -> 0 | P34: =IF(P33 = 0, 0, IF(P31 = (O$7+P$7),1,0)) -> 0 | Q34: =IF(Q33 = 0, 0, IF(Q31 = (Q$7+R$7),1,0)) -> 0 | R34: =IF(R33 = 0, 0, IF(R31 = (Q$7+R$7),1,0)) -> 0 | T34: =IF(T33 = 0, 0, IF(T31 = (T$7+U$7),1,0)) -> 0 | U34: =IF(U33 = 0, 0, IF(U31 = (T$7+U$7),1,0)) -> 0 | V34: =IF(V33 = 0, 0, IF(V31 = (V$7+W$7),1,0)) -> 0 | W34: =IF(W33 = 0, 0, IF(W31 = (V$7+W$7),1,0)) -> 0 | X34: =IF(X33 = 0, 0, IF(X31 = (X$7+Y$7),1,0)) -> 0 | Y34: =IF(Y33 = 0, 0, IF(Y31 = (X$7+Y$7),1,0)) -> 0 | Z34: =IF(Z33 = 0, 0, IF(Z31 = (Z$7+AA$7),1,0)) -> 0 | AA34: =IF(AA33 = 0, 0, IF(AA31 = (Z$7+AA$7),1,0)) -> 0 | AC34: =IF(AC33 = 0, 0, IF(AC31 = (AC$7+AD$7),1,0)) -> 0 | AD34: =IF(AD33 = 0, 0, IF(AD31 = (AC$7+AD$7),1,0)) -> 0 | AE34: =IF(AE33 = 0, 0, IF(AE31 = (AE$7+AF$7),1,0)) -> 0 | AF34: =IF(AF33 = 0, 0, IF(AF31 = (AE$7+AF$7),1,0)) -> 0 | AH34: =IF(AH33 = 0, 0, IF(AH31 = (AH$7+AI$7),1,0)) -> 0 | AI34: =IF(AI33 = 0, 0, IF(AI31 = (AH$7+AI$7),1,0)) -> 1 | AK34: =SUM(C34:AI34) -> 3
A35: =RANK(AL35,$AL$11:$AL$98,) -> 6 | B35: Daniel Darveau | C35: 4 | E35: 4 | G35: 6 | J35: 6 | K35: 6 | M35: 5 | O35: 6 | R35: 6 | S35: =SUM(C36:R36) -> 20 | U35: 6 | W35: 7 | Y35: 7 | Z35: 6 | AB35: =SUM(T36:AA36) -> 33 | AC35: 7 | AF35: 7 | AG35: =SUM(AC36:AF36) -> 38 | AI35: 6 | AJ35: =AH36 -> 24 | AK35: =MAX($AL$11:$AL$98) - AL35 -> 22 | AL35: =$S35+$AB35+$AG35+$AJ35 -> 115
A36: =RANK(AL36,$AL$11:$AL$98,) -> #N/A | C36: =(IF($C35<>"",($C$7*$O$105)+IF($C$7=4,($O$103)+IF($C35=$C$7+$D$7,$O$104,0),0),0)+IF($D35<>"",($D$7*$O$105)+IF($D$7=4,($O$103)+IF($D35=$C$7+$D$7,$O$104,0),0),0)) -> 0 | E36: =(IF($E35<>"",($E$7*$O$105)+IF($E$7=4,($O$103)+IF($E35=$E$7+$F$7,$O$104,0),0),0)+IF($F35<>"",($F$7*$O$105)+IF($F$7=4,($O$103)+IF($F35=$E$7+$F$7,$O$104,0),0),0)) -> 9 | G36: =(IF($G35<>"",($G$7*$O$105)+IF($G$7=4,($O$103)+IF($G35=$G$7+$H$7,$O$104,0),0),0)+IF($H35<>"",($H$7*$O$105)+IF($H$7=4,($O$103)+IF($H35=$G$7+$H$7,$O$104,0),0),0)) -> 3 | I36: =(IF($I35<>"",($I$7*$O$105)+IF($I$7=4,($O$103)+IF($I35=$I$7+$J$7,$O$104,0),0),0)+IF($J35<>"",($J$7*$O$105)+IF($J$7=4,($O$103)+IF($J35=$I$7+$J$7,$O$104,0),0),0)) -> 0 | K36: =(IF($K35<>"",($K$7*$O$105)+IF($K$7=4,($O$103)+IF($K35=$K$7+$L$7,$O$104,0),0),0)+IF($L35<>"",($L$7*$O$105)+IF($L$7=4,($O$103)+IF($L35=$K$7+$L$7,$O$104,0),0),0)) -> 1 | M36: =(IF($M35<>"",($M$7*$O$105)+IF($M$7=4,($O$103)+IF($M35=$M$7+$N$7,$O$104,0),0),0)+IF($N35<>"",($N$7*$O$105)+IF($N$7=4,($O$103)+IF($N35=$M$7+$N$7,$O$104,0),0),0)) -> 2 | O36: =(IF($O35<>"",($O$7*$O$105)+IF($O$7=4,($O$103)+IF($O35=$O$7+$P$7,$O$104,0),0),0)+IF($P35<>"",($P$7*$O$105)+IF($P$7=4,($O$103)+IF($P35=$O$7+$P$7,$O$104,0),0),0)) -> 2 | Q36: =(IF($Q35<>"",($Q$7*$O$105)+IF($Q$7=4,($O$103)+IF($Q35=$Q$7+$R$7,$O$104,0),0),0)+IF($R35<>"",($R$7*$O$105)+IF($R$7=4,($O$103)+IF($R35=$Q$7+$R$7,$O$104,0),0),0)) -> 3 | T36: =(IF($T35<>"",($T$7*$P$105)+IF($T$7=4,($P$103)+IF($T35=$T$7+$U$7,$P$104,0),0),0)+IF($U35<>"",($U$7*$P$105)+IF($U$7=4,($P$103)+IF($U35=$T$7+$U$7,$P$104,0),0),0)) -> 2 | V36: =(IF($V35<>"",($V$7*$P$105)+IF($V$7=4,($P$103)+IF($V35=$V$7+$W$7,$P$104,0),0),0)+IF($W35<>"",($W$7*$P$105)+IF($W$7=4,($P$103)+IF($W35=$V$7+$W$7,$P$104,0),0),0)) -> 14 | X36: =(IF($X35<>"",($X$7*$P$105)+IF($X$7=4,($P$103)+IF($X35=$X$7+$Y$7,$P$104,0),0),0)+IF($Y35<>"",($Y$7*$P$105)+IF($Y$7=4,($P$103)+IF($Y35=$X$7+$Y$7,$P$104,0),0),0)) -> 3 | Z36: =(IF($Z35<>"",($Z$7*$P$105)+IF($Z$7=4,($P$103)+IF($Z35=$Z$7+$AA$7,$P$104,0),0),0)+IF($AA35<>"",($AA$7*$P$105)+IF($AA$7=4,($P$103)+IF($AA35=$Z$7+$AA$7,$P$104,0),0),0)) -> 14 | AC36: =(IF($AC35<>"",($AC$7*$Q$105)+IF($AC$7=4,($Q$103)+IF($AC35=$AC$7+$AD$7,$Q$104,0),0),0)+IF($AD35<>"",($AD$7*$Q$105)+IF($AD$7=4,($Q$103)+IF($AD35=$AC$7+$AD$7,$Q$104,0),0),0)) -> 19 | AE36: =(IF($AE35<>"",($AE$7*$Q$105)+IF($AE$7=4,($Q$103)+IF($AE35=$AE$7+$AF$7,$Q$104,0),0),0)+IF($AF35<>"",($AF$7*$Q$105)+IF($AF$7=4,($Q$103)+IF($AF35=$AE$7+$AF$7,$Q$104,0),0),0)) -> 19 | AH36: =(IF($AH35<>"",($AH$7*$Q$105)+IF($AH$7=4,($R$103)+IF($AH35=$AH$7+$AI$7,$R$104,0),0),0)+IF($AI35<>"",($AI$7*$R$105)+IF($AI$7=4,($R$103)+IF($AI35=$AH$7+$AI$7,$R$104,0),0),0)) -> 24 | AK36: =MAX($AL$11:$AL$98) - AL36 -> 137
B37: Prédiction équipe | C37: =IF(ISBLANK(C35), 0, IF(C$7= 4, 1, 0)) -> 0 | D37: =IF(ISBLANK(D35), 0, IF(D$7 = 4, 1, 0)) -> 0 | E37: =IF(ISBLANK(E35), 0, IF(E$7= 4, 1, 0)) -> 1 | F37: =IF(ISBLANK(F35), 0, IF(F$7 = 4, 1, 0)) -> 0 | G37: =IF(ISBLANK(G35), 0, IF(G$7= 4, 1, 0)) -> 0 | H37: =IF(ISBLANK(H35), 0, IF(H$7 = 4, 1, 0)) -> 0 | I37: =IF(ISBLANK(I35), 0, IF(I$7= 4, 1, 0)) -> 0 | J37: =IF(ISBLANK(J35), 0, IF(J$7 = 4, 1, 0)) -> 0 | K37: =IF(ISBLANK(K35), 0, IF(K$7= 4, 1, 0)) -> 0 | L37: =IF(ISBLANK(L35), 0, IF(L$7 = 4, 1, 0)) -> 0 | M37: =IF(ISBLANK(M35), 0, IF(M$7= 4, 1, 0)) -> 0 | N37: =IF(ISBLANK(N35), 0, IF(N$7 = 4, 1, 0)) -> 0 | O37: =IF(ISBLANK(O35), 0, IF(O$7= 4, 1, 0)) -> 0 | P37: =IF(ISBLANK(P35), 0, IF(P$7 = 4, 1, 0)) -> 0 | Q37: =IF(ISBLANK(Q35), 0, IF(Q$7= 4, 1, 0)) -> 0 | R37: =IF(ISBLANK(R35), 0, IF(R$7 = 4, 1, 0)) -> 0 | T37: =IF(ISBLANK(T35), 0, IF(T$7= 4, 1, 0)) -> 0 | U37: =IF(ISBLANK(U35), 0, IF(U$7 = 4, 1, 0)) -> 0 | V37: =IF(ISBLANK(V35), 0, IF(V$7= 4, 1, 0)) -> 0 | W37: =IF(ISBLANK(W35), 0, IF(W$7 = 4, 1, 0)) -> 1 | X37: =IF(ISBLANK(X35), 0, IF(X$7= 4, 1, 0)) -> 0 | Y37: =IF(ISBLANK(Y35), 0, IF(Y$7 = 4, 1, 0)) -> 0 | Z37: =IF(ISBLANK(Z35), 0, IF(Z$7= 4, 1, 0)) -> 1 | AA37: =IF(ISBLANK(AA35), 0, IF(AA$7 = 4, 1, 0)) -> 0 | AC37: =IF(ISBLANK(AC35), 0, IF(AC$7= 4, 1, 0)) -> 1 | AD37: =IF(ISBLANK(AD35), 0, IF(AD$7 = 4, 1, 0)) -> 0 | AE37: =IF(ISBLANK(AE35), 0, IF(AE$7= 4, 1, 0)) -> 0 | AF37: =IF(ISBLANK(AF35), 0, IF(AF$7 = 4, 1, 0)) -> 1 | AH37: =IF(ISBLANK(AH35), 0, IF(AH$7= 4, 1, 0)) -> 0 | AI37: =IF(ISBLANK(AI35), 0, IF(AI$7 = 4, 1, 0)) -> 1 | AK37: =SUM(C37:AI37) -> 6
B38: Prédiciton nb matchs | C38: =IF(C37 = 0, 0, IF(C35 = (C$7+D$7),1,0)) -> 0 | D38: =IF(D37 = 0, 0, IF(D35 = (C$7+D$7),1,0)) -> 0 | E38: =IF(E37 = 0, 0, IF(E35 = (E$7+F$7),1,0)) -> 0 | F38: =IF(F37 = 0, 0, IF(F35 = (E$7+F$7),1,0)) -> 0 | G38: =IF(G37 = 0, 0, IF(G35 = (G$7+H$7),1,0)) -> 0 | H38: =IF(H37 = 0, 0, IF(H35 = (G$7+H$7),1,0)) -> 0 | I38: =IF(I37 = 0, 0, IF(I35 = (I$7+J$7),1,0)) -> 0 | J38: =IF(J37 = 0, 0, IF(J35 = (I$7+J$7),1,0)) -> 0 | K38: =IF(K37 = 0, 0, IF(K35 = (K$7+L$7),1,0)) -> 0 | L38: =IF(L37 = 0, 0, IF(L35 = (K$7+L$7),1,0)) -> 0 | M38: =IF(M37 = 0, 0, IF(M35 = (M$7+N$7),1,0)) -> 0 | N38: =IF(N37 = 0, 0, IF(N35 = (M$7+N$7),1,0)) -> 0 | O38: =IF(O37 = 0, 0, IF(O35 = (O$7+P$7),1,0)) -> 0 | P38: =IF(P37 = 0, 0, IF(P35 = (O$7+P$7),1,0)) -> 0 | Q38: =IF(Q37 = 0, 0, IF(Q35 = (Q$7+R$7),1,0)) -> 0 | R38: =IF(R37 = 0, 0, IF(R35 = (Q$7+R$7),1,0)) -> 0 | T38: =IF(T37 = 0, 0, IF(T35 = (T$7+U$7),1,0)) -> 0 | U38: =IF(U37 = 0, 0, IF(U35 = (T$7+U$7),1,0)) -> 0 | V38: =IF(V37 = 0, 0, IF(V35 = (V$7+W$7),1,0)) -> 0 | W38: =IF(W37 = 0, 0, IF(W35 = (V$7+W$7),1,0)) -> 0 | X38: =IF(X37 = 0, 0, IF(X35 = (X$7+Y$7),1,0)) -> 0 | Y38: =IF(Y37 = 0, 0, IF(Y35 = (X$7+Y$7),1,0)) -> 0 | Z38: =IF(Z37 = 0, 0, IF(Z35 = (Z$7+AA$7),1,0)) -> 0 | AA38: =IF(AA37 = 0, 0, IF(AA35 = (Z$7+AA$7),1,0)) -> 0 | AC38: =IF(AC37 = 0, 0, IF(AC35 = (AC$7+AD$7),1,0)) -> 0 | AD38: =IF(AD37 = 0, 0, IF(AD35 = (AC$7+AD$7),1,0)) -> 0 | AE38: =IF(AE37 = 0, 0, IF(AE35 = (AE$7+AF$7),1,0)) -> 0 | AF38: =IF(AF37 = 0, 0, IF(AF35 = (AE$7+AF$7),1,0)) -> 0 | AH38: =IF(AH37 = 0, 0, IF(AH35 = (AH$7+AI$7),1,0)) -> 0 | AI38: =IF(AI37 = 0, 0, IF(AI35 = (AH$7+AI$7),1,0)) -> 0 | AK38: =SUM(C38:AI38) -> 0
A39: =RANK(AL39,$AL$11:$AL$98,) -> 8 | B39: Thanh Vinh Nguyen | C39: 6 | E39: 7 | G39: 6 | J39: 7 | K39: 7 | M39: 6 | O39: 6 | R39: 7 | S39: =SUM(C40:R40) -> 22 | U39: 7 | W39: 7 | X39: 7 | Z39: 7 | AB39: =SUM(T40:AA40) -> 52 | AD39: 6 | AE39: 7 | AG39: =SUM(AC40:AF40) -> 2 | AI39: 7 | AJ39: =AH40 -> 32 | AK39: =MAX($AL$11:$AL$98) - AL39 -> 29 | AL39: =$S39+$AB39+$AG39+$AJ39 -> 108
A40: =RANK(AL40,$AL$11:$AL$98,) -> #N/A | C40: =(IF($C39<>"",($C$7*$O$105)+IF($C$7=4,($O$103)+IF($C39=$C$7+$D$7,$O$104,0),0),0)+IF($D39<>"",($D$7*$O$105)+IF($D$7=4,($O$103)+IF($D39=$C$7+$D$7,$O$104,0),0),0)) -> 0 | E40: =(IF($E39<>"",($E$7*$O$105)+IF($E$7=4,($O$103)+IF($E39=$E$7+$F$7,$O$104,0),0),0)+IF($F39<>"",($F$7*$O$105)+IF($F$7=4,($O$103)+IF($F39=$E$7+$F$7,$O$104,0),0),0)) -> 11 | G40: =(IF($G39<>"",($G$7*$O$105)+IF($G$7=4,($O$103)+IF($G39=$G$7+$H$7,$O$104,0),0),0)+IF($H39<>"",($H$7*$O$105)+IF($H$7=4,($O$103)+IF($H39=$G$7+$H$7,$O$104,0),0),0)) -> 3 | I40: =(IF($I39<>"",($I$7*$O$105)+IF($I$7=4,($O$103)+IF($I39=$I$7+$J$7,$O$104,0),0),0)+IF($J39<>"",($J$7*$O$105)+IF($J$7=4,($O$103)+IF($J39=$I$7+$J$7,$O$104,0),0),0)) -> 0 | K40: =(IF($K39<>"",($K$7*$O$105)+IF($K$7=4,($O$103)+IF($K39=$K$7+$L$7,$O$104,0),0),0)+IF($L39<>"",($L$7*$O$105)+IF($L$7=4,($O$103)+IF($L39=$K$7+$L$7,$O$104,0),0),0)) -> 1 | M40: =(IF($M39<>"",($M$7*$O$105)+IF($M$7=4,($O$103)+IF($M39=$M$7+$N$7,$O$104,0),0),0)+IF($N39<>"",($N$7*$O$105)+IF($N$7=4,($O$103)+IF($N39=$M$7+$N$7,$O$104,0),0),0)) -> 2 | O40: =(IF($O39<>"",($O$7*$O$105)+IF($O$7=4,($O$103)+IF($O39=$O$7+$P$7,$O$104,0),0),0)+IF($P39<>"",($P$7*$O$105)+IF($P$7=4,($O$103)+IF($P39=$O$7+$P$7,$O$104,0),0),0)) -> 2 | Q40: =(IF($Q39<>"",($Q$7*$O$105)+IF($Q$7=4,($O$103)+IF($Q39=$Q$7+$R$7,$O$104,0),0),0)+IF($R39<>"",($R$7*$O$105)+IF($R$7=4,($O$103)+IF($R39=$Q$7+$R$7,$O$104,0),0),0)) -> 3 | T40: =(IF($T39<>"",($T$7*$P$105)+IF($T$7=4,($P$103)+IF($T39=$T$7+$U$7,$P$104,0),0),0)+IF($U39<>"",($U$7*$P$105)+IF($U$7=4,($P$103)+IF($U39=$T$7+$U$7,$P$104,0),0),0)) -> 2 | V40: =(IF($V39<>"",($V$7*$P$105)+IF($V$7=4,($P$103)+IF($V39=$V$7+$W$7,$P$104,0),0),0)+IF($W39<>"",($W$7*$P$105)+IF($W$7=4,($P$103)+IF($W39=$V$7+$W$7,$P$104,0),0),0)) -> 14 | X40: =(IF($X39<>"",($X$7*$P$105)+IF($X$7=4,($P$103)+IF($X39=$X$7+$Y$7,$P$104,0),0),0)+IF($Y39<>"",($Y$7*$P$105)+IF($Y$7=4,($P$103)+IF($Y39=$X$7+$Y$7,$P$104,0),0),0)) -> 18 | Z40: =(IF($Z39<>"",($Z$7*$P$105)+IF($Z$7=4,($P$103)+IF($Z39=$Z$7+$AA$7,$P$104,0),0),0)+IF($AA39<>"",($AA$7*$P$105)+IF($AA$7=4,($P$103)+IF($AA39=$Z$7+$AA$7,$P$104,0),0),0)) -> 18 | AC40: =(IF($AC39<>"",($AC$7*$Q$105)+IF($AC$7=4,($Q$103)+IF($AC39=$AC$7+$AD$7,$Q$104,0),0),0)+IF($AD39<>"",($AD$7*$Q$105)+IF($AD$7=4,($Q$103)+IF($AD39=$AC$7+$AD$7,$Q$104,0),0),0)) -> 0 | AE40: =(IF($AE39<>"",($AE$7*$Q$105)+IF($AE$7=4,($Q$103)+IF($AE39=$AE$7+$AF$7,$Q$104,0),0),0)+IF($AF39<>"",($AF$7*$Q$105)+IF($AF$7=4,($Q$103)+IF($AF39=$AE$7+$AF$7,$Q$104,0),0),0)) -> 2 | AH40: =(IF($AH39<>"",($AH$7*$Q$105)+IF($AH$7=4,($R$103)+IF($AH39=$AH$7+$AI$7,$R$104,0),0),0)+IF($AI39<>"",($AI$7*$R$105)+IF($AI$7=4,($R$103)+IF($AI39=$AH$7+$AI$7,$R$104,0),0),0)) -> 32 | AK40: =MAX($AL$11:$AL$98) - AL40 -> 137
B41: Prédiction équipe | C41: =IF(ISBLANK(C39), 0, IF(C$7= 4, 1, 0)) -> 0 | D41: =IF(ISBLANK(D39), 0, IF(D$7 = 4, 1, 0)) -> 0 | E41: =IF(ISBLANK(E39), 0, IF(E$7= 4, 1, 0)) -> 1 | F41: =IF(ISBLANK(F39), 0, IF(F$7 = 4, 1, 0)) -> 0 | G41: =IF(ISBLANK(G39), 0, IF(G$7= 4, 1, 0)) -> 0 | H41: =IF(ISBLANK(H39), 0, IF(H$7 = 4, 1, 0)) -> 0 | I41: =IF(ISBLANK(I39), 0, IF(I$7= 4, 1, 0)) -> 0 | J41: =IF(ISBLANK(J39), 0, IF(J$7 = 4, 1, 0)) -> 0 | K41: =IF(ISBLANK(K39), 0, IF(K$7= 4, 1, 0)) -> 0 | L41: =IF(ISBLANK(L39), 0, IF(L$7 = 4, 1, 0)) -> 0 | M41: =IF(ISBLANK(M39), 0, IF(M$7= 4, 1, 0)) -> 0 | N41: =IF(ISBLANK(N39), 0, IF(N$7 = 4, 1, 0)) -> 0 | O41: =IF(ISBLANK(O39), 0, IF(O$7= 4, 1, 0)) -> 0 | P41: =IF(ISBLANK(P39), 0, IF(P$7 = 4, 1, 0)) -> 0 | Q41: =IF(ISBLANK(Q39), 0, IF(Q$7= 4, 1, 0)) -> 0 | R41: =IF(ISBLANK(R39), 0, IF(R$7 = 4, 1, 0)) -> 0 | T41: =IF(ISBLANK(T39), 0, IF(T$7= 4, 1, 0)) -> 0 | U41: =IF(ISBLANK(U39), 0, IF(U$7 = 4, 1, 0)) -> 0 | V41: =IF(ISBLANK(V39), 0, IF(V$7= 4, 1, 0)) -> 0 | W41: =IF(ISBLANK(W39), 0, IF(W$7 = 4, 1, 0)) -> 1 | X41: =IF(ISBLANK(X39), 0, IF(X$7= 4, 1, 0)) -> 1 | Y41: =IF(ISBLANK(Y39), 0, IF(Y$7 = 4, 1, 0)) -> 0 | Z41: =IF(ISBLANK(Z39), 0, IF(Z$7= 4, 1, 0)) -> 1 | AA41: =IF(ISBLANK(AA39), 0, IF(AA$7 = 4, 1, 0)) -> 0 | AC41: =IF(ISBLANK(AC39), 0, IF(AC$7= 4, 1, 0)) -> 0 | AD41: =IF(ISBLANK(AD39), 0, IF(AD$7 = 4, 1, 0)) -> 0 | AE41: =IF(ISBLANK(AE39), 0, IF(AE$7= 4, 1, 0)) -> 0 | AF41: =IF(ISBLANK(AF39), 0, IF(AF$7 = 4, 1, 0)) -> 0 | AH41: =IF(ISBLANK(AH39), 0, IF(AH$7= 4, 1, 0)) -> 0 | AI41: =IF(ISBLANK(AI39), 0, IF(AI$7 = 4, 1, 0)) -> 1 | AK41: =SUM(C41:AI41) -> 5
B42: Prédiciton nb matchs | C42: =IF(C41 = 0, 0, IF(C39 = (C$7+D$7),1,0)) -> 0 | D42: =IF(D41 = 0, 0, IF(D39 = (C$7+D$7),1,0)) -> 0 | E42: =IF(E41 = 0, 0, IF(E39 = (E$7+F$7),1,0)) -> 1 | F42: =IF(F41 = 0, 0, IF(F39 = (E$7+F$7),1,0)) -> 0 | G42: =IF(G41 = 0, 0, IF(G39 = (G$7+H$7),1,0)) -> 0 | H42: =IF(H41 = 0, 0, IF(H39 = (G$7+H$7),1,0)) -> 0 | I42: =IF(I41 = 0, 0, IF(I39 = (I$7+J$7),1,0)) -> 0 | J42: =IF(J41 = 0, 0, IF(J39 = (I$7+J$7),1,0)) -> 0 | K42: =IF(K41 = 0, 0, IF(K39 = (K$7+L$7),1,0)) -> 0 | L42: =IF(L41 = 0, 0, IF(L39 = (K$7+L$7),1,0)) -> 0 | M42: =IF(M41 = 0, 0, IF(M39 = (M$7+N$7),1,0)) -> 0 | N42: =IF(N41 = 0, 0, IF(N39 = (M$7+N$7),1,0)) -> 0 | O42: =IF(O41 = 0, 0, IF(O39 = (O$7+P$7),1,0)) -> 0 | P42: =IF(P41 = 0, 0, IF(P39 = (O$7+P$7),1,0)) -> 0 | Q42: =IF(Q41 = 0, 0, IF(Q39 = (Q$7+R$7),1,0)) -> 0 | R42: =IF(R41 = 0, 0, IF(R39 = (Q$7+R$7),1,0)) -> 0 | T42: =IF(T41 = 0, 0, IF(T39 = (T$7+U$7),1,0)) -> 0 | U42: =IF(U41 = 0, 0, IF(U39 = (T$7+U$7),1,0)) -> 0 | V42: =IF(V41 = 0, 0, IF(V39 = (V$7+W$7),1,0)) -> 0 | W42: =IF(W41 = 0, 0, IF(W39 = (V$7+W$7),1,0)) -> 0 | X42: =IF(X41 = 0, 0, IF(X39 = (X$7+Y$7),1,0)) -> 1 | Y42: =IF(Y41 = 0, 0, IF(Y39 = (X$7+Y$7),1,0)) -> 0 | Z42: =IF(Z41 = 0, 0, IF(Z39 = (Z$7+AA$7),1,0)) -> 1 | AA42: =IF(AA41 = 0, 0, IF(AA39 = (Z$7+AA$7),1,0)) -> 0 | AC42: =IF(AC41 = 0, 0, IF(AC39 = (AC$7+AD$7),1,0)) -> 0 | AD42: =IF(AD41 = 0, 0, IF(AD39 = (AC$7+AD$7),1,0)) -> 0 | AE42: =IF(AE41 = 0, 0, IF(AE39 = (AE$7+AF$7),1,0)) -> 0 | AF42: =IF(AF41 = 0, 0, IF(AF39 = (AE$7+AF$7),1,0)) -> 0 | AH42: =IF(AH41 = 0, 0, IF(AH39 = (AH$7+AI$7),1,0)) -> 0 | AI42: =IF(AI41 = 0, 0, IF(AI39 = (AH$7+AI$7),1,0)) -> 1 | AK42: =SUM(C42:AI42) -> 4
...

Sheet Résultats
A3: A1 | B3: TAMPA BAY | C3: 3 | D3: 1 | E3: 1 | F3: 3 | J3: =IF(C3>C4,1,0)+IF(D3>D4,1,0)+IF(E3>E4,1,0)+IF(F3>F4,1,0)+IF(G3>G4,1,0)+IF(H3>H4,1,0)+IF(I3>I4,1,0) -> 0
A4: WC2 | B4: COLUMBUS | C4: 4 | D4: 5 | E4: 3 | F4: 7 | J4: =IF(C4>C3,1,0)+IF(D4>D3,1,0)+IF(E4>E3,1,0)+IF(F4>F3,1,0)+IF(G4>G3,1,0)+IF(H4>H3,1,0)+IF(I4>I3,1,0) -> 4
A6: A2 | B6: BOSTON | C6: 1 | D6: 4 | E6: 2 | F6: 6 | G6: 1 | H6: 4 | I6: 5 | J6: =IF(C6>C7,1,0)+IF(D6>D7,1,0)+IF(E6>E7,1,0)+IF(F6>F7,1,0)+IF(G6>G7,1,0)+IF(H6>H7,1,0)+IF(I6>I7,1,0) -> 4 | M6: A2 | N6: BOSTON | O6: 3 | P6: 2 | Q6: 1 | R6: 4 | S6: 4 | T6: 3 | V6: =IF(O6>O7,1,0)+IF(P6>P7,1,0)+IF(Q6>Q7,1,0)+IF(R6>R7,1,0)+IF(S6>S7,1,0)+IF(T6>T7,1,0)+IF(U6>U7,1,0) -> 4
A7: A3 | B7: TORONTO | C7: 4 | D7: 1 | E7: 3 | F7: 4 | G7: 2 | H7: 2 | I7: 1 | J7: =IF(C7>C6,1,0)+IF(D7>D6,1,0)+IF(E7>E6,1,0)+IF(F7>F6,1,0)+IF(G7>G6,1,0)+IF(H7>H6,1,0)+IF(I7>I6,1,0) -> 3 | M7: WC2 | N7: COLUMBUS | O7: 2 | P7: 3 | Q7: 2 | R7: 1 | S7: 3 | T7: 0 | V7: =IF(O7>O6,1,0)+IF(P7>P6,1,0)+IF(Q7>Q6,1,0)+IF(R7>R6,1,0)+IF(S7>S6,1,0)+IF(T7>T6,1,0)+IF(U7>U6,1,0) -> 2
Y8: A2 | Z8: BOSTON | AA8: 5 | AB8: 6 | AC8: 2 | AD8: 4 | AH8: =IF(AA8>AA9,1,0)+IF(AB8>AB9,1,0)+IF(AC8>AC9,1,0)+IF(AD8>AD9,1,0)+IF(AE8>AE9,1,0)+IF(AF8>AF9,1,0)+IF(AG8>AG9,1,0) -> 4
Y9: WC1 | Z9: CAROLINE | AA9: 2 | AB9: 2 | AC9: 1 | AD9: 0 | AH9: =IF(AA9>AA8,1,0)+IF(AB9>AB8,1,0)+IF(AC9>AC8,1,0)+IF(AD9>AD8,1,0)+IF(AE9>AE8,1,0)+IF(AF9>AF8,1,0)+IF(AG9>AG8,1,0) -> 0
A10: M1 | B10: WASHINGTON | C10: 4 | D10: 4 | F10: 1 | G10: 6 | H10: 2 | I10: 3 | J10: =IF(C10>C11,1,0)+IF(D10>D11,1,0)+IF(E10>E11,1,0)+IF(F10>F11,1,0)+IF(G10>G11,1,0)+IF(H10>H11,1,0)+IF(I10>I11,1,0) -> 3 | M10: M2 | N10: NEW YORK I. | O10: 0 | P10: 1 | Q10: 2 | R10: 2 | V10: =IF(O10>O11,1,0)+IF(P10>P11,1,0)+IF(Q10>Q11,1,0)+IF(R10>R11,1,0)+IF(S10>S11,1,0)+IF(T10>T11,1,0)+IF(U10>U11,1,0) -> 0
A11: WC1 | B11: CAROLINE | C11: 2 | D11: 3 | E11: 5 | F11: 2 | G11: 0 | H11: 5 | I11: 4 | J11: =IF(C11>C10,1,0)+IF(D11>D10,1,0)+IF(E11>E10,1,0)+IF(F11>F10,1,0)+IF(G11>G10,1,0)+IF(H11>H10,1,0)+IF(I11>I10,1,0) -> 4 | M11: WC1 | N11: CAROLINE | O11: 1 | P11: 2 | Q11: 5 | R11: 5 | V11: =IF(O11>O10,1,0)+IF(P11>P10,1,0)+IF(Q11>Q10,1,0)+IF(R11>R10,1,0)+IF(S11>S10,1,0)+IF(T11>T10,1,0)+IF(U11>U10,1,0) -> 4
E12: 0
A13: M2 | B13: NEW YORK I. | C13: 4 | D13: 3 | E13: 4 | F13: 3 | J13: =IF(C13>C14,1,0)+IF(D13>D14,1,0)+IF(E13>E14,1,0)+IF(F13>F14,1,0)+IF(G13>G14,1,0)+IF(H13>H14,1,0)+IF(I13>I14,1,0) -> 4
A14: M3 | B14: PITTSBURGH | C14: 3 | D14: 1 | E14: 1 | F14: 1 | J14: =IF(C14>C13,1,0)+IF(D14>D13,1,0)+IF(E14>E13,1,0)+IF(F14>F13,1,0)+IF(G14>G13,1,0)+IF(H14>H13,1,0)+IF(I14>I13,1,0) -> 0
Y15: A2 | Z15: BOSTON | AA15: 4 | AB15: 2 | AC15: 7 | AD15: 2 | AE15: 1 | AF15: 5 | AG15: 1 | AH15: =IF(AA15>AA16,1,0)+IF(AB15>AB16,1,0)+IF(AC15>AC16,1,0)+IF(AD15>AD16,1,0)+IF(AE15>AE16,1,0)+IF(AF15>AF16,1,0)+IF(AG15>AG16,1,0) -> 3
Y16: C3 | Z16: ST-LOUIS | AA16: 2 | AB16: 3 | AC16: 2 | AD16: 4 | AE16: 2 | AF16: 1 | AG16: 4 | AH16: =IF(AA16>AA15,1,0)+IF(AB16>AB15,1,0)+IF(AC16>AC15,1,0)+IF(AD16>AD15,1,0)+IF(AE16>AE15,1,0)+IF(AF16>AF15,1,0)+IF(AG16>AG15,1,0) -> 4
A17: C1 | B17: CALGARY | C17: 4 | D17: 2 | E17: 2 | F17: 2 | G17: 1 | J17: =IF(C17>C18,1,0)+IF(D17>D18,1,0)+IF(E17>E18,1,0)+IF(F17>F18,1,0)+IF(G17>G18,1,0)+IF(H17>H18,1,0)+IF(I17>I18,1,0) -> 1
A18: WC2 | B18: COLORADO | C18: 0 | D18: 3 | E18: 6 | F18: 3 | G18: 5 | J18: =IF(C18>C17,1,0)+IF(D18>D17,1,0)+IF(E18>E17,1,0)+IF(F18>F17,1,0)+IF(G18>G17,1,0)+IF(H18>H17,1,0)+IF(I18>I17,1,0) -> 4
A20: C2 | B20: WINNIPEG | C20: 1 | D20: 3 | E20: 6 | F20: 2 | G20: 2 | H20: 2 | J20: =IF(C20>C21,1,0)+IF(D20>D21,1,0)+IF(E20>E21,1,0)+IF(F20>F21,1,0)+IF(G20>G21,1,0)+IF(H20>H21,1,0)+IF(I20>I21,1,0) -> 2 | M20: P2 | N20: SAN JOSE | O20: 5 | P20: 3 | Q20: 4 | R20: 0 | S20: 2 | T20: 3 | U20: 3 | V20: =IF(O20>O21,1,0)+IF(P20>P21,1,0)+IF(Q20>Q21,1,0)+IF(R20>R21,1,0)+IF(S20>S21,1,0)+IF(T20>T21,1,0)+IF(U20>U21,1,0) -> 4
A21: C3 | B21: ST-LOUIS | C21: 2 | D21: 4 | E21: 3 | F21: 1 | G21: 3 | H21: 3 | J21: =IF(C21>C20,1,0)+IF(D21>D20,1,0)+IF(E21>E20,1,0)+IF(F21>F20,1,0)+IF(G21>G20,1,0)+IF(H21>H20,1,0)+IF(I21>I20,1,0) -> 4 | M21: WC2 | N21: COLORADO | O21: 2 | P21: 4 | Q21: 2 | R21: 3 | S21: 1 | T21: 4 | U21: 2 | V21: =IF(O21>O20,1,0)+IF(P21>P20,1,0)+IF(Q21>Q20,1,0)+IF(R21>R20,1,0)+IF(S21>S20,1,0)+IF(T21>T20,1,0)+IF(U21>U20,1,0) -> 3
Y22: P2 | Z22: SAN JOSE | AA22: 6 | AB22: 2 | AC22: 5 | AD22: 1 | AE22: 0 | AF22: 1 | AH22: =IF(AA22>AA23,1,0)+IF(AB22>AB23,1,0)+IF(AC22>AC23,1,0)+IF(AD22>AD23,1,0)+IF(AE22>AE23,1,0)+IF(AF22>AF23,1,0)+IF(AG22>AG23,1,0) -> 2
Y23: C3 | Z23: ST-LOUIS | AA23: 3 | AB23: 4 | AC23: 4 | AD23: 2 | AE23: 5 | AF23: 5 | AH23: =IF(AA23>AA22,1,0)+IF(AB23>AB22,1,0)+IF(AC23>AC22,1,0)+IF(AD23>AD22,1,0)+IF(AE23>AE22,1,0)+IF(AF23>AF22,1,0)+IF(AG23>AG22,1,0) -> 4
